INFO 2025-01-16 02:08:00,507 autoreload Watching for file changes with StatReloader
ERROR 2025-01-16 02:08:02,670 views Login failed for username: Velcq
INFO 2025-01-16 02:08:02,680 basehttp "POST /index/login/ HTTP/1.1" 200 1022
ERROR 2025-01-16 02:08:04,914 views Login failed for username: Velcq
INFO 2025-01-16 02:08:04,916 basehttp "POST /index/login/ HTTP/1.1" 200 1022
ERROR 2025-01-16 02:08:06,869 views Login failed for username: Velcq
INFO 2025-01-16 02:08:06,871 basehttp "POST /index/login/ HTTP/1.1" 200 1022
WARNING 2025-01-16 02:08:09,658 views Suspicious login attempts for username: Velcq from IP: 127.0.0.1
ERROR 2025-01-16 02:08:10,162 views Login failed for username: Velcq
INFO 2025-01-16 02:08:10,167 basehttp "POST /index/login/ HTTP/1.1" 200 1022
INFO 2025-01-16 02:08:30,610 basehttp "GET /index/register/ HTTP/1.1" 200 2486
ERROR 2025-01-16 02:08:50,592 log Internal Server Error: /index/register/
Traceback (most recent call last):
  File "C:\Users\Mihnea\AppData\Local\Programs\Python\Python312\Lib\site-packages\django\core\handlers\exception.py", line 55, in inner
    response = get_response(request)
               ^^^^^^^^^^^^^^^^^^^^^
  File "C:\Users\Mihnea\AppData\Local\Programs\Python\Python312\Lib\site-packages\django\core\handlers\base.py", line 197, in _get_response
    response = wrapped_callback(request, *callback_args, **callback_kwargs)
               ^^^^^^^^^^^^^^^^^^^^^^^^^^^^^^^^^^^^^^^^^^^^^^^^^^^^^^^^^^^^
  File "C:\Users\Mihnea\Documents\Unibuc-FMI\2024-2025\Semestrul_1\Django\proiect\app_0\views.py", line 103, in register
    messages.error(request, 'This username is not allowed.')
    ^^^^^^^^^^^^^^
AttributeError: 'dict' object has no attribute 'error'
ERROR 2025-01-16 02:08:50,594 basehttp "POST /index/register/ HTTP/1.1" 500 72624
INFO 2025-01-16 02:10:19,540 autoreload Watching for file changes with StatReloader
CRITICAL 2025-01-16 02:10:23,377 views Attempt to register with username 'admin' from email: mihneave2004@gmail.com
INFO 2025-01-16 02:10:23,383 basehttp "POST /index/register/ HTTP/1.1" 302 0
INFO 2025-01-16 02:10:23,401 basehttp "GET /index/register/ HTTP/1.1" 200 2486
CRITICAL 2025-01-16 02:10:48,526 views Attempt to register with username 'admin' from email: mihneave2004@gmail.com
INFO 2025-01-16 02:10:48,527 basehttp "POST /index/register/ HTTP/1.1" 302 0
INFO 2025-01-16 02:10:48,538 basehttp "GET /index/register/ HTTP/1.1" 200 2486
WARNING 2025-01-16 02:12:22,795 log Not Found: /index/recent_purchases
WARNING 2025-01-16 02:12:22,796 basehttp "GET /index/recent_purchases HTTP/1.1" 404 6942
ERROR 2025-01-16 02:12:40,584 views Login failed for username: Velcq
INFO 2025-01-16 02:12:40,588 basehttp "POST /index/login/ HTTP/1.1" 200 1022
INFO 2025-01-16 02:12:46,929 basehttp "POST /index/login/ HTTP/1.1" 302 0
INFO 2025-01-16 02:12:46,992 basehttp "GET /index/profile/ HTTP/1.1" 200 791
WARNING 2025-01-16 02:12:59,777 log Not Found: /index/recent_purchases
WARNING 2025-01-16 02:12:59,777 basehttp "GET /index/recent_purchases HTTP/1.1" 404 6942
WARNING 2025-01-16 02:13:03,856 log Not Found: /index/recent_purchases/Velcq
WARNING 2025-01-16 02:13:03,856 basehttp "GET /index/recent_purchases/Velcq HTTP/1.1" 404 6966
INFO 2025-01-16 02:13:53,252 basehttp "GET /index/bilete/ HTTP/1.1" 200 4418
INFO 2025-01-16 02:13:54,832 basehttp "POST /index/cumpara-bilet/1/ HTTP/1.1" 302 0
INFO 2025-01-16 02:13:54,902 basehttp "GET /index/bilete/ HTTP/1.1" 200 4418
INFO 2025-01-16 02:13:56,505 basehttp "POST /index/cumpara-bilet/2/ HTTP/1.1" 302 0
INFO 2025-01-16 02:13:56,577 basehttp "GET /index/bilete/ HTTP/1.1" 200 4418
INFO 2025-01-16 02:13:59,108 basehttp "POST /index/cumpara-bilet/3/ HTTP/1.1" 302 0
INFO 2025-01-16 02:13:59,205 basehttp "GET /index/bilete/ HTTP/1.1" 200 4418
WARNING 2025-01-16 02:14:08,031 log Not Found: /index/recent_purchases
WARNING 2025-01-16 02:14:08,032 basehttp "GET /index/recent_purchases HTTP/1.1" 404 6942
CRITICAL 2025-01-16 02:14:24,191 views An error occurred: Cannot resolve keyword 'user' into field. Choices are: cursa, cursa_id, id, loc, pret, vagon, vagon_id, vizualizare
ERROR 2025-01-16 02:14:24,191 log Internal Server Error: /index/recent_purchases/
ERROR 2025-01-16 02:14:24,192 basehttp "GET /index/recent_purchases/ HTTP/1.1" 500 18
INFO 2025-01-16 02:17:35,697 autoreload C:\Users\Mihnea\Documents\Unibuc-FMI\2024-2025\Semestrul_1\Django\proiect\app_0\views.py changed, reloading.
INFO 2025-01-16 02:17:36,147 autoreload Watching for file changes with StatReloader
INFO 2025-01-16 02:17:52,861 autoreload C:\Users\Mihnea\Documents\Unibuc-FMI\2024-2025\Semestrul_1\Django\proiect\app_0\urls.py changed, reloading.
INFO 2025-01-16 02:17:53,300 autoreload Watching for file changes with StatReloader
WARNING 2025-01-16 02:18:02,070 log Not Found: /index/test_403
WARNING 2025-01-16 02:18:02,071 basehttp "GET /index/test_403 HTTP/1.1" 404 7175
INFO 2025-01-16 02:18:25,512 autoreload C:\Users\Mihnea\Documents\Unibuc-FMI\2024-2025\Semestrul_1\Django\proiect\app_0\views.py changed, reloading.
INFO 2025-01-16 02:18:25,937 autoreload Watching for file changes with StatReloader
INFO 2025-01-16 02:18:51,842 autoreload C:\Users\Mihnea\Documents\Unibuc-FMI\2024-2025\Semestrul_1\Django\proiect\proiect\urls.py changed, reloading.
INFO 2025-01-16 02:18:52,281 autoreload Watching for file changes with StatReloader
WARNING 2025-01-16 02:18:57,340 log Not Found: /index/test_403
WARNING 2025-01-16 02:18:57,340 basehttp "GET /index/test_403 HTTP/1.1" 404 7175
WARNING 2025-01-16 02:18:58,032 log Not Found: /index/test_403
WARNING 2025-01-16 02:18:58,033 basehttp "GET /index/test_403 HTTP/1.1" 404 7175
WARNING 2025-01-16 02:18:58,719 log Not Found: /index/test_403
WARNING 2025-01-16 02:18:58,720 basehttp "GET /index/test_403 HTTP/1.1" 404 7175
WARNING 2025-01-16 02:20:52,609 log Not Found: /aplicatieProj/confirmare_email/dd0c555c-f8d4-412c-b795-be23bf6f8d64/
WARNING 2025-01-16 02:20:52,610 basehttp "GET /aplicatieProj/confirmare_email/dd0c555c-f8d4-412c-b795-be23bf6f8d64/ HTTP/1.1" 404 3168
WARNING 2025-01-16 02:22:02,359 log Not Found: /index/test_403
WARNING 2025-01-16 02:22:02,359 basehttp "GET /index/test_403 HTTP/1.1" 404 7175
WARNING 2025-01-16 02:22:24,666 log Not Found: /test_403
WARNING 2025-01-16 02:22:24,667 basehttp "GET /test_403 HTTP/1.1" 404 2929
INFO 2025-01-16 02:22:47,188 autoreload C:\Users\Mihnea\Documents\Unibuc-FMI\2024-2025\Semestrul_1\Django\proiect\proiect\urls.py changed, reloading.
INFO 2025-01-16 02:22:47,614 autoreload Watching for file changes with StatReloader
WARNING 2025-01-16 02:22:50,001 log Not Found: /test_403
WARNING 2025-01-16 02:22:50,002 basehttp "GET /test_403 HTTP/1.1" 404 3081
WARNING 2025-01-16 02:23:05,865 log Not Found: /index/403
WARNING 2025-01-16 02:23:05,866 basehttp "GET /index/403 HTTP/1.1" 404 7307
WARNING 2025-01-16 02:23:18,400 log Not Found: /index/403
WARNING 2025-01-16 02:23:18,401 basehttp "GET /index/403 HTTP/1.1" 404 7307
WARNING 2025-01-16 02:23:23,849 log Not Found: /index/test_403
WARNING 2025-01-16 02:23:23,850 basehttp "GET /index/test_403 HTTP/1.1" 404 7327
INFO 2025-01-16 02:23:34,262 autoreload C:\Users\Mihnea\Documents\Unibuc-FMI\2024-2025\Semestrul_1\Django\proiect\proiect\urls.py changed, reloading.
INFO 2025-01-16 02:23:34,690 autoreload Watching for file changes with StatReloader
WARNING 2025-01-16 02:23:37,669 log Not Found: /index/test_403
WARNING 2025-01-16 02:23:37,670 basehttp "GET /index/test_403 HTTP/1.1" 404 7175
WARNING 2025-01-16 02:23:38,376 log Not Found: /index/test_403
WARNING 2025-01-16 02:23:38,376 basehttp "GET /index/test_403 HTTP/1.1" 404 7175
INFO 2025-01-16 02:24:45,724 autoreload C:\Users\Mihnea\Documents\Unibuc-FMI\2024-2025\Semestrul_1\Django\proiect\app_0\urls.py changed, reloading.
INFO 2025-01-16 02:24:46,139 autoreload Watching for file changes with StatReloader
INFO 2025-01-16 02:24:49,410 autoreload C:\Users\Mihnea\Documents\Unibuc-FMI\2024-2025\Semestrul_1\Django\proiect\app_0\urls.py changed, reloading.
INFO 2025-01-16 02:24:49,818 autoreload Watching for file changes with StatReloader
INFO 2025-01-16 02:24:57,315 autoreload C:\Users\Mihnea\Documents\Unibuc-FMI\2024-2025\Semestrul_1\Django\proiect\app_0\views.py changed, reloading.
INFO 2025-01-16 02:24:57,735 autoreload Watching for file changes with StatReloader
WARNING 2025-01-16 02:25:05,979 log Not Found: /index/test_403
WARNING 2025-01-16 02:25:05,980 basehttp "GET /index/test_403 HTTP/1.1" 404 7175
INFO 2025-01-16 02:25:27,849 autoreload C:\Users\Mihnea\Documents\Unibuc-FMI\2024-2025\Semestrul_1\Django\proiect\proiect\urls.py changed, reloading.
INFO 2025-01-16 02:25:28,281 autoreload Watching for file changes with StatReloader
INFO 2025-01-16 02:25:28,760 basehttp "GET /index/test_403 HTTP/1.1" 301 0
ERROR 2025-01-16 02:25:29,096 log Internal Server Error: /index/test_403/
Traceback (most recent call last):
  File "C:\Users\Mihnea\AppData\Local\Programs\Python\Python312\Lib\site-packages\django\core\handlers\exception.py", line 55, in inner
    response = get_response(request)
               ^^^^^^^^^^^^^^^^^^^^^
  File "C:\Users\Mihnea\AppData\Local\Programs\Python\Python312\Lib\site-packages\django\core\handlers\base.py", line 197, in _get_response
    response = wrapped_callback(request, *callback_args, **callback_kwargs)
               ^^^^^^^^^^^^^^^^^^^^^^^^^^^^^^^^^^^^^^^^^^^^^^^^^^^^^^^^^^^^
TypeError: custom_403_view() missing 1 required positional argument: 'exception'
ERROR 2025-01-16 02:25:29,097 basehttp "GET /index/test_403/ HTTP/1.1" 500 65677
INFO 2025-01-16 02:25:42,592 basehttp "GET /index/register/ HTTP/1.1" 200 2486
INFO 2025-01-16 02:26:00,835 views New user registered: 1234
INFO 2025-01-16 02:26:00,841 basehttp "POST /index/register/ HTTP/1.1" 302 0
INFO 2025-01-16 02:26:00,850 basehttp "GET /index/login/ HTTP/1.1" 200 865
INFO 2025-01-16 02:26:06,937 basehttp "GET /index/confirma_mail/6a3da309-6178-408a-ab85-0c634be9c29d/ HTTP/1.1" 200 245
INFO 2025-01-16 02:26:09,431 basehttp "GET /index/login/ HTTP/1.1" 200 865
INFO 2025-01-16 02:26:26,247 autoreload C:\Users\Mihnea\Documents\Unibuc-FMI\2024-2025\Semestrul_1\Django\proiect\app_0\views.py changed, reloading.
INFO 2025-01-16 02:26:26,696 autoreload Watching for file changes with StatReloader
INFO 2025-01-16 02:26:37,285 autoreload C:\Users\Mihnea\Documents\Unibuc-FMI\2024-2025\Semestrul_1\Django\proiect\app_0\urls.py changed, reloading.
INFO 2025-01-16 02:26:37,724 autoreload Watching for file changes with StatReloader
WARNING 2025-01-16 02:26:38,420 log Forbidden (Permission denied): /index/test_403/
Traceback (most recent call last):
  File "C:\Users\Mihnea\AppData\Local\Programs\Python\Python312\Lib\site-packages\django\core\handlers\exception.py", line 55, in inner
    response = get_response(request)
               ^^^^^^^^^^^^^^^^^^^^^
  File "C:\Users\Mihnea\AppData\Local\Programs\Python\Python312\Lib\site-packages\django\core\handlers\base.py", line 197, in _get_response
    response = wrapped_callback(request, *callback_args, **callback_kwargs)
               ^^^^^^^^^^^^^^^^^^^^^^^^^^^^^^^^^^^^^^^^^^^^^^^^^^^^^^^^^^^^
  File "C:\Users\Mihnea\Documents\Unibuc-FMI\2024-2025\Semestrul_1\Django\proiect\app_0\views.py", line 267, in test_403
    raise PermissionDenied("You do not have permission to access this resource.")
django.core.exceptions.PermissionDenied: You do not have permission to access this resource.
WARNING 2025-01-16 02:26:38,422 basehttp "GET /index/test_403/ HTTP/1.1" 403 135
INFO 2025-01-16 02:26:58,541 autoreload C:\Users\Mihnea\Documents\Unibuc-FMI\2024-2025\Semestrul_1\Django\proiect\app_0\urls.py changed, reloading.
INFO 2025-01-16 02:26:58,964 autoreload Watching for file changes with StatReloader
INFO 2025-01-16 02:27:03,418 autoreload C:\Users\Mihnea\Documents\Unibuc-FMI\2024-2025\Semestrul_1\Django\proiect\app_0\views.py changed, reloading.
INFO 2025-01-16 02:27:03,829 autoreload Watching for file changes with StatReloader
ERROR 2025-01-16 02:27:06,166 log Internal Server Error: /index/test_403/
Traceback (most recent call last):
  File "C:\Users\Mihnea\AppData\Local\Programs\Python\Python312\Lib\site-packages\django\core\handlers\exception.py", line 55, in inner
    response = get_response(request)
               ^^^^^^^^^^^^^^^^^^^^^
  File "C:\Users\Mihnea\AppData\Local\Programs\Python\Python312\Lib\site-packages\django\core\handlers\base.py", line 197, in _get_response
    response = wrapped_callback(request, *callback_args, **callback_kwargs)
               ^^^^^^^^^^^^^^^^^^^^^^^^^^^^^^^^^^^^^^^^^^^^^^^^^^^^^^^^^^^^
TypeError: custom_403_view() missing 1 required positional argument: 'exception'
ERROR 2025-01-16 02:27:06,167 basehttp "GET /index/test_403/ HTTP/1.1" 500 65677
INFO 2025-01-16 02:27:48,235 autoreload C:\Users\Mihnea\Documents\Unibuc-FMI\2024-2025\Semestrul_1\Django\proiect\proiect\urls.py changed, reloading.
INFO 2025-01-16 02:27:48,665 autoreload Watching for file changes with StatReloader
ERROR 2025-01-16 02:27:50,405 log Internal Server Error: /index/test_403/
Traceback (most recent call last):
  File "C:\Users\Mihnea\AppData\Local\Programs\Python\Python312\Lib\site-packages\django\core\handlers\exception.py", line 55, in inner
    response = get_response(request)
               ^^^^^^^^^^^^^^^^^^^^^
  File "C:\Users\Mihnea\AppData\Local\Programs\Python\Python312\Lib\site-packages\django\core\handlers\base.py", line 197, in _get_response
    response = wrapped_callback(request, *callback_args, **callback_kwargs)
               ^^^^^^^^^^^^^^^^^^^^^^^^^^^^^^^^^^^^^^^^^^^^^^^^^^^^^^^^^^^^
TypeError: custom_403_view() missing 1 required positional argument: 'exception'
ERROR 2025-01-16 02:27:50,407 basehttp "GET /index/test_403/ HTTP/1.1" 500 65677
ERROR 2025-01-16 02:27:51,450 log Internal Server Error: /index/test_403/
Traceback (most recent call last):
  File "C:\Users\Mihnea\AppData\Local\Programs\Python\Python312\Lib\site-packages\django\core\handlers\exception.py", line 55, in inner
    response = get_response(request)
               ^^^^^^^^^^^^^^^^^^^^^
  File "C:\Users\Mihnea\AppData\Local\Programs\Python\Python312\Lib\site-packages\django\core\handlers\base.py", line 197, in _get_response
    response = wrapped_callback(request, *callback_args, **callback_kwargs)
               ^^^^^^^^^^^^^^^^^^^^^^^^^^^^^^^^^^^^^^^^^^^^^^^^^^^^^^^^^^^^
TypeError: custom_403_view() missing 1 required positional argument: 'exception'
ERROR 2025-01-16 02:27:51,451 basehttp "GET /index/test_403/ HTTP/1.1" 500 65677
INFO 2025-01-16 02:29:01,733 autoreload C:\Users\Mihnea\Documents\Unibuc-FMI\2024-2025\Semestrul_1\Django\proiect\app_0\views.py changed, reloading.
INFO 2025-01-16 02:29:02,183 autoreload Watching for file changes with StatReloader
INFO 2025-01-16 02:29:07,685 autoreload C:\Users\Mihnea\Documents\Unibuc-FMI\2024-2025\Semestrul_1\Django\proiect\proiect\urls.py changed, reloading.
INFO 2025-01-16 02:29:08,126 autoreload Watching for file changes with StatReloader
ERROR 2025-01-16 02:29:09,101 log Internal Server Error: /index/test_403/
Traceback (most recent call last):
  File "C:\Users\Mihnea\AppData\Local\Programs\Python\Python312\Lib\site-packages\django\core\handlers\exception.py", line 55, in inner
    response = get_response(request)
               ^^^^^^^^^^^^^^^^^^^^^
  File "C:\Users\Mihnea\AppData\Local\Programs\Python\Python312\Lib\site-packages\django\core\handlers\base.py", line 197, in _get_response
    response = wrapped_callback(request, *callback_args, **callback_kwargs)
               ^^^^^^^^^^^^^^^^^^^^^^^^^^^^^^^^^^^^^^^^^^^^^^^^^^^^^^^^^^^^
TypeError: custom_403_view() missing 1 required positional argument: 'exception'
ERROR 2025-01-16 02:29:09,102 basehttp "GET /index/test_403/ HTTP/1.1" 500 65677
ERROR 2025-01-16 02:29:11,100 log Internal Server Error: /index/test_403/
Traceback (most recent call last):
  File "C:\Users\Mihnea\AppData\Local\Programs\Python\Python312\Lib\site-packages\django\core\handlers\exception.py", line 55, in inner
    response = get_response(request)
               ^^^^^^^^^^^^^^^^^^^^^
  File "C:\Users\Mihnea\AppData\Local\Programs\Python\Python312\Lib\site-packages\django\core\handlers\base.py", line 197, in _get_response
    response = wrapped_callback(request, *callback_args, **callback_kwargs)
               ^^^^^^^^^^^^^^^^^^^^^^^^^^^^^^^^^^^^^^^^^^^^^^^^^^^^^^^^^^^^
TypeError: custom_403_view() missing 1 required positional argument: 'exception'
ERROR 2025-01-16 02:29:11,101 basehttp "GET /index/test_403/ HTTP/1.1" 500 65677
INFO 2025-01-16 02:29:26,908 autoreload C:\Users\Mihnea\Documents\Unibuc-FMI\2024-2025\Semestrul_1\Django\proiect\app_0\urls.py changed, reloading.
INFO 2025-01-16 02:29:27,347 autoreload Watching for file changes with StatReloader
WARNING 2025-01-16 02:29:32,280 log Not Found: /aplicatieProj/confirmare_email/2b62740a-58b2-4a2c-adca-a3157fa76739/
WARNING 2025-01-16 02:29:32,281 basehttp "GET /aplicatieProj/confirmare_email/2b62740a-58b2-4a2c-adca-a3157fa76739/ HTTP/1.1" 404 2702
ERROR 2025-01-16 02:29:48,975 log Forbidden (Permission denied): /index/test_403/
Traceback (most recent call last):
  File "C:\Users\Mihnea\AppData\Local\Programs\Python\Python312\Lib\site-packages\django\core\handlers\exception.py", line 55, in inner
    response = get_response(request)
               ^^^^^^^^^^^^^^^^^^^^^
  File "C:\Users\Mihnea\AppData\Local\Programs\Python\Python312\Lib\site-packages\django\core\handlers\base.py", line 197, in _get_response
    response = wrapped_callback(request, *callback_args, **callback_kwargs)
               ^^^^^^^^^^^^^^^^^^^^^^^^^^^^^^^^^^^^^^^^^^^^^^^^^^^^^^^^^^^^
  File "C:\Users\Mihnea\Documents\Unibuc-FMI\2024-2025\Semestrul_1\Django\proiect\app_0\views.py", line 267, in test_403
    raise PermissionDenied("You do not have permission to access this resource.")
django.core.exceptions.PermissionDenied: You do not have permission to access this resource.
ERROR 2025-01-16 02:29:48,976 basehttp "GET /index/test_403/ HTTP/1.1" 500 92508
ERROR 2025-01-16 02:30:18,763 log Forbidden (Permission denied): /index/test_403/
Traceback (most recent call last):
  File "C:\Users\Mihnea\AppData\Local\Programs\Python\Python312\Lib\site-packages\django\core\handlers\exception.py", line 55, in inner
    response = get_response(request)
               ^^^^^^^^^^^^^^^^^^^^^
  File "C:\Users\Mihnea\AppData\Local\Programs\Python\Python312\Lib\site-packages\django\core\handlers\base.py", line 197, in _get_response
    response = wrapped_callback(request, *callback_args, **callback_kwargs)
               ^^^^^^^^^^^^^^^^^^^^^^^^^^^^^^^^^^^^^^^^^^^^^^^^^^^^^^^^^^^^
  File "C:\Users\Mihnea\Documents\Unibuc-FMI\2024-2025\Semestrul_1\Django\proiect\app_0\views.py", line 267, in test_403
    raise PermissionDenied("You do not have permission to access this resource.")
django.core.exceptions.PermissionDenied: You do not have permission to access this resource.
ERROR 2025-01-16 02:30:18,764 basehttp "GET /index/test_403/ HTTP/1.1" 500 92508
INFO 2025-01-16 02:30:30,351 autoreload C:\Users\Mihnea\Documents\Unibuc-FMI\2024-2025\Semestrul_1\Django\proiect\app_0\urls.py changed, reloading.
INFO 2025-01-16 02:30:30,809 autoreload Watching for file changes with StatReloader
ERROR 2025-01-16 02:30:31,150 log Forbidden (Permission denied): /index/test_403/
Traceback (most recent call last):
  File "C:\Users\Mihnea\AppData\Local\Programs\Python\Python312\Lib\site-packages\django\core\handlers\exception.py", line 55, in inner
    response = get_response(request)
               ^^^^^^^^^^^^^^^^^^^^^
  File "C:\Users\Mihnea\AppData\Local\Programs\Python\Python312\Lib\site-packages\django\core\handlers\base.py", line 197, in _get_response
    response = wrapped_callback(request, *callback_args, **callback_kwargs)
               ^^^^^^^^^^^^^^^^^^^^^^^^^^^^^^^^^^^^^^^^^^^^^^^^^^^^^^^^^^^^
  File "C:\Users\Mihnea\Documents\Unibuc-FMI\2024-2025\Semestrul_1\Django\proiect\app_0\views.py", line 267, in test_403
    raise PermissionDenied("You do not have permission to access this resource.")
django.core.exceptions.PermissionDenied: You do not have permission to access this resource.
ERROR 2025-01-16 02:30:31,151 basehttp "GET /index/test_403/ HTTP/1.1" 500 92508
ERROR 2025-01-16 02:30:32,500 log Forbidden (Permission denied): /index/test_403/
Traceback (most recent call last):
  File "C:\Users\Mihnea\AppData\Local\Programs\Python\Python312\Lib\site-packages\django\core\handlers\exception.py", line 55, in inner
    response = get_response(request)
               ^^^^^^^^^^^^^^^^^^^^^
  File "C:\Users\Mihnea\AppData\Local\Programs\Python\Python312\Lib\site-packages\django\core\handlers\base.py", line 197, in _get_response
    response = wrapped_callback(request, *callback_args, **callback_kwargs)
               ^^^^^^^^^^^^^^^^^^^^^^^^^^^^^^^^^^^^^^^^^^^^^^^^^^^^^^^^^^^^
  File "C:\Users\Mihnea\Documents\Unibuc-FMI\2024-2025\Semestrul_1\Django\proiect\app_0\views.py", line 267, in test_403
    raise PermissionDenied("You do not have permission to access this resource.")
django.core.exceptions.PermissionDenied: You do not have permission to access this resource.
ERROR 2025-01-16 02:30:32,502 basehttp "GET /index/test_403/ HTTP/1.1" 500 92508
ERROR 2025-01-16 02:30:33,417 log Forbidden (Permission denied): /index/test_403/
Traceback (most recent call last):
  File "C:\Users\Mihnea\AppData\Local\Programs\Python\Python312\Lib\site-packages\django\core\handlers\exception.py", line 55, in inner
    response = get_response(request)
               ^^^^^^^^^^^^^^^^^^^^^
  File "C:\Users\Mihnea\AppData\Local\Programs\Python\Python312\Lib\site-packages\django\core\handlers\base.py", line 197, in _get_response
    response = wrapped_callback(request, *callback_args, **callback_kwargs)
               ^^^^^^^^^^^^^^^^^^^^^^^^^^^^^^^^^^^^^^^^^^^^^^^^^^^^^^^^^^^^
  File "C:\Users\Mihnea\Documents\Unibuc-FMI\2024-2025\Semestrul_1\Django\proiect\app_0\views.py", line 267, in test_403
    raise PermissionDenied("You do not have permission to access this resource.")
django.core.exceptions.PermissionDenied: You do not have permission to access this resource.
ERROR 2025-01-16 02:30:33,418 basehttp "GET /index/test_403/ HTTP/1.1" 500 92508
ERROR 2025-01-16 02:30:46,842 log Forbidden (Permission denied): /index/test_403/
Traceback (most recent call last):
  File "C:\Users\Mihnea\AppData\Local\Programs\Python\Python312\Lib\site-packages\django\core\handlers\exception.py", line 55, in inner
    response = get_response(request)
               ^^^^^^^^^^^^^^^^^^^^^
  File "C:\Users\Mihnea\AppData\Local\Programs\Python\Python312\Lib\site-packages\django\core\handlers\base.py", line 197, in _get_response
    response = wrapped_callback(request, *callback_args, **callback_kwargs)
               ^^^^^^^^^^^^^^^^^^^^^^^^^^^^^^^^^^^^^^^^^^^^^^^^^^^^^^^^^^^^
  File "C:\Users\Mihnea\Documents\Unibuc-FMI\2024-2025\Semestrul_1\Django\proiect\app_0\views.py", line 267, in test_403
    raise PermissionDenied("You do not have permission to access this resource.")
django.core.exceptions.PermissionDenied: You do not have permission to access this resource.
ERROR 2025-01-16 02:30:46,843 basehttp "GET /index/test_403/ HTTP/1.1" 500 92508
ERROR 2025-01-16 02:30:47,626 log Forbidden (Permission denied): /index/test_403/
Traceback (most recent call last):
  File "C:\Users\Mihnea\AppData\Local\Programs\Python\Python312\Lib\site-packages\django\core\handlers\exception.py", line 55, in inner
    response = get_response(request)
               ^^^^^^^^^^^^^^^^^^^^^
  File "C:\Users\Mihnea\AppData\Local\Programs\Python\Python312\Lib\site-packages\django\core\handlers\base.py", line 197, in _get_response
    response = wrapped_callback(request, *callback_args, **callback_kwargs)
               ^^^^^^^^^^^^^^^^^^^^^^^^^^^^^^^^^^^^^^^^^^^^^^^^^^^^^^^^^^^^
  File "C:\Users\Mihnea\Documents\Unibuc-FMI\2024-2025\Semestrul_1\Django\proiect\app_0\views.py", line 267, in test_403
    raise PermissionDenied("You do not have permission to access this resource.")
django.core.exceptions.PermissionDenied: You do not have permission to access this resource.
ERROR 2025-01-16 02:30:47,628 basehttp "GET /index/test_403/ HTTP/1.1" 500 92508
ERROR 2025-01-16 02:30:48,119 log Forbidden (Permission denied): /index/test_403/
Traceback (most recent call last):
  File "C:\Users\Mihnea\AppData\Local\Programs\Python\Python312\Lib\site-packages\django\core\handlers\exception.py", line 55, in inner
    response = get_response(request)
               ^^^^^^^^^^^^^^^^^^^^^
  File "C:\Users\Mihnea\AppData\Local\Programs\Python\Python312\Lib\site-packages\django\core\handlers\base.py", line 197, in _get_response
    response = wrapped_callback(request, *callback_args, **callback_kwargs)
               ^^^^^^^^^^^^^^^^^^^^^^^^^^^^^^^^^^^^^^^^^^^^^^^^^^^^^^^^^^^^
  File "C:\Users\Mihnea\Documents\Unibuc-FMI\2024-2025\Semestrul_1\Django\proiect\app_0\views.py", line 267, in test_403
    raise PermissionDenied("You do not have permission to access this resource.")
django.core.exceptions.PermissionDenied: You do not have permission to access this resource.
ERROR 2025-01-16 02:30:48,120 basehttp "GET /index/test_403/ HTTP/1.1" 500 92508
ERROR 2025-01-16 02:30:48,416 log Forbidden (Permission denied): /index/test_403/
Traceback (most recent call last):
  File "C:\Users\Mihnea\AppData\Local\Programs\Python\Python312\Lib\site-packages\django\core\handlers\exception.py", line 55, in inner
    response = get_response(request)
               ^^^^^^^^^^^^^^^^^^^^^
  File "C:\Users\Mihnea\AppData\Local\Programs\Python\Python312\Lib\site-packages\django\core\handlers\base.py", line 197, in _get_response
    response = wrapped_callback(request, *callback_args, **callback_kwargs)
               ^^^^^^^^^^^^^^^^^^^^^^^^^^^^^^^^^^^^^^^^^^^^^^^^^^^^^^^^^^^^
  File "C:\Users\Mihnea\Documents\Unibuc-FMI\2024-2025\Semestrul_1\Django\proiect\app_0\views.py", line 267, in test_403
    raise PermissionDenied("You do not have permission to access this resource.")
django.core.exceptions.PermissionDenied: You do not have permission to access this resource.
ERROR 2025-01-16 02:30:48,417 basehttp "GET /index/test_403/ HTTP/1.1" 500 92508
INFO 2025-01-16 02:32:01,127 autoreload C:\Users\Mihnea\Documents\Unibuc-FMI\2024-2025\Semestrul_1\Django\proiect\proiect\settings.py changed, reloading.
INFO 2025-01-16 02:32:01,567 autoreload Watching for file changes with StatReloader
ERROR 2025-01-16 02:32:04,073 log Forbidden (Permission denied): /index/test_403/
Traceback (most recent call last):
  File "C:\Users\Mihnea\AppData\Local\Programs\Python\Python312\Lib\site-packages\django\core\handlers\exception.py", line 55, in inner
    response = get_response(request)
               ^^^^^^^^^^^^^^^^^^^^^
  File "C:\Users\Mihnea\AppData\Local\Programs\Python\Python312\Lib\site-packages\django\core\handlers\base.py", line 197, in _get_response
    response = wrapped_callback(request, *callback_args, **callback_kwargs)
               ^^^^^^^^^^^^^^^^^^^^^^^^^^^^^^^^^^^^^^^^^^^^^^^^^^^^^^^^^^^^
  File "C:\Users\Mihnea\Documents\Unibuc-FMI\2024-2025\Semestrul_1\Django\proiect\app_0\views.py", line 267, in test_403
    raise PermissionDenied("You do not have permission to access this resource.")
django.core.exceptions.PermissionDenied: You do not have permission to access this resource.
ERROR 2025-01-16 02:32:04,075 basehttp "GET /index/test_403/ HTTP/1.1" 500 92508
