INFO 2025-01-16 02:08:00,507 autoreload Watching for file changes with StatReloader
ERROR 2025-01-16 02:08:02,670 views Login failed for username: Velcq
INFO 2025-01-16 02:08:02,680 basehttp "POST /index/login/ HTTP/1.1" 200 1022
ERROR 2025-01-16 02:08:04,914 views Login failed for username: Velcq
INFO 2025-01-16 02:08:04,916 basehttp "POST /index/login/ HTTP/1.1" 200 1022
ERROR 2025-01-16 02:08:06,869 views Login failed for username: Velcq
INFO 2025-01-16 02:08:06,871 basehttp "POST /index/login/ HTTP/1.1" 200 1022
WARNING 2025-01-16 02:08:09,658 views Suspicious login attempts for username: Velcq from IP: 127.0.0.1
ERROR 2025-01-16 02:08:10,162 views Login failed for username: Velcq
INFO 2025-01-16 02:08:10,167 basehttp "POST /index/login/ HTTP/1.1" 200 1022
INFO 2025-01-16 02:08:30,610 basehttp "GET /index/register/ HTTP/1.1" 200 2486
ERROR 2025-01-16 02:08:50,592 log Internal Server Error: /index/register/
Traceback (most recent call last):
  File "C:\Users\Mihnea\AppData\Local\Programs\Python\Python312\Lib\site-packages\django\core\handlers\exception.py", line 55, in inner
    response = get_response(request)
               ^^^^^^^^^^^^^^^^^^^^^
  File "C:\Users\Mihnea\AppData\Local\Programs\Python\Python312\Lib\site-packages\django\core\handlers\base.py", line 197, in _get_response
    response = wrapped_callback(request, *callback_args, **callback_kwargs)
               ^^^^^^^^^^^^^^^^^^^^^^^^^^^^^^^^^^^^^^^^^^^^^^^^^^^^^^^^^^^^
  File "C:\Users\Mihnea\Documents\Unibuc-FMI\2024-2025\Semestrul_1\Django\proiect\app_0\views.py", line 103, in register
    messages.error(request, 'This username is not allowed.')
    ^^^^^^^^^^^^^^
AttributeError: 'dict' object has no attribute 'error'
ERROR 2025-01-16 02:08:50,594 basehttp "POST /index/register/ HTTP/1.1" 500 72624
INFO 2025-01-16 02:10:19,540 autoreload Watching for file changes with StatReloader
CRITICAL 2025-01-16 02:10:23,377 views Attempt to register with username 'admin' from email: mihneave2004@gmail.com
INFO 2025-01-16 02:10:23,383 basehttp "POST /index/register/ HTTP/1.1" 302 0
INFO 2025-01-16 02:10:23,401 basehttp "GET /index/register/ HTTP/1.1" 200 2486
CRITICAL 2025-01-16 02:10:48,526 views Attempt to register with username 'admin' from email: mihneave2004@gmail.com
INFO 2025-01-16 02:10:48,527 basehttp "POST /index/register/ HTTP/1.1" 302 0
INFO 2025-01-16 02:10:48,538 basehttp "GET /index/register/ HTTP/1.1" 200 2486
WARNING 2025-01-16 02:12:22,795 log Not Found: /index/recent_purchases
WARNING 2025-01-16 02:12:22,796 basehttp "GET /index/recent_purchases HTTP/1.1" 404 6942
ERROR 2025-01-16 02:12:40,584 views Login failed for username: Velcq
INFO 2025-01-16 02:12:40,588 basehttp "POST /index/login/ HTTP/1.1" 200 1022
INFO 2025-01-16 02:12:46,929 basehttp "POST /index/login/ HTTP/1.1" 302 0
INFO 2025-01-16 02:12:46,992 basehttp "GET /index/profile/ HTTP/1.1" 200 791
WARNING 2025-01-16 02:12:59,777 log Not Found: /index/recent_purchases
WARNING 2025-01-16 02:12:59,777 basehttp "GET /index/recent_purchases HTTP/1.1" 404 6942
WARNING 2025-01-16 02:13:03,856 log Not Found: /index/recent_purchases/Velcq
WARNING 2025-01-16 02:13:03,856 basehttp "GET /index/recent_purchases/Velcq HTTP/1.1" 404 6966
INFO 2025-01-16 02:13:53,252 basehttp "GET /index/bilete/ HTTP/1.1" 200 4418
INFO 2025-01-16 02:13:54,832 basehttp "POST /index/cumpara-bilet/1/ HTTP/1.1" 302 0
INFO 2025-01-16 02:13:54,902 basehttp "GET /index/bilete/ HTTP/1.1" 200 4418
INFO 2025-01-16 02:13:56,505 basehttp "POST /index/cumpara-bilet/2/ HTTP/1.1" 302 0
INFO 2025-01-16 02:13:56,577 basehttp "GET /index/bilete/ HTTP/1.1" 200 4418
INFO 2025-01-16 02:13:59,108 basehttp "POST /index/cumpara-bilet/3/ HTTP/1.1" 302 0
INFO 2025-01-16 02:13:59,205 basehttp "GET /index/bilete/ HTTP/1.1" 200 4418
WARNING 2025-01-16 02:14:08,031 log Not Found: /index/recent_purchases
WARNING 2025-01-16 02:14:08,032 basehttp "GET /index/recent_purchases HTTP/1.1" 404 6942
CRITICAL 2025-01-16 02:14:24,191 views An error occurred: Cannot resolve keyword 'user' into field. Choices are: cursa, cursa_id, id, loc, pret, vagon, vagon_id, vizualizare
ERROR 2025-01-16 02:14:24,191 log Internal Server Error: /index/recent_purchases/
ERROR 2025-01-16 02:14:24,192 basehttp "GET /index/recent_purchases/ HTTP/1.1" 500 18
INFO 2025-01-16 02:17:35,697 autoreload C:\Users\Mihnea\Documents\Unibuc-FMI\2024-2025\Semestrul_1\Django\proiect\app_0\views.py changed, reloading.
INFO 2025-01-16 02:17:36,147 autoreload Watching for file changes with StatReloader
INFO 2025-01-16 02:17:52,861 autoreload C:\Users\Mihnea\Documents\Unibuc-FMI\2024-2025\Semestrul_1\Django\proiect\app_0\urls.py changed, reloading.
INFO 2025-01-16 02:17:53,300 autoreload Watching for file changes with StatReloader
WARNING 2025-01-16 02:18:02,070 log Not Found: /index/test_403
WARNING 2025-01-16 02:18:02,071 basehttp "GET /index/test_403 HTTP/1.1" 404 7175
INFO 2025-01-16 02:18:25,512 autoreload C:\Users\Mihnea\Documents\Unibuc-FMI\2024-2025\Semestrul_1\Django\proiect\app_0\views.py changed, reloading.
INFO 2025-01-16 02:18:25,937 autoreload Watching for file changes with StatReloader
INFO 2025-01-16 02:18:51,842 autoreload C:\Users\Mihnea\Documents\Unibuc-FMI\2024-2025\Semestrul_1\Django\proiect\proiect\urls.py changed, reloading.
INFO 2025-01-16 02:18:52,281 autoreload Watching for file changes with StatReloader
WARNING 2025-01-16 02:18:57,340 log Not Found: /index/test_403
WARNING 2025-01-16 02:18:57,340 basehttp "GET /index/test_403 HTTP/1.1" 404 7175
WARNING 2025-01-16 02:18:58,032 log Not Found: /index/test_403
WARNING 2025-01-16 02:18:58,033 basehttp "GET /index/test_403 HTTP/1.1" 404 7175
WARNING 2025-01-16 02:18:58,719 log Not Found: /index/test_403
WARNING 2025-01-16 02:18:58,720 basehttp "GET /index/test_403 HTTP/1.1" 404 7175
WARNING 2025-01-16 02:20:52,609 log Not Found: /aplicatieProj/confirmare_email/dd0c555c-f8d4-412c-b795-be23bf6f8d64/
WARNING 2025-01-16 02:20:52,610 basehttp "GET /aplicatieProj/confirmare_email/dd0c555c-f8d4-412c-b795-be23bf6f8d64/ HTTP/1.1" 404 3168
WARNING 2025-01-16 02:22:02,359 log Not Found: /index/test_403
WARNING 2025-01-16 02:22:02,359 basehttp "GET /index/test_403 HTTP/1.1" 404 7175
WARNING 2025-01-16 02:22:24,666 log Not Found: /test_403
WARNING 2025-01-16 02:22:24,667 basehttp "GET /test_403 HTTP/1.1" 404 2929
INFO 2025-01-16 02:22:47,188 autoreload C:\Users\Mihnea\Documents\Unibuc-FMI\2024-2025\Semestrul_1\Django\proiect\proiect\urls.py changed, reloading.
INFO 2025-01-16 02:22:47,614 autoreload Watching for file changes with StatReloader
WARNING 2025-01-16 02:22:50,001 log Not Found: /test_403
WARNING 2025-01-16 02:22:50,002 basehttp "GET /test_403 HTTP/1.1" 404 3081
WARNING 2025-01-16 02:23:05,865 log Not Found: /index/403
WARNING 2025-01-16 02:23:05,866 basehttp "GET /index/403 HTTP/1.1" 404 7307
WARNING 2025-01-16 02:23:18,400 log Not Found: /index/403
WARNING 2025-01-16 02:23:18,401 basehttp "GET /index/403 HTTP/1.1" 404 7307
WARNING 2025-01-16 02:23:23,849 log Not Found: /index/test_403
WARNING 2025-01-16 02:23:23,850 basehttp "GET /index/test_403 HTTP/1.1" 404 7327
INFO 2025-01-16 02:23:34,262 autoreload C:\Users\Mihnea\Documents\Unibuc-FMI\2024-2025\Semestrul_1\Django\proiect\proiect\urls.py changed, reloading.
INFO 2025-01-16 02:23:34,690 autoreload Watching for file changes with StatReloader
WARNING 2025-01-16 02:23:37,669 log Not Found: /index/test_403
WARNING 2025-01-16 02:23:37,670 basehttp "GET /index/test_403 HTTP/1.1" 404 7175
WARNING 2025-01-16 02:23:38,376 log Not Found: /index/test_403
WARNING 2025-01-16 02:23:38,376 basehttp "GET /index/test_403 HTTP/1.1" 404 7175
INFO 2025-01-16 02:24:45,724 autoreload C:\Users\Mihnea\Documents\Unibuc-FMI\2024-2025\Semestrul_1\Django\proiect\app_0\urls.py changed, reloading.
INFO 2025-01-16 02:24:46,139 autoreload Watching for file changes with StatReloader
INFO 2025-01-16 02:24:49,410 autoreload C:\Users\Mihnea\Documents\Unibuc-FMI\2024-2025\Semestrul_1\Django\proiect\app_0\urls.py changed, reloading.
INFO 2025-01-16 02:24:49,818 autoreload Watching for file changes with StatReloader
INFO 2025-01-16 02:24:57,315 autoreload C:\Users\Mihnea\Documents\Unibuc-FMI\2024-2025\Semestrul_1\Django\proiect\app_0\views.py changed, reloading.
INFO 2025-01-16 02:24:57,735 autoreload Watching for file changes with StatReloader
WARNING 2025-01-16 02:25:05,979 log Not Found: /index/test_403
WARNING 2025-01-16 02:25:05,980 basehttp "GET /index/test_403 HTTP/1.1" 404 7175
INFO 2025-01-16 02:25:27,849 autoreload C:\Users\Mihnea\Documents\Unibuc-FMI\2024-2025\Semestrul_1\Django\proiect\proiect\urls.py changed, reloading.
INFO 2025-01-16 02:25:28,281 autoreload Watching for file changes with StatReloader
INFO 2025-01-16 02:25:28,760 basehttp "GET /index/test_403 HTTP/1.1" 301 0
ERROR 2025-01-16 02:25:29,096 log Internal Server Error: /index/test_403/
Traceback (most recent call last):
  File "C:\Users\Mihnea\AppData\Local\Programs\Python\Python312\Lib\site-packages\django\core\handlers\exception.py", line 55, in inner
    response = get_response(request)
               ^^^^^^^^^^^^^^^^^^^^^
  File "C:\Users\Mihnea\AppData\Local\Programs\Python\Python312\Lib\site-packages\django\core\handlers\base.py", line 197, in _get_response
    response = wrapped_callback(request, *callback_args, **callback_kwargs)
               ^^^^^^^^^^^^^^^^^^^^^^^^^^^^^^^^^^^^^^^^^^^^^^^^^^^^^^^^^^^^
TypeError: custom_403_view() missing 1 required positional argument: 'exception'
ERROR 2025-01-16 02:25:29,097 basehttp "GET /index/test_403/ HTTP/1.1" 500 65677
INFO 2025-01-16 02:25:42,592 basehttp "GET /index/register/ HTTP/1.1" 200 2486
INFO 2025-01-16 02:26:00,835 views New user registered: 1234
INFO 2025-01-16 02:26:00,841 basehttp "POST /index/register/ HTTP/1.1" 302 0
INFO 2025-01-16 02:26:00,850 basehttp "GET /index/login/ HTTP/1.1" 200 865
INFO 2025-01-16 02:26:06,937 basehttp "GET /index/confirma_mail/6a3da309-6178-408a-ab85-0c634be9c29d/ HTTP/1.1" 200 245
INFO 2025-01-16 02:26:09,431 basehttp "GET /index/login/ HTTP/1.1" 200 865
INFO 2025-01-16 02:26:26,247 autoreload C:\Users\Mihnea\Documents\Unibuc-FMI\2024-2025\Semestrul_1\Django\proiect\app_0\views.py changed, reloading.
INFO 2025-01-16 02:26:26,696 autoreload Watching for file changes with StatReloader
INFO 2025-01-16 02:26:37,285 autoreload C:\Users\Mihnea\Documents\Unibuc-FMI\2024-2025\Semestrul_1\Django\proiect\app_0\urls.py changed, reloading.
INFO 2025-01-16 02:26:37,724 autoreload Watching for file changes with StatReloader
WARNING 2025-01-16 02:26:38,420 log Forbidden (Permission denied): /index/test_403/
Traceback (most recent call last):
  File "C:\Users\Mihnea\AppData\Local\Programs\Python\Python312\Lib\site-packages\django\core\handlers\exception.py", line 55, in inner
    response = get_response(request)
               ^^^^^^^^^^^^^^^^^^^^^
  File "C:\Users\Mihnea\AppData\Local\Programs\Python\Python312\Lib\site-packages\django\core\handlers\base.py", line 197, in _get_response
    response = wrapped_callback(request, *callback_args, **callback_kwargs)
               ^^^^^^^^^^^^^^^^^^^^^^^^^^^^^^^^^^^^^^^^^^^^^^^^^^^^^^^^^^^^
  File "C:\Users\Mihnea\Documents\Unibuc-FMI\2024-2025\Semestrul_1\Django\proiect\app_0\views.py", line 267, in test_403
    raise PermissionDenied("You do not have permission to access this resource.")
django.core.exceptions.PermissionDenied: You do not have permission to access this resource.
WARNING 2025-01-16 02:26:38,422 basehttp "GET /index/test_403/ HTTP/1.1" 403 135
INFO 2025-01-16 02:26:58,541 autoreload C:\Users\Mihnea\Documents\Unibuc-FMI\2024-2025\Semestrul_1\Django\proiect\app_0\urls.py changed, reloading.
INFO 2025-01-16 02:26:58,964 autoreload Watching for file changes with StatReloader
INFO 2025-01-16 02:27:03,418 autoreload C:\Users\Mihnea\Documents\Unibuc-FMI\2024-2025\Semestrul_1\Django\proiect\app_0\views.py changed, reloading.
INFO 2025-01-16 02:27:03,829 autoreload Watching for file changes with StatReloader
ERROR 2025-01-16 02:27:06,166 log Internal Server Error: /index/test_403/
Traceback (most recent call last):
  File "C:\Users\Mihnea\AppData\Local\Programs\Python\Python312\Lib\site-packages\django\core\handlers\exception.py", line 55, in inner
    response = get_response(request)
               ^^^^^^^^^^^^^^^^^^^^^
  File "C:\Users\Mihnea\AppData\Local\Programs\Python\Python312\Lib\site-packages\django\core\handlers\base.py", line 197, in _get_response
    response = wrapped_callback(request, *callback_args, **callback_kwargs)
               ^^^^^^^^^^^^^^^^^^^^^^^^^^^^^^^^^^^^^^^^^^^^^^^^^^^^^^^^^^^^
TypeError: custom_403_view() missing 1 required positional argument: 'exception'
ERROR 2025-01-16 02:27:06,167 basehttp "GET /index/test_403/ HTTP/1.1" 500 65677
INFO 2025-01-16 02:27:48,235 autoreload C:\Users\Mihnea\Documents\Unibuc-FMI\2024-2025\Semestrul_1\Django\proiect\proiect\urls.py changed, reloading.
INFO 2025-01-16 02:27:48,665 autoreload Watching for file changes with StatReloader
ERROR 2025-01-16 02:27:50,405 log Internal Server Error: /index/test_403/
Traceback (most recent call last):
  File "C:\Users\Mihnea\AppData\Local\Programs\Python\Python312\Lib\site-packages\django\core\handlers\exception.py", line 55, in inner
    response = get_response(request)
               ^^^^^^^^^^^^^^^^^^^^^
  File "C:\Users\Mihnea\AppData\Local\Programs\Python\Python312\Lib\site-packages\django\core\handlers\base.py", line 197, in _get_response
    response = wrapped_callback(request, *callback_args, **callback_kwargs)
               ^^^^^^^^^^^^^^^^^^^^^^^^^^^^^^^^^^^^^^^^^^^^^^^^^^^^^^^^^^^^
TypeError: custom_403_view() missing 1 required positional argument: 'exception'
ERROR 2025-01-16 02:27:50,407 basehttp "GET /index/test_403/ HTTP/1.1" 500 65677
ERROR 2025-01-16 02:27:51,450 log Internal Server Error: /index/test_403/
Traceback (most recent call last):
  File "C:\Users\Mihnea\AppData\Local\Programs\Python\Python312\Lib\site-packages\django\core\handlers\exception.py", line 55, in inner
    response = get_response(request)
               ^^^^^^^^^^^^^^^^^^^^^
  File "C:\Users\Mihnea\AppData\Local\Programs\Python\Python312\Lib\site-packages\django\core\handlers\base.py", line 197, in _get_response
    response = wrapped_callback(request, *callback_args, **callback_kwargs)
               ^^^^^^^^^^^^^^^^^^^^^^^^^^^^^^^^^^^^^^^^^^^^^^^^^^^^^^^^^^^^
TypeError: custom_403_view() missing 1 required positional argument: 'exception'
ERROR 2025-01-16 02:27:51,451 basehttp "GET /index/test_403/ HTTP/1.1" 500 65677
INFO 2025-01-16 02:29:01,733 autoreload C:\Users\Mihnea\Documents\Unibuc-FMI\2024-2025\Semestrul_1\Django\proiect\app_0\views.py changed, reloading.
INFO 2025-01-16 02:29:02,183 autoreload Watching for file changes with StatReloader
INFO 2025-01-16 02:29:07,685 autoreload C:\Users\Mihnea\Documents\Unibuc-FMI\2024-2025\Semestrul_1\Django\proiect\proiect\urls.py changed, reloading.
INFO 2025-01-16 02:29:08,126 autoreload Watching for file changes with StatReloader
ERROR 2025-01-16 02:29:09,101 log Internal Server Error: /index/test_403/
Traceback (most recent call last):
  File "C:\Users\Mihnea\AppData\Local\Programs\Python\Python312\Lib\site-packages\django\core\handlers\exception.py", line 55, in inner
    response = get_response(request)
               ^^^^^^^^^^^^^^^^^^^^^
  File "C:\Users\Mihnea\AppData\Local\Programs\Python\Python312\Lib\site-packages\django\core\handlers\base.py", line 197, in _get_response
    response = wrapped_callback(request, *callback_args, **callback_kwargs)
               ^^^^^^^^^^^^^^^^^^^^^^^^^^^^^^^^^^^^^^^^^^^^^^^^^^^^^^^^^^^^
TypeError: custom_403_view() missing 1 required positional argument: 'exception'
ERROR 2025-01-16 02:29:09,102 basehttp "GET /index/test_403/ HTTP/1.1" 500 65677
ERROR 2025-01-16 02:29:11,100 log Internal Server Error: /index/test_403/
Traceback (most recent call last):
  File "C:\Users\Mihnea\AppData\Local\Programs\Python\Python312\Lib\site-packages\django\core\handlers\exception.py", line 55, in inner
    response = get_response(request)
               ^^^^^^^^^^^^^^^^^^^^^
  File "C:\Users\Mihnea\AppData\Local\Programs\Python\Python312\Lib\site-packages\django\core\handlers\base.py", line 197, in _get_response
    response = wrapped_callback(request, *callback_args, **callback_kwargs)
               ^^^^^^^^^^^^^^^^^^^^^^^^^^^^^^^^^^^^^^^^^^^^^^^^^^^^^^^^^^^^
TypeError: custom_403_view() missing 1 required positional argument: 'exception'
ERROR 2025-01-16 02:29:11,101 basehttp "GET /index/test_403/ HTTP/1.1" 500 65677
INFO 2025-01-16 02:29:26,908 autoreload C:\Users\Mihnea\Documents\Unibuc-FMI\2024-2025\Semestrul_1\Django\proiect\app_0\urls.py changed, reloading.
INFO 2025-01-16 02:29:27,347 autoreload Watching for file changes with StatReloader
WARNING 2025-01-16 02:29:32,280 log Not Found: /aplicatieProj/confirmare_email/2b62740a-58b2-4a2c-adca-a3157fa76739/
WARNING 2025-01-16 02:29:32,281 basehttp "GET /aplicatieProj/confirmare_email/2b62740a-58b2-4a2c-adca-a3157fa76739/ HTTP/1.1" 404 2702
ERROR 2025-01-16 02:29:48,975 log Forbidden (Permission denied): /index/test_403/
Traceback (most recent call last):
  File "C:\Users\Mihnea\AppData\Local\Programs\Python\Python312\Lib\site-packages\django\core\handlers\exception.py", line 55, in inner
    response = get_response(request)
               ^^^^^^^^^^^^^^^^^^^^^
  File "C:\Users\Mihnea\AppData\Local\Programs\Python\Python312\Lib\site-packages\django\core\handlers\base.py", line 197, in _get_response
    response = wrapped_callback(request, *callback_args, **callback_kwargs)
               ^^^^^^^^^^^^^^^^^^^^^^^^^^^^^^^^^^^^^^^^^^^^^^^^^^^^^^^^^^^^
  File "C:\Users\Mihnea\Documents\Unibuc-FMI\2024-2025\Semestrul_1\Django\proiect\app_0\views.py", line 267, in test_403
    raise PermissionDenied("You do not have permission to access this resource.")
django.core.exceptions.PermissionDenied: You do not have permission to access this resource.
ERROR 2025-01-16 02:29:48,976 basehttp "GET /index/test_403/ HTTP/1.1" 500 92508
ERROR 2025-01-16 02:30:18,763 log Forbidden (Permission denied): /index/test_403/
Traceback (most recent call last):
  File "C:\Users\Mihnea\AppData\Local\Programs\Python\Python312\Lib\site-packages\django\core\handlers\exception.py", line 55, in inner
    response = get_response(request)
               ^^^^^^^^^^^^^^^^^^^^^
  File "C:\Users\Mihnea\AppData\Local\Programs\Python\Python312\Lib\site-packages\django\core\handlers\base.py", line 197, in _get_response
    response = wrapped_callback(request, *callback_args, **callback_kwargs)
               ^^^^^^^^^^^^^^^^^^^^^^^^^^^^^^^^^^^^^^^^^^^^^^^^^^^^^^^^^^^^
  File "C:\Users\Mihnea\Documents\Unibuc-FMI\2024-2025\Semestrul_1\Django\proiect\app_0\views.py", line 267, in test_403
    raise PermissionDenied("You do not have permission to access this resource.")
django.core.exceptions.PermissionDenied: You do not have permission to access this resource.
ERROR 2025-01-16 02:30:18,764 basehttp "GET /index/test_403/ HTTP/1.1" 500 92508
INFO 2025-01-16 02:30:30,351 autoreload C:\Users\Mihnea\Documents\Unibuc-FMI\2024-2025\Semestrul_1\Django\proiect\app_0\urls.py changed, reloading.
INFO 2025-01-16 02:30:30,809 autoreload Watching for file changes with StatReloader
ERROR 2025-01-16 02:30:31,150 log Forbidden (Permission denied): /index/test_403/
Traceback (most recent call last):
  File "C:\Users\Mihnea\AppData\Local\Programs\Python\Python312\Lib\site-packages\django\core\handlers\exception.py", line 55, in inner
    response = get_response(request)
               ^^^^^^^^^^^^^^^^^^^^^
  File "C:\Users\Mihnea\AppData\Local\Programs\Python\Python312\Lib\site-packages\django\core\handlers\base.py", line 197, in _get_response
    response = wrapped_callback(request, *callback_args, **callback_kwargs)
               ^^^^^^^^^^^^^^^^^^^^^^^^^^^^^^^^^^^^^^^^^^^^^^^^^^^^^^^^^^^^
  File "C:\Users\Mihnea\Documents\Unibuc-FMI\2024-2025\Semestrul_1\Django\proiect\app_0\views.py", line 267, in test_403
    raise PermissionDenied("You do not have permission to access this resource.")
django.core.exceptions.PermissionDenied: You do not have permission to access this resource.
ERROR 2025-01-16 02:30:31,151 basehttp "GET /index/test_403/ HTTP/1.1" 500 92508
ERROR 2025-01-16 02:30:32,500 log Forbidden (Permission denied): /index/test_403/
Traceback (most recent call last):
  File "C:\Users\Mihnea\AppData\Local\Programs\Python\Python312\Lib\site-packages\django\core\handlers\exception.py", line 55, in inner
    response = get_response(request)
               ^^^^^^^^^^^^^^^^^^^^^
  File "C:\Users\Mihnea\AppData\Local\Programs\Python\Python312\Lib\site-packages\django\core\handlers\base.py", line 197, in _get_response
    response = wrapped_callback(request, *callback_args, **callback_kwargs)
               ^^^^^^^^^^^^^^^^^^^^^^^^^^^^^^^^^^^^^^^^^^^^^^^^^^^^^^^^^^^^
  File "C:\Users\Mihnea\Documents\Unibuc-FMI\2024-2025\Semestrul_1\Django\proiect\app_0\views.py", line 267, in test_403
    raise PermissionDenied("You do not have permission to access this resource.")
django.core.exceptions.PermissionDenied: You do not have permission to access this resource.
ERROR 2025-01-16 02:30:32,502 basehttp "GET /index/test_403/ HTTP/1.1" 500 92508
ERROR 2025-01-16 02:30:33,417 log Forbidden (Permission denied): /index/test_403/
Traceback (most recent call last):
  File "C:\Users\Mihnea\AppData\Local\Programs\Python\Python312\Lib\site-packages\django\core\handlers\exception.py", line 55, in inner
    response = get_response(request)
               ^^^^^^^^^^^^^^^^^^^^^
  File "C:\Users\Mihnea\AppData\Local\Programs\Python\Python312\Lib\site-packages\django\core\handlers\base.py", line 197, in _get_response
    response = wrapped_callback(request, *callback_args, **callback_kwargs)
               ^^^^^^^^^^^^^^^^^^^^^^^^^^^^^^^^^^^^^^^^^^^^^^^^^^^^^^^^^^^^
  File "C:\Users\Mihnea\Documents\Unibuc-FMI\2024-2025\Semestrul_1\Django\proiect\app_0\views.py", line 267, in test_403
    raise PermissionDenied("You do not have permission to access this resource.")
django.core.exceptions.PermissionDenied: You do not have permission to access this resource.
ERROR 2025-01-16 02:30:33,418 basehttp "GET /index/test_403/ HTTP/1.1" 500 92508
ERROR 2025-01-16 02:30:46,842 log Forbidden (Permission denied): /index/test_403/
Traceback (most recent call last):
  File "C:\Users\Mihnea\AppData\Local\Programs\Python\Python312\Lib\site-packages\django\core\handlers\exception.py", line 55, in inner
    response = get_response(request)
               ^^^^^^^^^^^^^^^^^^^^^
  File "C:\Users\Mihnea\AppData\Local\Programs\Python\Python312\Lib\site-packages\django\core\handlers\base.py", line 197, in _get_response
    response = wrapped_callback(request, *callback_args, **callback_kwargs)
               ^^^^^^^^^^^^^^^^^^^^^^^^^^^^^^^^^^^^^^^^^^^^^^^^^^^^^^^^^^^^
  File "C:\Users\Mihnea\Documents\Unibuc-FMI\2024-2025\Semestrul_1\Django\proiect\app_0\views.py", line 267, in test_403
    raise PermissionDenied("You do not have permission to access this resource.")
django.core.exceptions.PermissionDenied: You do not have permission to access this resource.
ERROR 2025-01-16 02:30:46,843 basehttp "GET /index/test_403/ HTTP/1.1" 500 92508
ERROR 2025-01-16 02:30:47,626 log Forbidden (Permission denied): /index/test_403/
Traceback (most recent call last):
  File "C:\Users\Mihnea\AppData\Local\Programs\Python\Python312\Lib\site-packages\django\core\handlers\exception.py", line 55, in inner
    response = get_response(request)
               ^^^^^^^^^^^^^^^^^^^^^
  File "C:\Users\Mihnea\AppData\Local\Programs\Python\Python312\Lib\site-packages\django\core\handlers\base.py", line 197, in _get_response
    response = wrapped_callback(request, *callback_args, **callback_kwargs)
               ^^^^^^^^^^^^^^^^^^^^^^^^^^^^^^^^^^^^^^^^^^^^^^^^^^^^^^^^^^^^
  File "C:\Users\Mihnea\Documents\Unibuc-FMI\2024-2025\Semestrul_1\Django\proiect\app_0\views.py", line 267, in test_403
    raise PermissionDenied("You do not have permission to access this resource.")
django.core.exceptions.PermissionDenied: You do not have permission to access this resource.
ERROR 2025-01-16 02:30:47,628 basehttp "GET /index/test_403/ HTTP/1.1" 500 92508
ERROR 2025-01-16 02:30:48,119 log Forbidden (Permission denied): /index/test_403/
Traceback (most recent call last):
  File "C:\Users\Mihnea\AppData\Local\Programs\Python\Python312\Lib\site-packages\django\core\handlers\exception.py", line 55, in inner
    response = get_response(request)
               ^^^^^^^^^^^^^^^^^^^^^
  File "C:\Users\Mihnea\AppData\Local\Programs\Python\Python312\Lib\site-packages\django\core\handlers\base.py", line 197, in _get_response
    response = wrapped_callback(request, *callback_args, **callback_kwargs)
               ^^^^^^^^^^^^^^^^^^^^^^^^^^^^^^^^^^^^^^^^^^^^^^^^^^^^^^^^^^^^
  File "C:\Users\Mihnea\Documents\Unibuc-FMI\2024-2025\Semestrul_1\Django\proiect\app_0\views.py", line 267, in test_403
    raise PermissionDenied("You do not have permission to access this resource.")
django.core.exceptions.PermissionDenied: You do not have permission to access this resource.
ERROR 2025-01-16 02:30:48,120 basehttp "GET /index/test_403/ HTTP/1.1" 500 92508
ERROR 2025-01-16 02:30:48,416 log Forbidden (Permission denied): /index/test_403/
Traceback (most recent call last):
  File "C:\Users\Mihnea\AppData\Local\Programs\Python\Python312\Lib\site-packages\django\core\handlers\exception.py", line 55, in inner
    response = get_response(request)
               ^^^^^^^^^^^^^^^^^^^^^
  File "C:\Users\Mihnea\AppData\Local\Programs\Python\Python312\Lib\site-packages\django\core\handlers\base.py", line 197, in _get_response
    response = wrapped_callback(request, *callback_args, **callback_kwargs)
               ^^^^^^^^^^^^^^^^^^^^^^^^^^^^^^^^^^^^^^^^^^^^^^^^^^^^^^^^^^^^
  File "C:\Users\Mihnea\Documents\Unibuc-FMI\2024-2025\Semestrul_1\Django\proiect\app_0\views.py", line 267, in test_403
    raise PermissionDenied("You do not have permission to access this resource.")
django.core.exceptions.PermissionDenied: You do not have permission to access this resource.
ERROR 2025-01-16 02:30:48,417 basehttp "GET /index/test_403/ HTTP/1.1" 500 92508
INFO 2025-01-16 02:32:01,127 autoreload C:\Users\Mihnea\Documents\Unibuc-FMI\2024-2025\Semestrul_1\Django\proiect\proiect\settings.py changed, reloading.
INFO 2025-01-16 02:32:01,567 autoreload Watching for file changes with StatReloader
ERROR 2025-01-16 02:32:04,073 log Forbidden (Permission denied): /index/test_403/
Traceback (most recent call last):
  File "C:\Users\Mihnea\AppData\Local\Programs\Python\Python312\Lib\site-packages\django\core\handlers\exception.py", line 55, in inner
    response = get_response(request)
               ^^^^^^^^^^^^^^^^^^^^^
  File "C:\Users\Mihnea\AppData\Local\Programs\Python\Python312\Lib\site-packages\django\core\handlers\base.py", line 197, in _get_response
    response = wrapped_callback(request, *callback_args, **callback_kwargs)
               ^^^^^^^^^^^^^^^^^^^^^^^^^^^^^^^^^^^^^^^^^^^^^^^^^^^^^^^^^^^^
  File "C:\Users\Mihnea\Documents\Unibuc-FMI\2024-2025\Semestrul_1\Django\proiect\app_0\views.py", line 267, in test_403
    raise PermissionDenied("You do not have permission to access this resource.")
django.core.exceptions.PermissionDenied: You do not have permission to access this resource.
ERROR 2025-01-16 02:32:04,075 basehttp "GET /index/test_403/ HTTP/1.1" 500 92508
INFO 2025-01-16 03:52:47,353 autoreload Watching for file changes with StatReloader
ERROR 2025-01-16 03:52:51,736 log Forbidden (Permission denied): /index/test_403/
Traceback (most recent call last):
  File "C:\Users\Mihnea\AppData\Local\Programs\Python\Python312\Lib\site-packages\django\core\handlers\exception.py", line 55, in inner
    response = get_response(request)
               ^^^^^^^^^^^^^^^^^^^^^
  File "C:\Users\Mihnea\AppData\Local\Programs\Python\Python312\Lib\site-packages\django\core\handlers\base.py", line 197, in _get_response
    response = wrapped_callback(request, *callback_args, **callback_kwargs)
               ^^^^^^^^^^^^^^^^^^^^^^^^^^^^^^^^^^^^^^^^^^^^^^^^^^^^^^^^^^^^
  File "C:\Users\Mihnea\Documents\Unibuc-FMI\2024-2025\Semestrul_1\Django\proiect\app_0\views.py", line 267, in test_403
    raise PermissionDenied("You do not have permission to access this resource.")
django.core.exceptions.PermissionDenied: You do not have permission to access this resource.
ERROR 2025-01-16 03:52:51,737 basehttp "GET /index/test_403/ HTTP/1.1" 500 92508
ERROR 2025-01-16 03:55:06,315 log Forbidden (Permission denied): /index/test_403/
Traceback (most recent call last):
  File "C:\Users\Mihnea\AppData\Local\Programs\Python\Python312\Lib\site-packages\django\core\handlers\exception.py", line 55, in inner
    response = get_response(request)
               ^^^^^^^^^^^^^^^^^^^^^
  File "C:\Users\Mihnea\AppData\Local\Programs\Python\Python312\Lib\site-packages\django\core\handlers\base.py", line 197, in _get_response
    response = wrapped_callback(request, *callback_args, **callback_kwargs)
               ^^^^^^^^^^^^^^^^^^^^^^^^^^^^^^^^^^^^^^^^^^^^^^^^^^^^^^^^^^^^
  File "C:\Users\Mihnea\Documents\Unibuc-FMI\2024-2025\Semestrul_1\Django\proiect\app_0\views.py", line 267, in test_403
    raise PermissionDenied("You do not have permission to access this resource.")
django.core.exceptions.PermissionDenied: You do not have permission to access this resource.
ERROR 2025-01-16 03:55:06,317 basehttp "GET /index/test_403/ HTTP/1.1" 500 92508
INFO 2025-01-16 03:55:29,247 autoreload C:\Users\Mihnea\Documents\Unibuc-FMI\2024-2025\Semestrul_1\Django\proiect\app_0\views.py changed, reloading.
INFO 2025-01-16 03:55:29,739 autoreload Watching for file changes with StatReloader
INFO 2025-01-16 03:55:31,009 log Forbidden (Permission denied): /index/test_403/
Traceback (most recent call last):
  File "C:\Users\Mihnea\AppData\Local\Programs\Python\Python312\Lib\site-packages\django\core\handlers\exception.py", line 55, in inner
    response = get_response(request)
               ^^^^^^^^^^^^^^^^^^^^^
  File "C:\Users\Mihnea\AppData\Local\Programs\Python\Python312\Lib\site-packages\django\core\handlers\base.py", line 197, in _get_response
    response = wrapped_callback(request, *callback_args, **callback_kwargs)
               ^^^^^^^^^^^^^^^^^^^^^^^^^^^^^^^^^^^^^^^^^^^^^^^^^^^^^^^^^^^^
  File "C:\Users\Mihnea\Documents\Unibuc-FMI\2024-2025\Semestrul_1\Django\proiect\app_0\views.py", line 267, in test_403
    raise PermissionDenied("You do not have permission to access this resource.")
django.core.exceptions.PermissionDenied: You do not have permission to access this resource.
INFO 2025-01-16 03:55:31,011 basehttp "GET /index/test_403/ HTTP/1.1" 200 222
WARNING 2025-01-16 03:56:07,872 log Not Found: /index/profil
WARNING 2025-01-16 03:56:07,873 basehttp "GET /index/profil HTTP/1.1" 404 6756
INFO 2025-01-16 03:56:10,777 basehttp "GET /index/profile HTTP/1.1" 301 0
INFO 2025-01-16 03:56:10,843 basehttp "GET /index/profile/ HTTP/1.1" 200 791
INFO 2025-01-16 03:56:12,100 basehttp "GET /index/logout/ HTTP/1.1" 302 0
INFO 2025-01-16 03:56:12,114 basehttp "GET /index/login/ HTTP/1.1" 200 865
INFO 2025-01-16 03:56:17,470 log Forbidden (Permission denied): /index/test_403/
Traceback (most recent call last):
  File "C:\Users\Mihnea\AppData\Local\Programs\Python\Python312\Lib\site-packages\django\core\handlers\exception.py", line 55, in inner
    response = get_response(request)
               ^^^^^^^^^^^^^^^^^^^^^
  File "C:\Users\Mihnea\AppData\Local\Programs\Python\Python312\Lib\site-packages\django\core\handlers\base.py", line 197, in _get_response
    response = wrapped_callback(request, *callback_args, **callback_kwargs)
               ^^^^^^^^^^^^^^^^^^^^^^^^^^^^^^^^^^^^^^^^^^^^^^^^^^^^^^^^^^^^
  File "C:\Users\Mihnea\Documents\Unibuc-FMI\2024-2025\Semestrul_1\Django\proiect\app_0\views.py", line 267, in test_403
    raise PermissionDenied("You do not have permission to access this resource.")
django.core.exceptions.PermissionDenied: You do not have permission to access this resource.
INFO 2025-01-16 03:56:17,471 basehttp "GET /index/test_403/ HTTP/1.1" 200 235
INFO 2025-01-16 03:57:56,465 autoreload C:\Users\Mihnea\Documents\Unibuc-FMI\2024-2025\Semestrul_1\Django\proiect\app_0\admin.py changed, reloading.
INFO 2025-01-16 03:57:56,924 autoreload Watching for file changes with StatReloader
INFO 2025-01-16 03:58:57,203 autoreload C:\Users\Mihnea\Documents\Unibuc-FMI\2024-2025\Semestrul_1\Django\proiect\app_0\views.py changed, reloading.
INFO 2025-01-16 03:58:57,614 autoreload Watching for file changes with StatReloader
INFO 2025-01-16 04:00:12,498 autoreload Watching for file changes with StatReloader
INFO 2025-01-16 04:02:06,628 autoreload Watching for file changes with StatReloader
INFO 2025-01-16 04:02:09,390 basehttp "GET /admin/ HTTP/1.1" 302 0
INFO 2025-01-16 04:02:09,419 basehttp "GET /admin/login/?next=/admin/ HTTP/1.1" 200 4379
INFO 2025-01-16 04:02:18,893 basehttp "POST /admin/login/?next=/admin/ HTTP/1.1" 302 0
INFO 2025-01-16 04:02:18,965 basehttp "GET /admin/ HTTP/1.1" 200 14573
INFO 2025-01-16 04:02:22,030 basehttp "GET /admin/auth/group/add/ HTTP/1.1" 200 16700
INFO 2025-01-16 04:02:22,141 basehttp "GET /admin/jsi18n/ HTTP/1.1" 200 3342
INFO 2025-01-16 04:03:00,336 basehttp "POST /admin/auth/group/add/ HTTP/1.1" 302 0
INFO 2025-01-16 04:03:00,420 basehttp "GET /admin/auth/group/ HTTP/1.1" 200 12575
INFO 2025-01-16 04:03:00,523 basehttp "GET /admin/jsi18n/ HTTP/1.1" 200 3342
INFO 2025-01-16 04:05:04,124 autoreload Watching for file changes with StatReloader
INFO 2025-01-16 04:05:05,893 basehttp "GET /admin/auth/group/1/change/ HTTP/1.1" 200 17016
INFO 2025-01-16 04:05:06,035 basehttp "GET /admin/jsi18n/ HTTP/1.1" 200 3342
INFO 2025-01-16 04:05:13,198 basehttp "GET /admin/auth/group/ HTTP/1.1" 200 12365
INFO 2025-01-16 04:52:19,713 autoreload Watching for file changes with StatReloader
INFO 2025-01-16 04:52:22,131 basehttp "GET /admin/app_0/customuser/ HTTP/1.1" 200 16793
INFO 2025-01-16 04:52:22,290 basehttp "GET /admin/jsi18n/ HTTP/1.1" 200 3342
INFO 2025-01-16 04:53:07,235 basehttp "GET /admin/app_0/customuser/9/change/ HTTP/1.1" 200 30788
INFO 2025-01-16 04:53:07,333 basehttp "GET /admin/jsi18n/ HTTP/1.1" 200 3342
INFO 2025-01-16 04:53:19,427 basehttp "POST /admin/app_0/customuser/9/change/ HTTP/1.1" 302 0
INFO 2025-01-16 04:53:19,495 basehttp "GET /admin/app_0/customuser/ HTTP/1.1" 200 16994
INFO 2025-01-16 04:53:19,597 basehttp "GET /admin/jsi18n/ HTTP/1.1" 200 3342
INFO 2025-01-16 04:53:21,530 basehttp "GET /admin/app_0/customuser/1/change/ HTTP/1.1" 200 30824
INFO 2025-01-16 04:53:21,629 basehttp "GET /admin/jsi18n/ HTTP/1.1" 200 3342
INFO 2025-01-16 04:53:27,581 basehttp "POST /admin/app_0/customuser/1/change/ HTTP/1.1" 302 0
INFO 2025-01-16 04:53:27,651 basehttp "GET /admin/app_0/customuser/ HTTP/1.1" 200 16994
INFO 2025-01-16 04:53:27,752 basehttp "GET /admin/jsi18n/ HTTP/1.1" 200 3342
WARNING 2025-01-16 04:53:37,052 log Not Found: /app_0
WARNING 2025-01-16 04:53:37,053 basehttp "GET /app_0 HTTP/1.1" 404 2513
INFO 2025-01-16 04:53:43,390 basehttp "GET /index HTTP/1.1" 301 0
INFO 2025-01-16 04:53:43,705 basehttp "GET /index/ HTTP/1.1" 200 40
WARNING 2025-01-16 04:53:49,426 log Not Found: /index/ceva
WARNING 2025-01-16 04:53:49,427 basehttp "GET /index/ceva HTTP/1.1" 404 6750
INFO 2025-01-16 04:54:01,095 basehttp "GET /index/adauga-bilet HTTP/1.1" 301 0
INFO 2025-01-16 04:54:01,165 basehttp "GET /index/adauga-bilet/ HTTP/1.1" 200 1797
INFO 2025-01-16 04:54:08,568 basehttp "POST /index/adauga-bilet/ HTTP/1.1" 302 0
INFO 2025-01-16 04:54:08,574 basehttp "GET /index/adauga-bilet/success/ HTTP/1.1" 200 191
INFO 2025-01-16 04:54:33,519 basehttp "GET /index/profile/ HTTP/1.1" 200 745
INFO 2025-01-16 04:54:37,751 basehttp "GET /index/logout/ HTTP/1.1" 302 0
INFO 2025-01-16 04:54:37,758 basehttp "GET /index/login/ HTTP/1.1" 200 865
INFO 2025-01-16 04:54:49,239 basehttp "POST /index/login/ HTTP/1.1" 302 0
INFO 2025-01-16 04:54:49,299 basehttp "GET /index/profile/ HTTP/1.1" 200 791
INFO 2025-01-16 04:54:52,537 log Forbidden (Permission denied): /index/adauga-bilet/
Traceback (most recent call last):
  File "C:\Users\Mihnea\AppData\Local\Programs\Python\Python312\Lib\site-packages\django\core\handlers\exception.py", line 55, in inner
    response = get_response(request)
               ^^^^^^^^^^^^^^^^^^^^^
  File "C:\Users\Mihnea\AppData\Local\Programs\Python\Python312\Lib\site-packages\django\core\handlers\base.py", line 197, in _get_response
    response = wrapped_callback(request, *callback_args, **callback_kwargs)
               ^^^^^^^^^^^^^^^^^^^^^^^^^^^^^^^^^^^^^^^^^^^^^^^^^^^^^^^^^^^^
  File "C:\Users\Mihnea\AppData\Local\Programs\Python\Python312\Lib\site-packages\django\contrib\auth\decorators.py", line 57, in _view_wrapper
    test_pass = test_func(request.user)
                ^^^^^^^^^^^^^^^^^^^^^^^
  File "C:\Users\Mihnea\AppData\Local\Programs\Python\Python312\Lib\site-packages\django\contrib\auth\decorators.py", line 130, in check_perms
    raise PermissionDenied
django.core.exceptions.PermissionDenied
INFO 2025-01-16 04:54:52,541 basehttp "GET /index/adauga-bilet/ HTTP/1.1" 200 171
INFO 2025-01-16 04:58:56,282 autoreload C:\Users\Mihnea\Documents\Unibuc-FMI\2024-2025\Semestrul_1\Django\proiect\app_0\views.py changed, reloading.
INFO 2025-01-16 04:58:56,747 autoreload Watching for file changes with StatReloader
INFO 2025-01-16 04:59:08,375 autoreload C:\Users\Mihnea\Documents\Unibuc-FMI\2024-2025\Semestrul_1\Django\proiect\app_0\views.py changed, reloading.
INFO 2025-01-16 04:59:08,803 autoreload Watching for file changes with StatReloader
INFO 2025-01-16 04:59:27,548 autoreload C:\Users\Mihnea\Documents\Unibuc-FMI\2024-2025\Semestrul_1\Django\proiect\app_0\views.py changed, reloading.
INFO 2025-01-16 04:59:27,987 autoreload Watching for file changes with StatReloader
INFO 2025-01-16 05:02:36,221 autoreload C:\Users\Mihnea\Documents\Unibuc-FMI\2024-2025\Semestrul_1\Django\proiect\app_0\urls.py changed, reloading.
INFO 2025-01-16 05:02:36,659 autoreload Watching for file changes with StatReloader
INFO 2025-01-16 05:03:04,625 basehttp "GET /index/bilete/ HTTP/1.1" 200 6323
INFO 2025-01-16 05:03:10,079 basehttp "GET /index/bilete/ HTTP/1.1" 200 6323
INFO 2025-01-16 05:03:10,683 basehttp "GET /index/bilete/ HTTP/1.1" 200 6323
INFO 2025-01-16 05:03:11,981 basehttp "GET /index/bilete/ HTTP/1.1" 200 6323
INFO 2025-01-16 05:04:21,609 basehttp "GET /index/bilete/ HTTP/1.1" 200 6295
INFO 2025-01-16 05:04:22,439 basehttp "GET /index/bilete/ HTTP/1.1" 200 6295
INFO 2025-01-16 05:04:24,993 basehttp "GET /index/bilete/ HTTP/1.1" 200 6295
INFO 2025-01-16 05:04:25,574 basehttp "GET /index/bilete/ HTTP/1.1" 200 6295
INFO 2025-01-16 05:04:28,798 basehttp "GET /index/bilet/4/ HTTP/1.1" 200 726
INFO 2025-01-16 05:04:56,641 basehttp "GET /index/bilete/ HTTP/1.1" 200 6295
INFO 2025-01-16 05:04:57,201 basehttp "GET /index/bilete/ HTTP/1.1" 200 6295
INFO 2025-01-16 05:04:57,744 basehttp "GET /index/bilete/ HTTP/1.1" 200 6295
INFO 2025-01-16 05:05:10,231 basehttp "GET /index/bilete/ HTTP/1.1" 200 6298
ERROR 2025-01-16 05:05:13,789 log Internal Server Error: /index/assign_offer_permission/
Traceback (most recent call last):
  File "C:\Users\Mihnea\AppData\Local\Programs\Python\Python312\Lib\site-packages\django\core\handlers\exception.py", line 55, in inner
    response = get_response(request)
               ^^^^^^^^^^^^^^^^^^^^^
  File "C:\Users\Mihnea\AppData\Local\Programs\Python\Python312\Lib\site-packages\django\core\handlers\base.py", line 197, in _get_response
    response = wrapped_callback(request, *callback_args, **callback_kwargs)
               ^^^^^^^^^^^^^^^^^^^^^^^^^^^^^^^^^^^^^^^^^^^^^^^^^^^^^^^^^^^^
  File "C:\Users\Mihnea\AppData\Local\Programs\Python\Python312\Lib\site-packages\django\contrib\auth\decorators.py", line 60, in _view_wrapper
    return view_func(request, *args, **kwargs)
           ^^^^^^^^^^^^^^^^^^^^^^^^^^^^^^^^^^^
  File "C:\Users\Mihnea\Documents\Unibuc-FMI\2024-2025\Semestrul_1\Django\proiect\app_0\views.py", line 282, in assign_offer_permission
    permission = Permission.objects.get(codename='vizualizeaza_oferta')
                 ^^^^^^^^^^^^^^^^^^^^^^^^^^^^^^^^^^^^^^^^^^^^^^^^^^^^^^
  File "C:\Users\Mihnea\AppData\Local\Programs\Python\Python312\Lib\site-packages\django\db\models\manager.py", line 87, in manager_method
    return getattr(self.get_queryset(), name)(*args, **kwargs)
           ^^^^^^^^^^^^^^^^^^^^^^^^^^^^^^^^^^^^^^^^^^^^^^^^^^^
  File "C:\Users\Mihnea\AppData\Local\Programs\Python\Python312\Lib\site-packages\django\db\models\query.py", line 649, in get
    raise self.model.DoesNotExist(
django.contrib.auth.models.Permission.DoesNotExist: Permission matching query does not exist.
ERROR 2025-01-16 05:05:13,791 basehttp "POST /index/assign_offer_permission/ HTTP/1.1" 500 84370
ERROR 2025-01-16 05:05:15,390 log Internal Server Error: /index/assign_offer_permission/
Traceback (most recent call last):
  File "C:\Users\Mihnea\AppData\Local\Programs\Python\Python312\Lib\site-packages\django\core\handlers\exception.py", line 55, in inner
    response = get_response(request)
               ^^^^^^^^^^^^^^^^^^^^^
  File "C:\Users\Mihnea\AppData\Local\Programs\Python\Python312\Lib\site-packages\django\core\handlers\base.py", line 197, in _get_response
    response = wrapped_callback(request, *callback_args, **callback_kwargs)
               ^^^^^^^^^^^^^^^^^^^^^^^^^^^^^^^^^^^^^^^^^^^^^^^^^^^^^^^^^^^^
  File "C:\Users\Mihnea\AppData\Local\Programs\Python\Python312\Lib\site-packages\django\contrib\auth\decorators.py", line 60, in _view_wrapper
    return view_func(request, *args, **kwargs)
           ^^^^^^^^^^^^^^^^^^^^^^^^^^^^^^^^^^^
  File "C:\Users\Mihnea\Documents\Unibuc-FMI\2024-2025\Semestrul_1\Django\proiect\app_0\views.py", line 282, in assign_offer_permission
    permission = Permission.objects.get(codename='vizualizeaza_oferta')
                 ^^^^^^^^^^^^^^^^^^^^^^^^^^^^^^^^^^^^^^^^^^^^^^^^^^^^^^
  File "C:\Users\Mihnea\AppData\Local\Programs\Python\Python312\Lib\site-packages\django\db\models\manager.py", line 87, in manager_method
    return getattr(self.get_queryset(), name)(*args, **kwargs)
           ^^^^^^^^^^^^^^^^^^^^^^^^^^^^^^^^^^^^^^^^^^^^^^^^^^^
  File "C:\Users\Mihnea\AppData\Local\Programs\Python\Python312\Lib\site-packages\django\db\models\query.py", line 649, in get
    raise self.model.DoesNotExist(
django.contrib.auth.models.Permission.DoesNotExist: Permission matching query does not exist.
ERROR 2025-01-16 05:05:15,392 basehttp "POST /index/assign_offer_permission/ HTTP/1.1" 500 84370
ERROR 2025-01-16 05:05:16,426 log Internal Server Error: /index/assign_offer_permission/
Traceback (most recent call last):
  File "C:\Users\Mihnea\AppData\Local\Programs\Python\Python312\Lib\site-packages\django\core\handlers\exception.py", line 55, in inner
    response = get_response(request)
               ^^^^^^^^^^^^^^^^^^^^^
  File "C:\Users\Mihnea\AppData\Local\Programs\Python\Python312\Lib\site-packages\django\core\handlers\base.py", line 197, in _get_response
    response = wrapped_callback(request, *callback_args, **callback_kwargs)
               ^^^^^^^^^^^^^^^^^^^^^^^^^^^^^^^^^^^^^^^^^^^^^^^^^^^^^^^^^^^^
  File "C:\Users\Mihnea\AppData\Local\Programs\Python\Python312\Lib\site-packages\django\contrib\auth\decorators.py", line 60, in _view_wrapper
    return view_func(request, *args, **kwargs)
           ^^^^^^^^^^^^^^^^^^^^^^^^^^^^^^^^^^^
  File "C:\Users\Mihnea\Documents\Unibuc-FMI\2024-2025\Semestrul_1\Django\proiect\app_0\views.py", line 282, in assign_offer_permission
    permission = Permission.objects.get(codename='vizualizeaza_oferta')
                 ^^^^^^^^^^^^^^^^^^^^^^^^^^^^^^^^^^^^^^^^^^^^^^^^^^^^^^
  File "C:\Users\Mihnea\AppData\Local\Programs\Python\Python312\Lib\site-packages\django\db\models\manager.py", line 87, in manager_method
    return getattr(self.get_queryset(), name)(*args, **kwargs)
           ^^^^^^^^^^^^^^^^^^^^^^^^^^^^^^^^^^^^^^^^^^^^^^^^^^^
  File "C:\Users\Mihnea\AppData\Local\Programs\Python\Python312\Lib\site-packages\django\db\models\query.py", line 649, in get
    raise self.model.DoesNotExist(
django.contrib.auth.models.Permission.DoesNotExist: Permission matching query does not exist.
ERROR 2025-01-16 05:05:16,428 basehttp "POST /index/assign_offer_permission/ HTTP/1.1" 500 84370
ERROR 2025-01-16 05:05:16,608 log Internal Server Error: /index/assign_offer_permission/
Traceback (most recent call last):
  File "C:\Users\Mihnea\AppData\Local\Programs\Python\Python312\Lib\site-packages\django\core\handlers\exception.py", line 55, in inner
    response = get_response(request)
               ^^^^^^^^^^^^^^^^^^^^^
  File "C:\Users\Mihnea\AppData\Local\Programs\Python\Python312\Lib\site-packages\django\core\handlers\base.py", line 197, in _get_response
    response = wrapped_callback(request, *callback_args, **callback_kwargs)
               ^^^^^^^^^^^^^^^^^^^^^^^^^^^^^^^^^^^^^^^^^^^^^^^^^^^^^^^^^^^^
  File "C:\Users\Mihnea\AppData\Local\Programs\Python\Python312\Lib\site-packages\django\contrib\auth\decorators.py", line 60, in _view_wrapper
    return view_func(request, *args, **kwargs)
           ^^^^^^^^^^^^^^^^^^^^^^^^^^^^^^^^^^^
  File "C:\Users\Mihnea\Documents\Unibuc-FMI\2024-2025\Semestrul_1\Django\proiect\app_0\views.py", line 282, in assign_offer_permission
    permission = Permission.objects.get(codename='vizualizeaza_oferta')
                 ^^^^^^^^^^^^^^^^^^^^^^^^^^^^^^^^^^^^^^^^^^^^^^^^^^^^^^
  File "C:\Users\Mihnea\AppData\Local\Programs\Python\Python312\Lib\site-packages\django\db\models\manager.py", line 87, in manager_method
    return getattr(self.get_queryset(), name)(*args, **kwargs)
           ^^^^^^^^^^^^^^^^^^^^^^^^^^^^^^^^^^^^^^^^^^^^^^^^^^^
  File "C:\Users\Mihnea\AppData\Local\Programs\Python\Python312\Lib\site-packages\django\db\models\query.py", line 649, in get
    raise self.model.DoesNotExist(
django.contrib.auth.models.Permission.DoesNotExist: Permission matching query does not exist.
ERROR 2025-01-16 05:05:16,610 basehttp "POST /index/assign_offer_permission/ HTTP/1.1" 500 84370
ERROR 2025-01-16 05:05:17,115 log Internal Server Error: /index/assign_offer_permission/
Traceback (most recent call last):
  File "C:\Users\Mihnea\AppData\Local\Programs\Python\Python312\Lib\site-packages\django\core\handlers\exception.py", line 55, in inner
    response = get_response(request)
               ^^^^^^^^^^^^^^^^^^^^^
  File "C:\Users\Mihnea\AppData\Local\Programs\Python\Python312\Lib\site-packages\django\core\handlers\base.py", line 197, in _get_response
    response = wrapped_callback(request, *callback_args, **callback_kwargs)
               ^^^^^^^^^^^^^^^^^^^^^^^^^^^^^^^^^^^^^^^^^^^^^^^^^^^^^^^^^^^^
  File "C:\Users\Mihnea\AppData\Local\Programs\Python\Python312\Lib\site-packages\django\contrib\auth\decorators.py", line 60, in _view_wrapper
    return view_func(request, *args, **kwargs)
           ^^^^^^^^^^^^^^^^^^^^^^^^^^^^^^^^^^^
  File "C:\Users\Mihnea\Documents\Unibuc-FMI\2024-2025\Semestrul_1\Django\proiect\app_0\views.py", line 282, in assign_offer_permission
    permission = Permission.objects.get(codename='vizualizeaza_oferta')
                 ^^^^^^^^^^^^^^^^^^^^^^^^^^^^^^^^^^^^^^^^^^^^^^^^^^^^^^
  File "C:\Users\Mihnea\AppData\Local\Programs\Python\Python312\Lib\site-packages\django\db\models\manager.py", line 87, in manager_method
    return getattr(self.get_queryset(), name)(*args, **kwargs)
           ^^^^^^^^^^^^^^^^^^^^^^^^^^^^^^^^^^^^^^^^^^^^^^^^^^^
  File "C:\Users\Mihnea\AppData\Local\Programs\Python\Python312\Lib\site-packages\django\db\models\query.py", line 649, in get
    raise self.model.DoesNotExist(
django.contrib.auth.models.Permission.DoesNotExist: Permission matching query does not exist.
ERROR 2025-01-16 05:05:17,117 basehttp "POST /index/assign_offer_permission/ HTTP/1.1" 500 84370
ERROR 2025-01-16 05:05:17,463 log Internal Server Error: /index/assign_offer_permission/
Traceback (most recent call last):
  File "C:\Users\Mihnea\AppData\Local\Programs\Python\Python312\Lib\site-packages\django\core\handlers\exception.py", line 55, in inner
    response = get_response(request)
               ^^^^^^^^^^^^^^^^^^^^^
  File "C:\Users\Mihnea\AppData\Local\Programs\Python\Python312\Lib\site-packages\django\core\handlers\base.py", line 197, in _get_response
    response = wrapped_callback(request, *callback_args, **callback_kwargs)
               ^^^^^^^^^^^^^^^^^^^^^^^^^^^^^^^^^^^^^^^^^^^^^^^^^^^^^^^^^^^^
  File "C:\Users\Mihnea\AppData\Local\Programs\Python\Python312\Lib\site-packages\django\contrib\auth\decorators.py", line 60, in _view_wrapper
    return view_func(request, *args, **kwargs)
           ^^^^^^^^^^^^^^^^^^^^^^^^^^^^^^^^^^^
  File "C:\Users\Mihnea\Documents\Unibuc-FMI\2024-2025\Semestrul_1\Django\proiect\app_0\views.py", line 282, in assign_offer_permission
    permission = Permission.objects.get(codename='vizualizeaza_oferta')
                 ^^^^^^^^^^^^^^^^^^^^^^^^^^^^^^^^^^^^^^^^^^^^^^^^^^^^^^
  File "C:\Users\Mihnea\AppData\Local\Programs\Python\Python312\Lib\site-packages\django\db\models\manager.py", line 87, in manager_method
    return getattr(self.get_queryset(), name)(*args, **kwargs)
           ^^^^^^^^^^^^^^^^^^^^^^^^^^^^^^^^^^^^^^^^^^^^^^^^^^^
  File "C:\Users\Mihnea\AppData\Local\Programs\Python\Python312\Lib\site-packages\django\db\models\query.py", line 649, in get
    raise self.model.DoesNotExist(
django.contrib.auth.models.Permission.DoesNotExist: Permission matching query does not exist.
ERROR 2025-01-16 05:05:17,464 basehttp "POST /index/assign_offer_permission/ HTTP/1.1" 500 84370
ERROR 2025-01-16 05:05:17,901 log Internal Server Error: /index/assign_offer_permission/
Traceback (most recent call last):
  File "C:\Users\Mihnea\AppData\Local\Programs\Python\Python312\Lib\site-packages\django\core\handlers\exception.py", line 55, in inner
    response = get_response(request)
               ^^^^^^^^^^^^^^^^^^^^^
  File "C:\Users\Mihnea\AppData\Local\Programs\Python\Python312\Lib\site-packages\django\core\handlers\base.py", line 197, in _get_response
    response = wrapped_callback(request, *callback_args, **callback_kwargs)
               ^^^^^^^^^^^^^^^^^^^^^^^^^^^^^^^^^^^^^^^^^^^^^^^^^^^^^^^^^^^^
  File "C:\Users\Mihnea\AppData\Local\Programs\Python\Python312\Lib\site-packages\django\contrib\auth\decorators.py", line 60, in _view_wrapper
    return view_func(request, *args, **kwargs)
           ^^^^^^^^^^^^^^^^^^^^^^^^^^^^^^^^^^^
  File "C:\Users\Mihnea\Documents\Unibuc-FMI\2024-2025\Semestrul_1\Django\proiect\app_0\views.py", line 282, in assign_offer_permission
    permission = Permission.objects.get(codename='vizualizeaza_oferta')
                 ^^^^^^^^^^^^^^^^^^^^^^^^^^^^^^^^^^^^^^^^^^^^^^^^^^^^^^
  File "C:\Users\Mihnea\AppData\Local\Programs\Python\Python312\Lib\site-packages\django\db\models\manager.py", line 87, in manager_method
    return getattr(self.get_queryset(), name)(*args, **kwargs)
           ^^^^^^^^^^^^^^^^^^^^^^^^^^^^^^^^^^^^^^^^^^^^^^^^^^^
  File "C:\Users\Mihnea\AppData\Local\Programs\Python\Python312\Lib\site-packages\django\db\models\query.py", line 649, in get
    raise self.model.DoesNotExist(
django.contrib.auth.models.Permission.DoesNotExist: Permission matching query does not exist.
ERROR 2025-01-16 05:05:17,903 basehttp "POST /index/assign_offer_permission/ HTTP/1.1" 500 84370
ERROR 2025-01-16 05:05:18,477 log Internal Server Error: /index/assign_offer_permission/
Traceback (most recent call last):
  File "C:\Users\Mihnea\AppData\Local\Programs\Python\Python312\Lib\site-packages\django\core\handlers\exception.py", line 55, in inner
    response = get_response(request)
               ^^^^^^^^^^^^^^^^^^^^^
  File "C:\Users\Mihnea\AppData\Local\Programs\Python\Python312\Lib\site-packages\django\core\handlers\base.py", line 197, in _get_response
    response = wrapped_callback(request, *callback_args, **callback_kwargs)
               ^^^^^^^^^^^^^^^^^^^^^^^^^^^^^^^^^^^^^^^^^^^^^^^^^^^^^^^^^^^^
  File "C:\Users\Mihnea\AppData\Local\Programs\Python\Python312\Lib\site-packages\django\contrib\auth\decorators.py", line 60, in _view_wrapper
    return view_func(request, *args, **kwargs)
           ^^^^^^^^^^^^^^^^^^^^^^^^^^^^^^^^^^^
  File "C:\Users\Mihnea\Documents\Unibuc-FMI\2024-2025\Semestrul_1\Django\proiect\app_0\views.py", line 282, in assign_offer_permission
    permission = Permission.objects.get(codename='vizualizeaza_oferta')
                 ^^^^^^^^^^^^^^^^^^^^^^^^^^^^^^^^^^^^^^^^^^^^^^^^^^^^^^
  File "C:\Users\Mihnea\AppData\Local\Programs\Python\Python312\Lib\site-packages\django\db\models\manager.py", line 87, in manager_method
    return getattr(self.get_queryset(), name)(*args, **kwargs)
           ^^^^^^^^^^^^^^^^^^^^^^^^^^^^^^^^^^^^^^^^^^^^^^^^^^^
  File "C:\Users\Mihnea\AppData\Local\Programs\Python\Python312\Lib\site-packages\django\db\models\query.py", line 649, in get
    raise self.model.DoesNotExist(
django.contrib.auth.models.Permission.DoesNotExist: Permission matching query does not exist.
ERROR 2025-01-16 05:05:18,479 basehttp "POST /index/assign_offer_permission/ HTTP/1.1" 500 84370
INFO 2025-01-16 05:07:03,152 basehttp "GET /index/bilete/ HTTP/1.1" 200 6360
ERROR 2025-01-16 05:07:05,110 log Internal Server Error: /index/assign_offer_permission/
Traceback (most recent call last):
  File "C:\Users\Mihnea\AppData\Local\Programs\Python\Python312\Lib\site-packages\django\core\handlers\exception.py", line 55, in inner
    response = get_response(request)
               ^^^^^^^^^^^^^^^^^^^^^
  File "C:\Users\Mihnea\AppData\Local\Programs\Python\Python312\Lib\site-packages\django\core\handlers\base.py", line 197, in _get_response
    response = wrapped_callback(request, *callback_args, **callback_kwargs)
               ^^^^^^^^^^^^^^^^^^^^^^^^^^^^^^^^^^^^^^^^^^^^^^^^^^^^^^^^^^^^
  File "C:\Users\Mihnea\AppData\Local\Programs\Python\Python312\Lib\site-packages\django\contrib\auth\decorators.py", line 60, in _view_wrapper
    return view_func(request, *args, **kwargs)
           ^^^^^^^^^^^^^^^^^^^^^^^^^^^^^^^^^^^
  File "C:\Users\Mihnea\Documents\Unibuc-FMI\2024-2025\Semestrul_1\Django\proiect\app_0\views.py", line 282, in assign_offer_permission
    permission = Permission.objects.get(codename='vizualizeaza_oferta')
                 ^^^^^^^^^^^^^^^^^^^^^^^^^^^^^^^^^^^^^^^^^^^^^^^^^^^^^^
  File "C:\Users\Mihnea\AppData\Local\Programs\Python\Python312\Lib\site-packages\django\db\models\manager.py", line 87, in manager_method
    return getattr(self.get_queryset(), name)(*args, **kwargs)
           ^^^^^^^^^^^^^^^^^^^^^^^^^^^^^^^^^^^^^^^^^^^^^^^^^^^
  File "C:\Users\Mihnea\AppData\Local\Programs\Python\Python312\Lib\site-packages\django\db\models\query.py", line 649, in get
    raise self.model.DoesNotExist(
django.contrib.auth.models.Permission.DoesNotExist: Permission matching query does not exist.
ERROR 2025-01-16 05:07:05,112 basehttp "POST /index/assign_offer_permission/ HTTP/1.1" 500 84370
INFO 2025-01-16 05:07:21,519 autoreload C:\Users\Mihnea\Documents\Unibuc-FMI\2024-2025\Semestrul_1\Django\proiect\app_0\views.py changed, reloading.
INFO 2025-01-16 05:07:21,963 autoreload Watching for file changes with StatReloader
INFO 2025-01-16 05:07:31,539 autoreload C:\Users\Mihnea\Documents\Unibuc-FMI\2024-2025\Semestrul_1\Django\proiect\app_0\views.py changed, reloading.
INFO 2025-01-16 05:07:31,978 autoreload Watching for file changes with StatReloader
INFO 2025-01-16 05:07:42,577 autoreload C:\Users\Mihnea\Documents\Unibuc-FMI\2024-2025\Semestrul_1\Django\proiect\app_0\urls.py changed, reloading.
INFO 2025-01-16 05:07:42,995 autoreload Watching for file changes with StatReloader
INFO 2025-01-16 05:08:24,204 autoreload C:\Users\Mihnea\Documents\Unibuc-FMI\2024-2025\Semestrul_1\Django\proiect\app_0\views.py changed, reloading.
INFO 2025-01-16 05:08:24,622 autoreload Watching for file changes with StatReloader
INFO 2025-01-16 05:08:27,572 basehttp "GET /index/bilete/ HTTP/1.1" 200 6360
ERROR 2025-01-16 05:08:29,260 log Internal Server Error: /index/assign_offer_permission/
Traceback (most recent call last):
  File "C:\Users\Mihnea\AppData\Local\Programs\Python\Python312\Lib\site-packages\django\core\handlers\exception.py", line 55, in inner
    response = get_response(request)
               ^^^^^^^^^^^^^^^^^^^^^
  File "C:\Users\Mihnea\AppData\Local\Programs\Python\Python312\Lib\site-packages\django\core\handlers\base.py", line 197, in _get_response
    response = wrapped_callback(request, *callback_args, **callback_kwargs)
               ^^^^^^^^^^^^^^^^^^^^^^^^^^^^^^^^^^^^^^^^^^^^^^^^^^^^^^^^^^^^
  File "C:\Users\Mihnea\AppData\Local\Programs\Python\Python312\Lib\site-packages\django\contrib\auth\decorators.py", line 60, in _view_wrapper
    return view_func(request, *args, **kwargs)
           ^^^^^^^^^^^^^^^^^^^^^^^^^^^^^^^^^^^
  File "C:\Users\Mihnea\Documents\Unibuc-FMI\2024-2025\Semestrul_1\Django\proiect\app_0\views.py", line 283, in assign_offer_permission
    permission = Permission.objects.get(codename='vizualizeaza_oferta')
                 ^^^^^^^^^^^^^^^^^^^^^^^^^^^^^^^^^^^^^^^^^^^^^^^^^^^^^^
  File "C:\Users\Mihnea\AppData\Local\Programs\Python\Python312\Lib\site-packages\django\db\models\manager.py", line 87, in manager_method
    return getattr(self.get_queryset(), name)(*args, **kwargs)
           ^^^^^^^^^^^^^^^^^^^^^^^^^^^^^^^^^^^^^^^^^^^^^^^^^^^
  File "C:\Users\Mihnea\AppData\Local\Programs\Python\Python312\Lib\site-packages\django\db\models\query.py", line 649, in get
    raise self.model.DoesNotExist(
django.contrib.auth.models.Permission.DoesNotExist: Permission matching query does not exist.
ERROR 2025-01-16 05:08:29,262 basehttp "POST /index/assign_offer_permission/ HTTP/1.1" 500 84370
ERROR 2025-01-16 05:08:29,839 log Internal Server Error: /index/assign_offer_permission/
Traceback (most recent call last):
  File "C:\Users\Mihnea\AppData\Local\Programs\Python\Python312\Lib\site-packages\django\core\handlers\exception.py", line 55, in inner
    response = get_response(request)
               ^^^^^^^^^^^^^^^^^^^^^
  File "C:\Users\Mihnea\AppData\Local\Programs\Python\Python312\Lib\site-packages\django\core\handlers\base.py", line 197, in _get_response
    response = wrapped_callback(request, *callback_args, **callback_kwargs)
               ^^^^^^^^^^^^^^^^^^^^^^^^^^^^^^^^^^^^^^^^^^^^^^^^^^^^^^^^^^^^
  File "C:\Users\Mihnea\AppData\Local\Programs\Python\Python312\Lib\site-packages\django\contrib\auth\decorators.py", line 60, in _view_wrapper
    return view_func(request, *args, **kwargs)
           ^^^^^^^^^^^^^^^^^^^^^^^^^^^^^^^^^^^
  File "C:\Users\Mihnea\Documents\Unibuc-FMI\2024-2025\Semestrul_1\Django\proiect\app_0\views.py", line 283, in assign_offer_permission
    permission = Permission.objects.get(codename='vizualizeaza_oferta')
                 ^^^^^^^^^^^^^^^^^^^^^^^^^^^^^^^^^^^^^^^^^^^^^^^^^^^^^^
  File "C:\Users\Mihnea\AppData\Local\Programs\Python\Python312\Lib\site-packages\django\db\models\manager.py", line 87, in manager_method
    return getattr(self.get_queryset(), name)(*args, **kwargs)
           ^^^^^^^^^^^^^^^^^^^^^^^^^^^^^^^^^^^^^^^^^^^^^^^^^^^
  File "C:\Users\Mihnea\AppData\Local\Programs\Python\Python312\Lib\site-packages\django\db\models\query.py", line 649, in get
    raise self.model.DoesNotExist(
django.contrib.auth.models.Permission.DoesNotExist: Permission matching query does not exist.
ERROR 2025-01-16 05:08:29,841 basehttp "POST /index/assign_offer_permission/ HTTP/1.1" 500 84370
ERROR 2025-01-16 05:08:30,312 log Internal Server Error: /index/assign_offer_permission/
Traceback (most recent call last):
  File "C:\Users\Mihnea\AppData\Local\Programs\Python\Python312\Lib\site-packages\django\core\handlers\exception.py", line 55, in inner
    response = get_response(request)
               ^^^^^^^^^^^^^^^^^^^^^
  File "C:\Users\Mihnea\AppData\Local\Programs\Python\Python312\Lib\site-packages\django\core\handlers\base.py", line 197, in _get_response
    response = wrapped_callback(request, *callback_args, **callback_kwargs)
               ^^^^^^^^^^^^^^^^^^^^^^^^^^^^^^^^^^^^^^^^^^^^^^^^^^^^^^^^^^^^
  File "C:\Users\Mihnea\AppData\Local\Programs\Python\Python312\Lib\site-packages\django\contrib\auth\decorators.py", line 60, in _view_wrapper
    return view_func(request, *args, **kwargs)
           ^^^^^^^^^^^^^^^^^^^^^^^^^^^^^^^^^^^
  File "C:\Users\Mihnea\Documents\Unibuc-FMI\2024-2025\Semestrul_1\Django\proiect\app_0\views.py", line 283, in assign_offer_permission
    permission = Permission.objects.get(codename='vizualizeaza_oferta')
                 ^^^^^^^^^^^^^^^^^^^^^^^^^^^^^^^^^^^^^^^^^^^^^^^^^^^^^^
  File "C:\Users\Mihnea\AppData\Local\Programs\Python\Python312\Lib\site-packages\django\db\models\manager.py", line 87, in manager_method
    return getattr(self.get_queryset(), name)(*args, **kwargs)
           ^^^^^^^^^^^^^^^^^^^^^^^^^^^^^^^^^^^^^^^^^^^^^^^^^^^
  File "C:\Users\Mihnea\AppData\Local\Programs\Python\Python312\Lib\site-packages\django\db\models\query.py", line 649, in get
    raise self.model.DoesNotExist(
django.contrib.auth.models.Permission.DoesNotExist: Permission matching query does not exist.
ERROR 2025-01-16 05:08:30,313 basehttp "POST /index/assign_offer_permission/ HTTP/1.1" 500 84370
INFO 2025-01-16 05:08:35,155 basehttp "GET /index/oferta HTTP/1.1" 301 0
WARNING 2025-01-16 05:08:35,220 log Forbidden: /index/oferta/
WARNING 2025-01-16 05:08:35,221 basehttp "GET /index/oferta/ HTTP/1.1" 403 218
ERROR 2025-01-16 05:08:46,889 log Internal Server Error: /index/assign_offer_permission/
Traceback (most recent call last):
  File "C:\Users\Mihnea\AppData\Local\Programs\Python\Python312\Lib\site-packages\django\core\handlers\exception.py", line 55, in inner
    response = get_response(request)
               ^^^^^^^^^^^^^^^^^^^^^
  File "C:\Users\Mihnea\AppData\Local\Programs\Python\Python312\Lib\site-packages\django\core\handlers\base.py", line 197, in _get_response
    response = wrapped_callback(request, *callback_args, **callback_kwargs)
               ^^^^^^^^^^^^^^^^^^^^^^^^^^^^^^^^^^^^^^^^^^^^^^^^^^^^^^^^^^^^
  File "C:\Users\Mihnea\AppData\Local\Programs\Python\Python312\Lib\site-packages\django\contrib\auth\decorators.py", line 60, in _view_wrapper
    return view_func(request, *args, **kwargs)
           ^^^^^^^^^^^^^^^^^^^^^^^^^^^^^^^^^^^
  File "C:\Users\Mihnea\Documents\Unibuc-FMI\2024-2025\Semestrul_1\Django\proiect\app_0\views.py", line 283, in assign_offer_permission
    permission = Permission.objects.get(codename='vizualizeaza_oferta')
                 ^^^^^^^^^^^^^^^^^^^^^^^^^^^^^^^^^^^^^^^^^^^^^^^^^^^^^^
  File "C:\Users\Mihnea\AppData\Local\Programs\Python\Python312\Lib\site-packages\django\db\models\manager.py", line 87, in manager_method
    return getattr(self.get_queryset(), name)(*args, **kwargs)
           ^^^^^^^^^^^^^^^^^^^^^^^^^^^^^^^^^^^^^^^^^^^^^^^^^^^
  File "C:\Users\Mihnea\AppData\Local\Programs\Python\Python312\Lib\site-packages\django\db\models\query.py", line 649, in get
    raise self.model.DoesNotExist(
django.contrib.auth.models.Permission.DoesNotExist: Permission matching query does not exist.
ERROR 2025-01-16 05:08:46,891 basehttp "POST /index/assign_offer_permission/ HTTP/1.1" 500 84370
WARNING 2025-01-16 05:09:02,351 log Not Found: /index/adauga-oferta
WARNING 2025-01-16 05:09:02,351 basehttp "GET /index/adauga-oferta HTTP/1.1" 404 7333
INFO 2025-01-16 05:09:12,638 basehttp "GET /index/assign_offer_permission HTTP/1.1" 301 0
WARNING 2025-01-16 05:09:13,018 log Bad Request: /index/assign_offer_permission/
WARNING 2025-01-16 05:09:13,018 basehttp "GET /index/assign_offer_permission/ HTTP/1.1" 400 19
INFO 2025-01-16 05:10:56,496 autoreload C:\Users\Mihnea\Documents\Unibuc-FMI\2024-2025\Semestrul_1\Django\proiect\app_0\views.py changed, reloading.
INFO 2025-01-16 05:10:56,953 autoreload Watching for file changes with StatReloader
INFO 2025-01-16 05:11:24,896 autoreload C:\Users\Mihnea\Documents\Unibuc-FMI\2024-2025\Semestrul_1\Django\proiect\app_0\views.py changed, reloading.
INFO 2025-01-16 05:11:25,329 autoreload Watching for file changes with StatReloader
WARNING 2025-01-16 05:11:25,898 log Not Found: /index/adauga-oferta
WARNING 2025-01-16 05:11:25,899 basehttp "GET /index/adauga-oferta HTTP/1.1" 404 7333
INFO 2025-01-16 05:11:34,944 basehttp "GET /index/bilete/ HTTP/1.1" 200 6225
ERROR 2025-01-16 05:11:36,298 log Internal Server Error: /index/assign_offer_permission/
Traceback (most recent call last):
  File "C:\Users\Mihnea\AppData\Local\Programs\Python\Python312\Lib\site-packages\django\core\handlers\exception.py", line 55, in inner
    response = get_response(request)
               ^^^^^^^^^^^^^^^^^^^^^
  File "C:\Users\Mihnea\AppData\Local\Programs\Python\Python312\Lib\site-packages\django\core\handlers\base.py", line 197, in _get_response
    response = wrapped_callback(request, *callback_args, **callback_kwargs)
               ^^^^^^^^^^^^^^^^^^^^^^^^^^^^^^^^^^^^^^^^^^^^^^^^^^^^^^^^^^^^
  File "C:\Users\Mihnea\AppData\Local\Programs\Python\Python312\Lib\site-packages\django\contrib\auth\decorators.py", line 60, in _view_wrapper
    return view_func(request, *args, **kwargs)
           ^^^^^^^^^^^^^^^^^^^^^^^^^^^^^^^^^^^
  File "C:\Users\Mihnea\Documents\Unibuc-FMI\2024-2025\Semestrul_1\Django\proiect\app_0\views.py", line 283, in assign_offer_permission
    permission = Permission.objects.get(codename='vizualizeaza_oferta')
                 ^^^^^^^^^^^^^^^^^^^^^^^^^^^^^^^^^^^^^^^^^^^^^^^^^^^^^^
  File "C:\Users\Mihnea\AppData\Local\Programs\Python\Python312\Lib\site-packages\django\db\models\manager.py", line 87, in manager_method
    return getattr(self.get_queryset(), name)(*args, **kwargs)
           ^^^^^^^^^^^^^^^^^^^^^^^^^^^^^^^^^^^^^^^^^^^^^^^^^^^
  File "C:\Users\Mihnea\AppData\Local\Programs\Python\Python312\Lib\site-packages\django\db\models\query.py", line 649, in get
    raise self.model.DoesNotExist(
django.contrib.auth.models.Permission.DoesNotExist: Permission matching query does not exist.
ERROR 2025-01-16 05:11:36,300 basehttp "POST /index/assign_offer_permission/ HTTP/1.1" 500 84370
ERROR 2025-01-16 05:11:36,810 log Internal Server Error: /index/assign_offer_permission/
Traceback (most recent call last):
  File "C:\Users\Mihnea\AppData\Local\Programs\Python\Python312\Lib\site-packages\django\core\handlers\exception.py", line 55, in inner
    response = get_response(request)
               ^^^^^^^^^^^^^^^^^^^^^
  File "C:\Users\Mihnea\AppData\Local\Programs\Python\Python312\Lib\site-packages\django\core\handlers\base.py", line 197, in _get_response
    response = wrapped_callback(request, *callback_args, **callback_kwargs)
               ^^^^^^^^^^^^^^^^^^^^^^^^^^^^^^^^^^^^^^^^^^^^^^^^^^^^^^^^^^^^
  File "C:\Users\Mihnea\AppData\Local\Programs\Python\Python312\Lib\site-packages\django\contrib\auth\decorators.py", line 60, in _view_wrapper
    return view_func(request, *args, **kwargs)
           ^^^^^^^^^^^^^^^^^^^^^^^^^^^^^^^^^^^
  File "C:\Users\Mihnea\Documents\Unibuc-FMI\2024-2025\Semestrul_1\Django\proiect\app_0\views.py", line 283, in assign_offer_permission
    permission = Permission.objects.get(codename='vizualizeaza_oferta')
                 ^^^^^^^^^^^^^^^^^^^^^^^^^^^^^^^^^^^^^^^^^^^^^^^^^^^^^^
  File "C:\Users\Mihnea\AppData\Local\Programs\Python\Python312\Lib\site-packages\django\db\models\manager.py", line 87, in manager_method
    return getattr(self.get_queryset(), name)(*args, **kwargs)
           ^^^^^^^^^^^^^^^^^^^^^^^^^^^^^^^^^^^^^^^^^^^^^^^^^^^
  File "C:\Users\Mihnea\AppData\Local\Programs\Python\Python312\Lib\site-packages\django\db\models\query.py", line 649, in get
    raise self.model.DoesNotExist(
django.contrib.auth.models.Permission.DoesNotExist: Permission matching query does not exist.
ERROR 2025-01-16 05:11:36,811 basehttp "POST /index/assign_offer_permission/ HTTP/1.1" 500 84370
ERROR 2025-01-16 05:11:37,390 log Internal Server Error: /index/assign_offer_permission/
Traceback (most recent call last):
  File "C:\Users\Mihnea\AppData\Local\Programs\Python\Python312\Lib\site-packages\django\core\handlers\exception.py", line 55, in inner
    response = get_response(request)
               ^^^^^^^^^^^^^^^^^^^^^
  File "C:\Users\Mihnea\AppData\Local\Programs\Python\Python312\Lib\site-packages\django\core\handlers\base.py", line 197, in _get_response
    response = wrapped_callback(request, *callback_args, **callback_kwargs)
               ^^^^^^^^^^^^^^^^^^^^^^^^^^^^^^^^^^^^^^^^^^^^^^^^^^^^^^^^^^^^
  File "C:\Users\Mihnea\AppData\Local\Programs\Python\Python312\Lib\site-packages\django\contrib\auth\decorators.py", line 60, in _view_wrapper
    return view_func(request, *args, **kwargs)
           ^^^^^^^^^^^^^^^^^^^^^^^^^^^^^^^^^^^
  File "C:\Users\Mihnea\Documents\Unibuc-FMI\2024-2025\Semestrul_1\Django\proiect\app_0\views.py", line 283, in assign_offer_permission
    permission = Permission.objects.get(codename='vizualizeaza_oferta')
                 ^^^^^^^^^^^^^^^^^^^^^^^^^^^^^^^^^^^^^^^^^^^^^^^^^^^^^^
  File "C:\Users\Mihnea\AppData\Local\Programs\Python\Python312\Lib\site-packages\django\db\models\manager.py", line 87, in manager_method
    return getattr(self.get_queryset(), name)(*args, **kwargs)
           ^^^^^^^^^^^^^^^^^^^^^^^^^^^^^^^^^^^^^^^^^^^^^^^^^^^
  File "C:\Users\Mihnea\AppData\Local\Programs\Python\Python312\Lib\site-packages\django\db\models\query.py", line 649, in get
    raise self.model.DoesNotExist(
django.contrib.auth.models.Permission.DoesNotExist: Permission matching query does not exist.
ERROR 2025-01-16 05:11:37,392 basehttp "POST /index/assign_offer_permission/ HTTP/1.1" 500 84370
ERROR 2025-01-16 05:11:38,056 log Internal Server Error: /index/assign_offer_permission/
Traceback (most recent call last):
  File "C:\Users\Mihnea\AppData\Local\Programs\Python\Python312\Lib\site-packages\django\core\handlers\exception.py", line 55, in inner
    response = get_response(request)
               ^^^^^^^^^^^^^^^^^^^^^
  File "C:\Users\Mihnea\AppData\Local\Programs\Python\Python312\Lib\site-packages\django\core\handlers\base.py", line 197, in _get_response
    response = wrapped_callback(request, *callback_args, **callback_kwargs)
               ^^^^^^^^^^^^^^^^^^^^^^^^^^^^^^^^^^^^^^^^^^^^^^^^^^^^^^^^^^^^
  File "C:\Users\Mihnea\AppData\Local\Programs\Python\Python312\Lib\site-packages\django\contrib\auth\decorators.py", line 60, in _view_wrapper
    return view_func(request, *args, **kwargs)
           ^^^^^^^^^^^^^^^^^^^^^^^^^^^^^^^^^^^
  File "C:\Users\Mihnea\Documents\Unibuc-FMI\2024-2025\Semestrul_1\Django\proiect\app_0\views.py", line 283, in assign_offer_permission
    permission = Permission.objects.get(codename='vizualizeaza_oferta')
                 ^^^^^^^^^^^^^^^^^^^^^^^^^^^^^^^^^^^^^^^^^^^^^^^^^^^^^^
  File "C:\Users\Mihnea\AppData\Local\Programs\Python\Python312\Lib\site-packages\django\db\models\manager.py", line 87, in manager_method
    return getattr(self.get_queryset(), name)(*args, **kwargs)
           ^^^^^^^^^^^^^^^^^^^^^^^^^^^^^^^^^^^^^^^^^^^^^^^^^^^
  File "C:\Users\Mihnea\AppData\Local\Programs\Python\Python312\Lib\site-packages\django\db\models\query.py", line 649, in get
    raise self.model.DoesNotExist(
django.contrib.auth.models.Permission.DoesNotExist: Permission matching query does not exist.
ERROR 2025-01-16 05:11:38,057 basehttp "POST /index/assign_offer_permission/ HTTP/1.1" 500 84370
ERROR 2025-01-16 05:11:39,789 log Internal Server Error: /index/assign_offer_permission/
Traceback (most recent call last):
  File "C:\Users\Mihnea\AppData\Local\Programs\Python\Python312\Lib\site-packages\django\core\handlers\exception.py", line 55, in inner
    response = get_response(request)
               ^^^^^^^^^^^^^^^^^^^^^
  File "C:\Users\Mihnea\AppData\Local\Programs\Python\Python312\Lib\site-packages\django\core\handlers\base.py", line 197, in _get_response
    response = wrapped_callback(request, *callback_args, **callback_kwargs)
               ^^^^^^^^^^^^^^^^^^^^^^^^^^^^^^^^^^^^^^^^^^^^^^^^^^^^^^^^^^^^
  File "C:\Users\Mihnea\AppData\Local\Programs\Python\Python312\Lib\site-packages\django\contrib\auth\decorators.py", line 60, in _view_wrapper
    return view_func(request, *args, **kwargs)
           ^^^^^^^^^^^^^^^^^^^^^^^^^^^^^^^^^^^
  File "C:\Users\Mihnea\Documents\Unibuc-FMI\2024-2025\Semestrul_1\Django\proiect\app_0\views.py", line 283, in assign_offer_permission
    permission = Permission.objects.get(codename='vizualizeaza_oferta')
                 ^^^^^^^^^^^^^^^^^^^^^^^^^^^^^^^^^^^^^^^^^^^^^^^^^^^^^^
  File "C:\Users\Mihnea\AppData\Local\Programs\Python\Python312\Lib\site-packages\django\db\models\manager.py", line 87, in manager_method
    return getattr(self.get_queryset(), name)(*args, **kwargs)
           ^^^^^^^^^^^^^^^^^^^^^^^^^^^^^^^^^^^^^^^^^^^^^^^^^^^
  File "C:\Users\Mihnea\AppData\Local\Programs\Python\Python312\Lib\site-packages\django\db\models\query.py", line 649, in get
    raise self.model.DoesNotExist(
django.contrib.auth.models.Permission.DoesNotExist: Permission matching query does not exist.
ERROR 2025-01-16 05:11:39,790 basehttp "POST /index/assign_offer_permission/ HTTP/1.1" 500 84370
INFO 2025-01-16 05:12:33,799 basehttp "GET /index/bilete/ HTTP/1.1" 200 6409
INFO 2025-01-16 05:12:34,388 basehttp "GET /index/bilete/ HTTP/1.1" 200 6409
INFO 2025-01-16 05:12:34,953 basehttp "GET /index/bilete/ HTTP/1.1" 200 6409
INFO 2025-01-16 05:12:35,478 basehttp "GET /index/bilete/ HTTP/1.1" 200 6409
INFO 2025-01-16 05:12:35,947 basehttp "GET /index/bilete/ HTTP/1.1" 200 6409
INFO 2025-01-16 05:12:37,267 basehttp "GET /index/bilete/ HTTP/1.1" 200 6409
INFO 2025-01-16 05:12:38,264 basehttp "GET /index/bilete/ HTTP/1.1" 200 6409
INFO 2025-01-16 05:12:40,272 basehttp "GET /index/bilete/ HTTP/1.1" 200 6409
INFO 2025-01-16 05:12:41,013 basehttp "GET /index/bilete/ HTTP/1.1" 200 6409
INFO 2025-01-16 05:12:41,525 basehttp "GET /index/bilete/ HTTP/1.1" 200 6409
INFO 2025-01-16 05:12:41,693 basehttp "GET /index/bilete/ HTTP/1.1" 200 6409
INFO 2025-01-16 05:12:42,075 basehttp "GET /index/bilete/ HTTP/1.1" 200 6409
INFO 2025-01-16 05:12:42,396 basehttp "GET /index/bilete/ HTTP/1.1" 200 6409
INFO 2025-01-16 05:12:42,811 basehttp "GET /index/bilete/ HTTP/1.1" 200 6409
INFO 2025-01-16 05:12:43,261 basehttp "GET /index/bilete/ HTTP/1.1" 200 6409
INFO 2025-01-16 05:12:45,714 basehttp "GET /index/bilete/ HTTP/1.1" 200 6409
INFO 2025-01-16 05:12:53,848 basehttp "GET /index/bilete/ HTTP/1.1" 200 6407
INFO 2025-01-16 05:12:55,162 basehttp "GET /index/bilete/ HTTP/1.1" 200 6407
INFO 2025-01-16 05:12:59,800 basehttp "GET /index/bilete/ HTTP/1.1" 200 6411
ERROR 2025-01-16 05:13:16,907 log Internal Server Error: /index/bilete/
Traceback (most recent call last):
  File "C:\Users\Mihnea\AppData\Local\Programs\Python\Python312\Lib\site-packages\django\core\handlers\exception.py", line 55, in inner
    response = get_response(request)
               ^^^^^^^^^^^^^^^^^^^^^
  File "C:\Users\Mihnea\AppData\Local\Programs\Python\Python312\Lib\site-packages\django\core\handlers\base.py", line 197, in _get_response
    response = wrapped_callback(request, *callback_args, **callback_kwargs)
               ^^^^^^^^^^^^^^^^^^^^^^^^^^^^^^^^^^^^^^^^^^^^^^^^^^^^^^^^^^^^
  File "C:\Users\Mihnea\Documents\Unibuc-FMI\2024-2025\Semestrul_1\Django\proiect\app_0\views.py", line 57, in lista_bilete
    return render(request, 'app_0/lista_bilete.html', {'form': form, 'page_obj': page_obj})
           ^^^^^^^^^^^^^^^^^^^^^^^^^^^^^^^^^^^^^^^^^^^^^^^^^^^^^^^^^^^^^^^^^^^^^^^^^^^^^^^^
  File "C:\Users\Mihnea\AppData\Local\Programs\Python\Python312\Lib\site-packages\django\shortcuts.py", line 25, in render
    content = loader.render_to_string(template_name, context, request, using=using)
              ^^^^^^^^^^^^^^^^^^^^^^^^^^^^^^^^^^^^^^^^^^^^^^^^^^^^^^^^^^^^^^^^^^^^^
  File "C:\Users\Mihnea\AppData\Local\Programs\Python\Python312\Lib\site-packages\django\template\loader.py", line 62, in render_to_string
    return template.render(context, request)
           ^^^^^^^^^^^^^^^^^^^^^^^^^^^^^^^^^
  File "C:\Users\Mihnea\AppData\Local\Programs\Python\Python312\Lib\site-packages\django\template\backends\django.py", line 107, in render
    return self.template.render(context)
           ^^^^^^^^^^^^^^^^^^^^^^^^^^^^^
  File "C:\Users\Mihnea\AppData\Local\Programs\Python\Python312\Lib\site-packages\django\template\base.py", line 171, in render
    return self._render(context)
           ^^^^^^^^^^^^^^^^^^^^^
  File "C:\Users\Mihnea\AppData\Local\Programs\Python\Python312\Lib\site-packages\django\template\base.py", line 163, in _render
    return self.nodelist.render(context)
           ^^^^^^^^^^^^^^^^^^^^^^^^^^^^^
  File "C:\Users\Mihnea\AppData\Local\Programs\Python\Python312\Lib\site-packages\django\template\base.py", line 1008, in render
    return SafeString("".join([node.render_annotated(context) for node in self]))
                               ^^^^^^^^^^^^^^^^^^^^^^^^^^^^^^
  File "C:\Users\Mihnea\AppData\Local\Programs\Python\Python312\Lib\site-packages\django\template\base.py", line 969, in render_annotated
    return self.render(context)
           ^^^^^^^^^^^^^^^^^^^^
  File "C:\Users\Mihnea\AppData\Local\Programs\Python\Python312\Lib\site-packages\django\template\defaulttags.py", line 327, in render
    return nodelist.render(context)
           ^^^^^^^^^^^^^^^^^^^^^^^^
  File "C:\Users\Mihnea\AppData\Local\Programs\Python\Python312\Lib\site-packages\django\template\base.py", line 1008, in render
    return SafeString("".join([node.render_annotated(context) for node in self]))
                               ^^^^^^^^^^^^^^^^^^^^^^^^^^^^^^
  File "C:\Users\Mihnea\AppData\Local\Programs\Python\Python312\Lib\site-packages\django\template\base.py", line 969, in render_annotated
    return self.render(context)
           ^^^^^^^^^^^^^^^^^^^^
  File "C:\Users\Mihnea\AppData\Local\Programs\Python\Python312\Lib\site-packages\django\template\defaulttags.py", line 480, in render
    url = reverse(view_name, args=args, kwargs=kwargs, current_app=current_app)
          ^^^^^^^^^^^^^^^^^^^^^^^^^^^^^^^^^^^^^^^^^^^^^^^^^^^^^^^^^^^^^^^^^^^^^
  File "C:\Users\Mihnea\AppData\Local\Programs\Python\Python312\Lib\site-packages\django\urls\base.py", line 88, in reverse
    return resolver._reverse_with_prefix(view, prefix, *args, **kwargs)
           ^^^^^^^^^^^^^^^^^^^^^^^^^^^^^^^^^^^^^^^^^^^^^^^^^^^^^^^^^^^^
  File "C:\Users\Mihnea\AppData\Local\Programs\Python\Python312\Lib\site-packages\django\urls\resolvers.py", line 831, in _reverse_with_prefix
    raise NoReverseMatch(msg)
django.urls.exceptions.NoReverseMatch: Reverse for 'oferta.html' not found. 'oferta.html' is not a valid view function or pattern name.
ERROR 2025-01-16 05:13:20,078 basehttp "GET /index/bilete/ HTTP/1.1" 500 136761
INFO 2025-01-16 05:13:52,848 autoreload Watching for file changes with StatReloader
INFO 2025-01-16 05:13:53,187 basehttp "GET /index/bilete/ HTTP/1.1" 200 6238
INFO 2025-01-16 05:13:54,309 basehttp "GET /index/bilete/ HTTP/1.1" 200 6238
INFO 2025-01-16 05:13:59,147 basehttp "GET /index/bilete/ HTTP/1.1" 200 6236
ERROR 2025-01-16 05:14:01,100 log Internal Server Error: /index/assign_offer_permission/
Traceback (most recent call last):
  File "C:\Users\Mihnea\AppData\Local\Programs\Python\Python312\Lib\site-packages\django\core\handlers\exception.py", line 55, in inner
    response = get_response(request)
               ^^^^^^^^^^^^^^^^^^^^^
  File "C:\Users\Mihnea\AppData\Local\Programs\Python\Python312\Lib\site-packages\django\core\handlers\base.py", line 197, in _get_response
    response = wrapped_callback(request, *callback_args, **callback_kwargs)
               ^^^^^^^^^^^^^^^^^^^^^^^^^^^^^^^^^^^^^^^^^^^^^^^^^^^^^^^^^^^^
  File "C:\Users\Mihnea\AppData\Local\Programs\Python\Python312\Lib\site-packages\django\contrib\auth\decorators.py", line 60, in _view_wrapper
    return view_func(request, *args, **kwargs)
           ^^^^^^^^^^^^^^^^^^^^^^^^^^^^^^^^^^^
  File "C:\Users\Mihnea\Documents\Unibuc-FMI\2024-2025\Semestrul_1\Django\proiect\app_0\views.py", line 283, in assign_offer_permission
    permission = Permission.objects.get(codename='vizualizeaza_oferta')
                 ^^^^^^^^^^^^^^^^^^^^^^^^^^^^^^^^^^^^^^^^^^^^^^^^^^^^^^
  File "C:\Users\Mihnea\AppData\Local\Programs\Python\Python312\Lib\site-packages\django\db\models\manager.py", line 87, in manager_method
    return getattr(self.get_queryset(), name)(*args, **kwargs)
           ^^^^^^^^^^^^^^^^^^^^^^^^^^^^^^^^^^^^^^^^^^^^^^^^^^^
  File "C:\Users\Mihnea\AppData\Local\Programs\Python\Python312\Lib\site-packages\django\db\models\query.py", line 649, in get
    raise self.model.DoesNotExist(
django.contrib.auth.models.Permission.DoesNotExist: Permission matching query does not exist.
ERROR 2025-01-16 05:14:01,101 basehttp "POST /index/assign_offer_permission/ HTTP/1.1" 500 84370
ERROR 2025-01-16 05:14:01,685 log Internal Server Error: /index/assign_offer_permission/
Traceback (most recent call last):
  File "C:\Users\Mihnea\AppData\Local\Programs\Python\Python312\Lib\site-packages\django\core\handlers\exception.py", line 55, in inner
    response = get_response(request)
               ^^^^^^^^^^^^^^^^^^^^^
  File "C:\Users\Mihnea\AppData\Local\Programs\Python\Python312\Lib\site-packages\django\core\handlers\base.py", line 197, in _get_response
    response = wrapped_callback(request, *callback_args, **callback_kwargs)
               ^^^^^^^^^^^^^^^^^^^^^^^^^^^^^^^^^^^^^^^^^^^^^^^^^^^^^^^^^^^^
  File "C:\Users\Mihnea\AppData\Local\Programs\Python\Python312\Lib\site-packages\django\contrib\auth\decorators.py", line 60, in _view_wrapper
    return view_func(request, *args, **kwargs)
           ^^^^^^^^^^^^^^^^^^^^^^^^^^^^^^^^^^^
  File "C:\Users\Mihnea\Documents\Unibuc-FMI\2024-2025\Semestrul_1\Django\proiect\app_0\views.py", line 283, in assign_offer_permission
    permission = Permission.objects.get(codename='vizualizeaza_oferta')
                 ^^^^^^^^^^^^^^^^^^^^^^^^^^^^^^^^^^^^^^^^^^^^^^^^^^^^^^
  File "C:\Users\Mihnea\AppData\Local\Programs\Python\Python312\Lib\site-packages\django\db\models\manager.py", line 87, in manager_method
    return getattr(self.get_queryset(), name)(*args, **kwargs)
           ^^^^^^^^^^^^^^^^^^^^^^^^^^^^^^^^^^^^^^^^^^^^^^^^^^^
  File "C:\Users\Mihnea\AppData\Local\Programs\Python\Python312\Lib\site-packages\django\db\models\query.py", line 649, in get
    raise self.model.DoesNotExist(
django.contrib.auth.models.Permission.DoesNotExist: Permission matching query does not exist.
ERROR 2025-01-16 05:14:01,687 basehttp "POST /index/assign_offer_permission/ HTTP/1.1" 500 84370
ERROR 2025-01-16 05:14:02,635 log Internal Server Error: /index/assign_offer_permission/
Traceback (most recent call last):
  File "C:\Users\Mihnea\AppData\Local\Programs\Python\Python312\Lib\site-packages\django\core\handlers\exception.py", line 55, in inner
    response = get_response(request)
               ^^^^^^^^^^^^^^^^^^^^^
  File "C:\Users\Mihnea\AppData\Local\Programs\Python\Python312\Lib\site-packages\django\core\handlers\base.py", line 197, in _get_response
    response = wrapped_callback(request, *callback_args, **callback_kwargs)
               ^^^^^^^^^^^^^^^^^^^^^^^^^^^^^^^^^^^^^^^^^^^^^^^^^^^^^^^^^^^^
  File "C:\Users\Mihnea\AppData\Local\Programs\Python\Python312\Lib\site-packages\django\contrib\auth\decorators.py", line 60, in _view_wrapper
    return view_func(request, *args, **kwargs)
           ^^^^^^^^^^^^^^^^^^^^^^^^^^^^^^^^^^^
  File "C:\Users\Mihnea\Documents\Unibuc-FMI\2024-2025\Semestrul_1\Django\proiect\app_0\views.py", line 283, in assign_offer_permission
    permission = Permission.objects.get(codename='vizualizeaza_oferta')
                 ^^^^^^^^^^^^^^^^^^^^^^^^^^^^^^^^^^^^^^^^^^^^^^^^^^^^^^
  File "C:\Users\Mihnea\AppData\Local\Programs\Python\Python312\Lib\site-packages\django\db\models\manager.py", line 87, in manager_method
    return getattr(self.get_queryset(), name)(*args, **kwargs)
           ^^^^^^^^^^^^^^^^^^^^^^^^^^^^^^^^^^^^^^^^^^^^^^^^^^^
  File "C:\Users\Mihnea\AppData\Local\Programs\Python\Python312\Lib\site-packages\django\db\models\query.py", line 649, in get
    raise self.model.DoesNotExist(
django.contrib.auth.models.Permission.DoesNotExist: Permission matching query does not exist.
ERROR 2025-01-16 05:14:02,636 basehttp "POST /index/assign_offer_permission/ HTTP/1.1" 500 84370
ERROR 2025-01-16 05:14:02,778 log Internal Server Error: /index/assign_offer_permission/
Traceback (most recent call last):
  File "C:\Users\Mihnea\AppData\Local\Programs\Python\Python312\Lib\site-packages\django\core\handlers\exception.py", line 55, in inner
    response = get_response(request)
               ^^^^^^^^^^^^^^^^^^^^^
  File "C:\Users\Mihnea\AppData\Local\Programs\Python\Python312\Lib\site-packages\django\core\handlers\base.py", line 197, in _get_response
    response = wrapped_callback(request, *callback_args, **callback_kwargs)
               ^^^^^^^^^^^^^^^^^^^^^^^^^^^^^^^^^^^^^^^^^^^^^^^^^^^^^^^^^^^^
  File "C:\Users\Mihnea\AppData\Local\Programs\Python\Python312\Lib\site-packages\django\contrib\auth\decorators.py", line 60, in _view_wrapper
    return view_func(request, *args, **kwargs)
           ^^^^^^^^^^^^^^^^^^^^^^^^^^^^^^^^^^^
  File "C:\Users\Mihnea\Documents\Unibuc-FMI\2024-2025\Semestrul_1\Django\proiect\app_0\views.py", line 283, in assign_offer_permission
    permission = Permission.objects.get(codename='vizualizeaza_oferta')
                 ^^^^^^^^^^^^^^^^^^^^^^^^^^^^^^^^^^^^^^^^^^^^^^^^^^^^^^
  File "C:\Users\Mihnea\AppData\Local\Programs\Python\Python312\Lib\site-packages\django\db\models\manager.py", line 87, in manager_method
    return getattr(self.get_queryset(), name)(*args, **kwargs)
           ^^^^^^^^^^^^^^^^^^^^^^^^^^^^^^^^^^^^^^^^^^^^^^^^^^^
  File "C:\Users\Mihnea\AppData\Local\Programs\Python\Python312\Lib\site-packages\django\db\models\query.py", line 649, in get
    raise self.model.DoesNotExist(
django.contrib.auth.models.Permission.DoesNotExist: Permission matching query does not exist.
ERROR 2025-01-16 05:14:02,780 basehttp "POST /index/assign_offer_permission/ HTTP/1.1" 500 84370
INFO 2025-01-16 05:15:45,246 basehttp "GET /index/bilete/ HTTP/1.1" 200 6221
ERROR 2025-01-16 05:15:47,385 log Internal Server Error: /index/assign_offer_permission/
Traceback (most recent call last):
  File "C:\Users\Mihnea\AppData\Local\Programs\Python\Python312\Lib\site-packages\django\core\handlers\exception.py", line 55, in inner
    response = get_response(request)
               ^^^^^^^^^^^^^^^^^^^^^
  File "C:\Users\Mihnea\AppData\Local\Programs\Python\Python312\Lib\site-packages\django\core\handlers\base.py", line 197, in _get_response
    response = wrapped_callback(request, *callback_args, **callback_kwargs)
               ^^^^^^^^^^^^^^^^^^^^^^^^^^^^^^^^^^^^^^^^^^^^^^^^^^^^^^^^^^^^
  File "C:\Users\Mihnea\AppData\Local\Programs\Python\Python312\Lib\site-packages\django\contrib\auth\decorators.py", line 60, in _view_wrapper
    return view_func(request, *args, **kwargs)
           ^^^^^^^^^^^^^^^^^^^^^^^^^^^^^^^^^^^
  File "C:\Users\Mihnea\Documents\Unibuc-FMI\2024-2025\Semestrul_1\Django\proiect\app_0\views.py", line 283, in assign_offer_permission
    permission = Permission.objects.get(codename='vizualizeaza_oferta')
                 ^^^^^^^^^^^^^^^^^^^^^^^^^^^^^^^^^^^^^^^^^^^^^^^^^^^^^^
  File "C:\Users\Mihnea\AppData\Local\Programs\Python\Python312\Lib\site-packages\django\db\models\manager.py", line 87, in manager_method
    return getattr(self.get_queryset(), name)(*args, **kwargs)
           ^^^^^^^^^^^^^^^^^^^^^^^^^^^^^^^^^^^^^^^^^^^^^^^^^^^
  File "C:\Users\Mihnea\AppData\Local\Programs\Python\Python312\Lib\site-packages\django\db\models\query.py", line 649, in get
    raise self.model.DoesNotExist(
django.contrib.auth.models.Permission.DoesNotExist: Permission matching query does not exist.
ERROR 2025-01-16 05:15:47,387 basehttp "POST /index/assign_offer_permission/ HTTP/1.1" 500 84370
ERROR 2025-01-16 05:15:47,955 log Internal Server Error: /index/assign_offer_permission/
Traceback (most recent call last):
  File "C:\Users\Mihnea\AppData\Local\Programs\Python\Python312\Lib\site-packages\django\core\handlers\exception.py", line 55, in inner
    response = get_response(request)
               ^^^^^^^^^^^^^^^^^^^^^
  File "C:\Users\Mihnea\AppData\Local\Programs\Python\Python312\Lib\site-packages\django\core\handlers\base.py", line 197, in _get_response
    response = wrapped_callback(request, *callback_args, **callback_kwargs)
               ^^^^^^^^^^^^^^^^^^^^^^^^^^^^^^^^^^^^^^^^^^^^^^^^^^^^^^^^^^^^
  File "C:\Users\Mihnea\AppData\Local\Programs\Python\Python312\Lib\site-packages\django\contrib\auth\decorators.py", line 60, in _view_wrapper
    return view_func(request, *args, **kwargs)
           ^^^^^^^^^^^^^^^^^^^^^^^^^^^^^^^^^^^
  File "C:\Users\Mihnea\Documents\Unibuc-FMI\2024-2025\Semestrul_1\Django\proiect\app_0\views.py", line 283, in assign_offer_permission
    permission = Permission.objects.get(codename='vizualizeaza_oferta')
                 ^^^^^^^^^^^^^^^^^^^^^^^^^^^^^^^^^^^^^^^^^^^^^^^^^^^^^^
  File "C:\Users\Mihnea\AppData\Local\Programs\Python\Python312\Lib\site-packages\django\db\models\manager.py", line 87, in manager_method
    return getattr(self.get_queryset(), name)(*args, **kwargs)
           ^^^^^^^^^^^^^^^^^^^^^^^^^^^^^^^^^^^^^^^^^^^^^^^^^^^
  File "C:\Users\Mihnea\AppData\Local\Programs\Python\Python312\Lib\site-packages\django\db\models\query.py", line 649, in get
    raise self.model.DoesNotExist(
django.contrib.auth.models.Permission.DoesNotExist: Permission matching query does not exist.
ERROR 2025-01-16 05:15:47,956 basehttp "POST /index/assign_offer_permission/ HTTP/1.1" 500 84370
INFO 2025-01-16 05:15:55,029 basehttp "GET /index/bilete/ HTTP/1.1" 200 6227
ERROR 2025-01-16 05:15:56,791 log Internal Server Error: /index/assign_offer_permission/
Traceback (most recent call last):
  File "C:\Users\Mihnea\AppData\Local\Programs\Python\Python312\Lib\site-packages\django\core\handlers\exception.py", line 55, in inner
    response = get_response(request)
               ^^^^^^^^^^^^^^^^^^^^^
  File "C:\Users\Mihnea\AppData\Local\Programs\Python\Python312\Lib\site-packages\django\core\handlers\base.py", line 197, in _get_response
    response = wrapped_callback(request, *callback_args, **callback_kwargs)
               ^^^^^^^^^^^^^^^^^^^^^^^^^^^^^^^^^^^^^^^^^^^^^^^^^^^^^^^^^^^^
  File "C:\Users\Mihnea\AppData\Local\Programs\Python\Python312\Lib\site-packages\django\contrib\auth\decorators.py", line 60, in _view_wrapper
    return view_func(request, *args, **kwargs)
           ^^^^^^^^^^^^^^^^^^^^^^^^^^^^^^^^^^^
  File "C:\Users\Mihnea\Documents\Unibuc-FMI\2024-2025\Semestrul_1\Django\proiect\app_0\views.py", line 283, in assign_offer_permission
    permission = Permission.objects.get(codename='vizualizeaza_oferta')
                 ^^^^^^^^^^^^^^^^^^^^^^^^^^^^^^^^^^^^^^^^^^^^^^^^^^^^^^
  File "C:\Users\Mihnea\AppData\Local\Programs\Python\Python312\Lib\site-packages\django\db\models\manager.py", line 87, in manager_method
    return getattr(self.get_queryset(), name)(*args, **kwargs)
           ^^^^^^^^^^^^^^^^^^^^^^^^^^^^^^^^^^^^^^^^^^^^^^^^^^^
  File "C:\Users\Mihnea\AppData\Local\Programs\Python\Python312\Lib\site-packages\django\db\models\query.py", line 649, in get
    raise self.model.DoesNotExist(
django.contrib.auth.models.Permission.DoesNotExist: Permission matching query does not exist.
ERROR 2025-01-16 05:15:56,793 basehttp "POST /index/assign_offer_permission/ HTTP/1.1" 500 84370
INFO 2025-01-16 05:16:04,366 basehttp "GET /index/bilete/ HTTP/1.1" 200 6227
INFO 2025-01-16 05:16:12,517 basehttp "GET /index/bilete/ HTTP/1.1" 200 6221
INFO 2025-01-16 05:16:20,160 basehttp "GET /index/bilete/ HTTP/1.1" 200 6226
INFO 2025-01-16 05:16:29,441 basehttp "GET /index/bilete/ HTTP/1.1" 200 6225
INFO 2025-01-16 05:16:51,048 basehttp "GET /index/bilete/ HTTP/1.1" 200 6224
INFO 2025-01-16 05:17:25,904 autoreload C:\Users\Mihnea\Documents\Unibuc-FMI\2024-2025\Semestrul_1\Django\proiect\app_0\views.py changed, reloading.
INFO 2025-01-16 05:17:26,372 autoreload Watching for file changes with StatReloader
INFO 2025-01-16 05:17:34,919 autoreload C:\Users\Mihnea\Documents\Unibuc-FMI\2024-2025\Semestrul_1\Django\proiect\app_0\views.py changed, reloading.
INFO 2025-01-16 05:17:35,364 autoreload Watching for file changes with StatReloader
INFO 2025-01-16 05:17:37,950 basehttp "GET /index/bilete/ HTTP/1.1" 200 6224
WARNING 2025-01-16 05:17:39,694 log Bad Request: /index/assign_offer_permission/
WARNING 2025-01-16 05:17:39,695 basehttp "POST /index/assign_offer_permission/ HTTP/1.1" 400 59
WARNING 2025-01-16 05:17:40,317 log Bad Request: /index/assign_offer_permission/
WARNING 2025-01-16 05:17:40,319 basehttp "POST /index/assign_offer_permission/ HTTP/1.1" 400 59
WARNING 2025-01-16 05:17:43,263 log Forbidden: /index/oferta/
WARNING 2025-01-16 05:17:43,264 basehttp "GET /index/oferta/ HTTP/1.1" 403 218
