ERROR 2025-01-16 02:08:02,670 views Login failed for username: Velcq
ERROR 2025-01-16 02:08:04,914 views Login failed for username: Velcq
ERROR 2025-01-16 02:08:06,869 views Login failed for username: Velcq
WARNING 2025-01-16 02:08:09,658 views Suspicious login attempts for username: Velcq from IP: 127.0.0.1
ERROR 2025-01-16 02:08:10,162 views Login failed for username: Velcq
ERROR 2025-01-16 02:08:50,592 log Internal Server Error: /index/register/
Traceback (most recent call last):
  File "C:\Users\Mihnea\AppData\Local\Programs\Python\Python312\Lib\site-packages\django\core\handlers\exception.py", line 55, in inner
    response = get_response(request)
               ^^^^^^^^^^^^^^^^^^^^^
  File "C:\Users\Mihnea\AppData\Local\Programs\Python\Python312\Lib\site-packages\django\core\handlers\base.py", line 197, in _get_response
    response = wrapped_callback(request, *callback_args, **callback_kwargs)
               ^^^^^^^^^^^^^^^^^^^^^^^^^^^^^^^^^^^^^^^^^^^^^^^^^^^^^^^^^^^^
  File "C:\Users\Mihnea\Documents\Unibuc-FMI\2024-2025\Semestrul_1\Django\proiect\app_0\views.py", line 103, in register
    messages.error(request, 'This username is not allowed.')
    ^^^^^^^^^^^^^^
AttributeError: 'dict' object has no attribute 'error'
ERROR 2025-01-16 02:08:50,594 basehttp "POST /index/register/ HTTP/1.1" 500 72624
CRITICAL 2025-01-16 02:10:23,377 views Attempt to register with username 'admin' from email: mihneave2004@gmail.com
CRITICAL 2025-01-16 02:10:48,526 views Attempt to register with username 'admin' from email: mihneave2004@gmail.com
WARNING 2025-01-16 02:12:22,795 log Not Found: /index/recent_purchases
WARNING 2025-01-16 02:12:22,796 basehttp "GET /index/recent_purchases HTTP/1.1" 404 6942
ERROR 2025-01-16 02:12:40,584 views Login failed for username: Velcq
WARNING 2025-01-16 02:12:59,777 log Not Found: /index/recent_purchases
WARNING 2025-01-16 02:12:59,777 basehttp "GET /index/recent_purchases HTTP/1.1" 404 6942
WARNING 2025-01-16 02:13:03,856 log Not Found: /index/recent_purchases/Velcq
WARNING 2025-01-16 02:13:03,856 basehttp "GET /index/recent_purchases/Velcq HTTP/1.1" 404 6966
WARNING 2025-01-16 02:14:08,031 log Not Found: /index/recent_purchases
WARNING 2025-01-16 02:14:08,032 basehttp "GET /index/recent_purchases HTTP/1.1" 404 6942
CRITICAL 2025-01-16 02:14:24,191 views An error occurred: Cannot resolve keyword 'user' into field. Choices are: cursa, cursa_id, id, loc, pret, vagon, vagon_id, vizualizare
ERROR 2025-01-16 02:14:24,191 log Internal Server Error: /index/recent_purchases/
ERROR 2025-01-16 02:14:24,192 basehttp "GET /index/recent_purchases/ HTTP/1.1" 500 18
WARNING 2025-01-16 02:18:02,070 log Not Found: /index/test_403
WARNING 2025-01-16 02:18:02,071 basehttp "GET /index/test_403 HTTP/1.1" 404 7175
WARNING 2025-01-16 02:18:57,340 log Not Found: /index/test_403
WARNING 2025-01-16 02:18:57,340 basehttp "GET /index/test_403 HTTP/1.1" 404 7175
WARNING 2025-01-16 02:18:58,032 log Not Found: /index/test_403
WARNING 2025-01-16 02:18:58,033 basehttp "GET /index/test_403 HTTP/1.1" 404 7175
WARNING 2025-01-16 02:18:58,719 log Not Found: /index/test_403
WARNING 2025-01-16 02:18:58,720 basehttp "GET /index/test_403 HTTP/1.1" 404 7175
WARNING 2025-01-16 02:20:52,609 log Not Found: /aplicatieProj/confirmare_email/dd0c555c-f8d4-412c-b795-be23bf6f8d64/
WARNING 2025-01-16 02:20:52,610 basehttp "GET /aplicatieProj/confirmare_email/dd0c555c-f8d4-412c-b795-be23bf6f8d64/ HTTP/1.1" 404 3168
WARNING 2025-01-16 02:22:02,359 log Not Found: /index/test_403
WARNING 2025-01-16 02:22:02,359 basehttp "GET /index/test_403 HTTP/1.1" 404 7175
WARNING 2025-01-16 02:22:24,666 log Not Found: /test_403
WARNING 2025-01-16 02:22:24,667 basehttp "GET /test_403 HTTP/1.1" 404 2929
WARNING 2025-01-16 02:22:50,001 log Not Found: /test_403
WARNING 2025-01-16 02:22:50,002 basehttp "GET /test_403 HTTP/1.1" 404 3081
WARNING 2025-01-16 02:23:05,865 log Not Found: /index/403
WARNING 2025-01-16 02:23:05,866 basehttp "GET /index/403 HTTP/1.1" 404 7307
WARNING 2025-01-16 02:23:18,400 log Not Found: /index/403
WARNING 2025-01-16 02:23:18,401 basehttp "GET /index/403 HTTP/1.1" 404 7307
WARNING 2025-01-16 02:23:23,849 log Not Found: /index/test_403
WARNING 2025-01-16 02:23:23,850 basehttp "GET /index/test_403 HTTP/1.1" 404 7327
WARNING 2025-01-16 02:23:37,669 log Not Found: /index/test_403
WARNING 2025-01-16 02:23:37,670 basehttp "GET /index/test_403 HTTP/1.1" 404 7175
WARNING 2025-01-16 02:23:38,376 log Not Found: /index/test_403
WARNING 2025-01-16 02:23:38,376 basehttp "GET /index/test_403 HTTP/1.1" 404 7175
WARNING 2025-01-16 02:25:05,979 log Not Found: /index/test_403
WARNING 2025-01-16 02:25:05,980 basehttp "GET /index/test_403 HTTP/1.1" 404 7175
ERROR 2025-01-16 02:25:29,096 log Internal Server Error: /index/test_403/
Traceback (most recent call last):
  File "C:\Users\Mihnea\AppData\Local\Programs\Python\Python312\Lib\site-packages\django\core\handlers\exception.py", line 55, in inner
    response = get_response(request)
               ^^^^^^^^^^^^^^^^^^^^^
  File "C:\Users\Mihnea\AppData\Local\Programs\Python\Python312\Lib\site-packages\django\core\handlers\base.py", line 197, in _get_response
    response = wrapped_callback(request, *callback_args, **callback_kwargs)
               ^^^^^^^^^^^^^^^^^^^^^^^^^^^^^^^^^^^^^^^^^^^^^^^^^^^^^^^^^^^^
TypeError: custom_403_view() missing 1 required positional argument: 'exception'
ERROR 2025-01-16 02:25:29,097 basehttp "GET /index/test_403/ HTTP/1.1" 500 65677
WARNING 2025-01-16 02:26:38,420 log Forbidden (Permission denied): /index/test_403/
Traceback (most recent call last):
  File "C:\Users\Mihnea\AppData\Local\Programs\Python\Python312\Lib\site-packages\django\core\handlers\exception.py", line 55, in inner
    response = get_response(request)
               ^^^^^^^^^^^^^^^^^^^^^
  File "C:\Users\Mihnea\AppData\Local\Programs\Python\Python312\Lib\site-packages\django\core\handlers\base.py", line 197, in _get_response
    response = wrapped_callback(request, *callback_args, **callback_kwargs)
               ^^^^^^^^^^^^^^^^^^^^^^^^^^^^^^^^^^^^^^^^^^^^^^^^^^^^^^^^^^^^
  File "C:\Users\Mihnea\Documents\Unibuc-FMI\2024-2025\Semestrul_1\Django\proiect\app_0\views.py", line 267, in test_403
    raise PermissionDenied("You do not have permission to access this resource.")
django.core.exceptions.PermissionDenied: You do not have permission to access this resource.
WARNING 2025-01-16 02:26:38,422 basehttp "GET /index/test_403/ HTTP/1.1" 403 135
ERROR 2025-01-16 02:27:06,166 log Internal Server Error: /index/test_403/
Traceback (most recent call last):
  File "C:\Users\Mihnea\AppData\Local\Programs\Python\Python312\Lib\site-packages\django\core\handlers\exception.py", line 55, in inner
    response = get_response(request)
               ^^^^^^^^^^^^^^^^^^^^^
  File "C:\Users\Mihnea\AppData\Local\Programs\Python\Python312\Lib\site-packages\django\core\handlers\base.py", line 197, in _get_response
    response = wrapped_callback(request, *callback_args, **callback_kwargs)
               ^^^^^^^^^^^^^^^^^^^^^^^^^^^^^^^^^^^^^^^^^^^^^^^^^^^^^^^^^^^^
TypeError: custom_403_view() missing 1 required positional argument: 'exception'
ERROR 2025-01-16 02:27:06,167 basehttp "GET /index/test_403/ HTTP/1.1" 500 65677
ERROR 2025-01-16 02:27:50,405 log Internal Server Error: /index/test_403/
Traceback (most recent call last):
  File "C:\Users\Mihnea\AppData\Local\Programs\Python\Python312\Lib\site-packages\django\core\handlers\exception.py", line 55, in inner
    response = get_response(request)
               ^^^^^^^^^^^^^^^^^^^^^
  File "C:\Users\Mihnea\AppData\Local\Programs\Python\Python312\Lib\site-packages\django\core\handlers\base.py", line 197, in _get_response
    response = wrapped_callback(request, *callback_args, **callback_kwargs)
               ^^^^^^^^^^^^^^^^^^^^^^^^^^^^^^^^^^^^^^^^^^^^^^^^^^^^^^^^^^^^
TypeError: custom_403_view() missing 1 required positional argument: 'exception'
ERROR 2025-01-16 02:27:50,407 basehttp "GET /index/test_403/ HTTP/1.1" 500 65677
ERROR 2025-01-16 02:27:51,450 log Internal Server Error: /index/test_403/
Traceback (most recent call last):
  File "C:\Users\Mihnea\AppData\Local\Programs\Python\Python312\Lib\site-packages\django\core\handlers\exception.py", line 55, in inner
    response = get_response(request)
               ^^^^^^^^^^^^^^^^^^^^^
  File "C:\Users\Mihnea\AppData\Local\Programs\Python\Python312\Lib\site-packages\django\core\handlers\base.py", line 197, in _get_response
    response = wrapped_callback(request, *callback_args, **callback_kwargs)
               ^^^^^^^^^^^^^^^^^^^^^^^^^^^^^^^^^^^^^^^^^^^^^^^^^^^^^^^^^^^^
TypeError: custom_403_view() missing 1 required positional argument: 'exception'
ERROR 2025-01-16 02:27:51,451 basehttp "GET /index/test_403/ HTTP/1.1" 500 65677
ERROR 2025-01-16 02:29:09,101 log Internal Server Error: /index/test_403/
Traceback (most recent call last):
  File "C:\Users\Mihnea\AppData\Local\Programs\Python\Python312\Lib\site-packages\django\core\handlers\exception.py", line 55, in inner
    response = get_response(request)
               ^^^^^^^^^^^^^^^^^^^^^
  File "C:\Users\Mihnea\AppData\Local\Programs\Python\Python312\Lib\site-packages\django\core\handlers\base.py", line 197, in _get_response
    response = wrapped_callback(request, *callback_args, **callback_kwargs)
               ^^^^^^^^^^^^^^^^^^^^^^^^^^^^^^^^^^^^^^^^^^^^^^^^^^^^^^^^^^^^
TypeError: custom_403_view() missing 1 required positional argument: 'exception'
ERROR 2025-01-16 02:29:09,102 basehttp "GET /index/test_403/ HTTP/1.1" 500 65677
ERROR 2025-01-16 02:29:11,100 log Internal Server Error: /index/test_403/
Traceback (most recent call last):
  File "C:\Users\Mihnea\AppData\Local\Programs\Python\Python312\Lib\site-packages\django\core\handlers\exception.py", line 55, in inner
    response = get_response(request)
               ^^^^^^^^^^^^^^^^^^^^^
  File "C:\Users\Mihnea\AppData\Local\Programs\Python\Python312\Lib\site-packages\django\core\handlers\base.py", line 197, in _get_response
    response = wrapped_callback(request, *callback_args, **callback_kwargs)
               ^^^^^^^^^^^^^^^^^^^^^^^^^^^^^^^^^^^^^^^^^^^^^^^^^^^^^^^^^^^^
TypeError: custom_403_view() missing 1 required positional argument: 'exception'
ERROR 2025-01-16 02:29:11,101 basehttp "GET /index/test_403/ HTTP/1.1" 500 65677
WARNING 2025-01-16 02:29:32,280 log Not Found: /aplicatieProj/confirmare_email/2b62740a-58b2-4a2c-adca-a3157fa76739/
WARNING 2025-01-16 02:29:32,281 basehttp "GET /aplicatieProj/confirmare_email/2b62740a-58b2-4a2c-adca-a3157fa76739/ HTTP/1.1" 404 2702
ERROR 2025-01-16 02:29:48,975 log Forbidden (Permission denied): /index/test_403/
Traceback (most recent call last):
  File "C:\Users\Mihnea\AppData\Local\Programs\Python\Python312\Lib\site-packages\django\core\handlers\exception.py", line 55, in inner
    response = get_response(request)
               ^^^^^^^^^^^^^^^^^^^^^
  File "C:\Users\Mihnea\AppData\Local\Programs\Python\Python312\Lib\site-packages\django\core\handlers\base.py", line 197, in _get_response
    response = wrapped_callback(request, *callback_args, **callback_kwargs)
               ^^^^^^^^^^^^^^^^^^^^^^^^^^^^^^^^^^^^^^^^^^^^^^^^^^^^^^^^^^^^
  File "C:\Users\Mihnea\Documents\Unibuc-FMI\2024-2025\Semestrul_1\Django\proiect\app_0\views.py", line 267, in test_403
    raise PermissionDenied("You do not have permission to access this resource.")
django.core.exceptions.PermissionDenied: You do not have permission to access this resource.
ERROR 2025-01-16 02:29:48,976 basehttp "GET /index/test_403/ HTTP/1.1" 500 92508
ERROR 2025-01-16 02:30:18,763 log Forbidden (Permission denied): /index/test_403/
Traceback (most recent call last):
  File "C:\Users\Mihnea\AppData\Local\Programs\Python\Python312\Lib\site-packages\django\core\handlers\exception.py", line 55, in inner
    response = get_response(request)
               ^^^^^^^^^^^^^^^^^^^^^
  File "C:\Users\Mihnea\AppData\Local\Programs\Python\Python312\Lib\site-packages\django\core\handlers\base.py", line 197, in _get_response
    response = wrapped_callback(request, *callback_args, **callback_kwargs)
               ^^^^^^^^^^^^^^^^^^^^^^^^^^^^^^^^^^^^^^^^^^^^^^^^^^^^^^^^^^^^
  File "C:\Users\Mihnea\Documents\Unibuc-FMI\2024-2025\Semestrul_1\Django\proiect\app_0\views.py", line 267, in test_403
    raise PermissionDenied("You do not have permission to access this resource.")
django.core.exceptions.PermissionDenied: You do not have permission to access this resource.
ERROR 2025-01-16 02:30:18,764 basehttp "GET /index/test_403/ HTTP/1.1" 500 92508
ERROR 2025-01-16 02:30:31,150 log Forbidden (Permission denied): /index/test_403/
Traceback (most recent call last):
  File "C:\Users\Mihnea\AppData\Local\Programs\Python\Python312\Lib\site-packages\django\core\handlers\exception.py", line 55, in inner
    response = get_response(request)
               ^^^^^^^^^^^^^^^^^^^^^
  File "C:\Users\Mihnea\AppData\Local\Programs\Python\Python312\Lib\site-packages\django\core\handlers\base.py", line 197, in _get_response
    response = wrapped_callback(request, *callback_args, **callback_kwargs)
               ^^^^^^^^^^^^^^^^^^^^^^^^^^^^^^^^^^^^^^^^^^^^^^^^^^^^^^^^^^^^
  File "C:\Users\Mihnea\Documents\Unibuc-FMI\2024-2025\Semestrul_1\Django\proiect\app_0\views.py", line 267, in test_403
    raise PermissionDenied("You do not have permission to access this resource.")
django.core.exceptions.PermissionDenied: You do not have permission to access this resource.
ERROR 2025-01-16 02:30:31,151 basehttp "GET /index/test_403/ HTTP/1.1" 500 92508
ERROR 2025-01-16 02:30:32,500 log Forbidden (Permission denied): /index/test_403/
Traceback (most recent call last):
  File "C:\Users\Mihnea\AppData\Local\Programs\Python\Python312\Lib\site-packages\django\core\handlers\exception.py", line 55, in inner
    response = get_response(request)
               ^^^^^^^^^^^^^^^^^^^^^
  File "C:\Users\Mihnea\AppData\Local\Programs\Python\Python312\Lib\site-packages\django\core\handlers\base.py", line 197, in _get_response
    response = wrapped_callback(request, *callback_args, **callback_kwargs)
               ^^^^^^^^^^^^^^^^^^^^^^^^^^^^^^^^^^^^^^^^^^^^^^^^^^^^^^^^^^^^
  File "C:\Users\Mihnea\Documents\Unibuc-FMI\2024-2025\Semestrul_1\Django\proiect\app_0\views.py", line 267, in test_403
    raise PermissionDenied("You do not have permission to access this resource.")
django.core.exceptions.PermissionDenied: You do not have permission to access this resource.
ERROR 2025-01-16 02:30:32,502 basehttp "GET /index/test_403/ HTTP/1.1" 500 92508
ERROR 2025-01-16 02:30:33,417 log Forbidden (Permission denied): /index/test_403/
Traceback (most recent call last):
  File "C:\Users\Mihnea\AppData\Local\Programs\Python\Python312\Lib\site-packages\django\core\handlers\exception.py", line 55, in inner
    response = get_response(request)
               ^^^^^^^^^^^^^^^^^^^^^
  File "C:\Users\Mihnea\AppData\Local\Programs\Python\Python312\Lib\site-packages\django\core\handlers\base.py", line 197, in _get_response
    response = wrapped_callback(request, *callback_args, **callback_kwargs)
               ^^^^^^^^^^^^^^^^^^^^^^^^^^^^^^^^^^^^^^^^^^^^^^^^^^^^^^^^^^^^
  File "C:\Users\Mihnea\Documents\Unibuc-FMI\2024-2025\Semestrul_1\Django\proiect\app_0\views.py", line 267, in test_403
    raise PermissionDenied("You do not have permission to access this resource.")
django.core.exceptions.PermissionDenied: You do not have permission to access this resource.
ERROR 2025-01-16 02:30:33,418 basehttp "GET /index/test_403/ HTTP/1.1" 500 92508
ERROR 2025-01-16 02:30:46,842 log Forbidden (Permission denied): /index/test_403/
Traceback (most recent call last):
  File "C:\Users\Mihnea\AppData\Local\Programs\Python\Python312\Lib\site-packages\django\core\handlers\exception.py", line 55, in inner
    response = get_response(request)
               ^^^^^^^^^^^^^^^^^^^^^
  File "C:\Users\Mihnea\AppData\Local\Programs\Python\Python312\Lib\site-packages\django\core\handlers\base.py", line 197, in _get_response
    response = wrapped_callback(request, *callback_args, **callback_kwargs)
               ^^^^^^^^^^^^^^^^^^^^^^^^^^^^^^^^^^^^^^^^^^^^^^^^^^^^^^^^^^^^
  File "C:\Users\Mihnea\Documents\Unibuc-FMI\2024-2025\Semestrul_1\Django\proiect\app_0\views.py", line 267, in test_403
    raise PermissionDenied("You do not have permission to access this resource.")
django.core.exceptions.PermissionDenied: You do not have permission to access this resource.
ERROR 2025-01-16 02:30:46,843 basehttp "GET /index/test_403/ HTTP/1.1" 500 92508
ERROR 2025-01-16 02:30:47,626 log Forbidden (Permission denied): /index/test_403/
Traceback (most recent call last):
  File "C:\Users\Mihnea\AppData\Local\Programs\Python\Python312\Lib\site-packages\django\core\handlers\exception.py", line 55, in inner
    response = get_response(request)
               ^^^^^^^^^^^^^^^^^^^^^
  File "C:\Users\Mihnea\AppData\Local\Programs\Python\Python312\Lib\site-packages\django\core\handlers\base.py", line 197, in _get_response
    response = wrapped_callback(request, *callback_args, **callback_kwargs)
               ^^^^^^^^^^^^^^^^^^^^^^^^^^^^^^^^^^^^^^^^^^^^^^^^^^^^^^^^^^^^
  File "C:\Users\Mihnea\Documents\Unibuc-FMI\2024-2025\Semestrul_1\Django\proiect\app_0\views.py", line 267, in test_403
    raise PermissionDenied("You do not have permission to access this resource.")
django.core.exceptions.PermissionDenied: You do not have permission to access this resource.
ERROR 2025-01-16 02:30:47,628 basehttp "GET /index/test_403/ HTTP/1.1" 500 92508
ERROR 2025-01-16 02:30:48,119 log Forbidden (Permission denied): /index/test_403/
Traceback (most recent call last):
  File "C:\Users\Mihnea\AppData\Local\Programs\Python\Python312\Lib\site-packages\django\core\handlers\exception.py", line 55, in inner
    response = get_response(request)
               ^^^^^^^^^^^^^^^^^^^^^
  File "C:\Users\Mihnea\AppData\Local\Programs\Python\Python312\Lib\site-packages\django\core\handlers\base.py", line 197, in _get_response
    response = wrapped_callback(request, *callback_args, **callback_kwargs)
               ^^^^^^^^^^^^^^^^^^^^^^^^^^^^^^^^^^^^^^^^^^^^^^^^^^^^^^^^^^^^
  File "C:\Users\Mihnea\Documents\Unibuc-FMI\2024-2025\Semestrul_1\Django\proiect\app_0\views.py", line 267, in test_403
    raise PermissionDenied("You do not have permission to access this resource.")
django.core.exceptions.PermissionDenied: You do not have permission to access this resource.
ERROR 2025-01-16 02:30:48,120 basehttp "GET /index/test_403/ HTTP/1.1" 500 92508
ERROR 2025-01-16 02:30:48,416 log Forbidden (Permission denied): /index/test_403/
Traceback (most recent call last):
  File "C:\Users\Mihnea\AppData\Local\Programs\Python\Python312\Lib\site-packages\django\core\handlers\exception.py", line 55, in inner
    response = get_response(request)
               ^^^^^^^^^^^^^^^^^^^^^
  File "C:\Users\Mihnea\AppData\Local\Programs\Python\Python312\Lib\site-packages\django\core\handlers\base.py", line 197, in _get_response
    response = wrapped_callback(request, *callback_args, **callback_kwargs)
               ^^^^^^^^^^^^^^^^^^^^^^^^^^^^^^^^^^^^^^^^^^^^^^^^^^^^^^^^^^^^
  File "C:\Users\Mihnea\Documents\Unibuc-FMI\2024-2025\Semestrul_1\Django\proiect\app_0\views.py", line 267, in test_403
    raise PermissionDenied("You do not have permission to access this resource.")
django.core.exceptions.PermissionDenied: You do not have permission to access this resource.
ERROR 2025-01-16 02:30:48,417 basehttp "GET /index/test_403/ HTTP/1.1" 500 92508
ERROR 2025-01-16 02:32:04,073 log Forbidden (Permission denied): /index/test_403/
Traceback (most recent call last):
  File "C:\Users\Mihnea\AppData\Local\Programs\Python\Python312\Lib\site-packages\django\core\handlers\exception.py", line 55, in inner
    response = get_response(request)
               ^^^^^^^^^^^^^^^^^^^^^
  File "C:\Users\Mihnea\AppData\Local\Programs\Python\Python312\Lib\site-packages\django\core\handlers\base.py", line 197, in _get_response
    response = wrapped_callback(request, *callback_args, **callback_kwargs)
               ^^^^^^^^^^^^^^^^^^^^^^^^^^^^^^^^^^^^^^^^^^^^^^^^^^^^^^^^^^^^
  File "C:\Users\Mihnea\Documents\Unibuc-FMI\2024-2025\Semestrul_1\Django\proiect\app_0\views.py", line 267, in test_403
    raise PermissionDenied("You do not have permission to access this resource.")
django.core.exceptions.PermissionDenied: You do not have permission to access this resource.
ERROR 2025-01-16 02:32:04,075 basehttp "GET /index/test_403/ HTTP/1.1" 500 92508
ERROR 2025-01-16 03:52:51,736 log Forbidden (Permission denied): /index/test_403/
Traceback (most recent call last):
  File "C:\Users\Mihnea\AppData\Local\Programs\Python\Python312\Lib\site-packages\django\core\handlers\exception.py", line 55, in inner
    response = get_response(request)
               ^^^^^^^^^^^^^^^^^^^^^
  File "C:\Users\Mihnea\AppData\Local\Programs\Python\Python312\Lib\site-packages\django\core\handlers\base.py", line 197, in _get_response
    response = wrapped_callback(request, *callback_args, **callback_kwargs)
               ^^^^^^^^^^^^^^^^^^^^^^^^^^^^^^^^^^^^^^^^^^^^^^^^^^^^^^^^^^^^
  File "C:\Users\Mihnea\Documents\Unibuc-FMI\2024-2025\Semestrul_1\Django\proiect\app_0\views.py", line 267, in test_403
    raise PermissionDenied("You do not have permission to access this resource.")
django.core.exceptions.PermissionDenied: You do not have permission to access this resource.
ERROR 2025-01-16 03:52:51,737 basehttp "GET /index/test_403/ HTTP/1.1" 500 92508
ERROR 2025-01-16 03:55:06,315 log Forbidden (Permission denied): /index/test_403/
Traceback (most recent call last):
  File "C:\Users\Mihnea\AppData\Local\Programs\Python\Python312\Lib\site-packages\django\core\handlers\exception.py", line 55, in inner
    response = get_response(request)
               ^^^^^^^^^^^^^^^^^^^^^
  File "C:\Users\Mihnea\AppData\Local\Programs\Python\Python312\Lib\site-packages\django\core\handlers\base.py", line 197, in _get_response
    response = wrapped_callback(request, *callback_args, **callback_kwargs)
               ^^^^^^^^^^^^^^^^^^^^^^^^^^^^^^^^^^^^^^^^^^^^^^^^^^^^^^^^^^^^
  File "C:\Users\Mihnea\Documents\Unibuc-FMI\2024-2025\Semestrul_1\Django\proiect\app_0\views.py", line 267, in test_403
    raise PermissionDenied("You do not have permission to access this resource.")
django.core.exceptions.PermissionDenied: You do not have permission to access this resource.
ERROR 2025-01-16 03:55:06,317 basehttp "GET /index/test_403/ HTTP/1.1" 500 92508
WARNING 2025-01-16 03:56:07,872 log Not Found: /index/profil
WARNING 2025-01-16 03:56:07,873 basehttp "GET /index/profil HTTP/1.1" 404 6756
WARNING 2025-01-16 04:53:37,052 log Not Found: /app_0
WARNING 2025-01-16 04:53:37,053 basehttp "GET /app_0 HTTP/1.1" 404 2513
WARNING 2025-01-16 04:53:49,426 log Not Found: /index/ceva
WARNING 2025-01-16 04:53:49,427 basehttp "GET /index/ceva HTTP/1.1" 404 6750
ERROR 2025-01-16 05:05:13,789 log Internal Server Error: /index/assign_offer_permission/
Traceback (most recent call last):
  File "C:\Users\Mihnea\AppData\Local\Programs\Python\Python312\Lib\site-packages\django\core\handlers\exception.py", line 55, in inner
    response = get_response(request)
               ^^^^^^^^^^^^^^^^^^^^^
  File "C:\Users\Mihnea\AppData\Local\Programs\Python\Python312\Lib\site-packages\django\core\handlers\base.py", line 197, in _get_response
    response = wrapped_callback(request, *callback_args, **callback_kwargs)
               ^^^^^^^^^^^^^^^^^^^^^^^^^^^^^^^^^^^^^^^^^^^^^^^^^^^^^^^^^^^^
  File "C:\Users\Mihnea\AppData\Local\Programs\Python\Python312\Lib\site-packages\django\contrib\auth\decorators.py", line 60, in _view_wrapper
    return view_func(request, *args, **kwargs)
           ^^^^^^^^^^^^^^^^^^^^^^^^^^^^^^^^^^^
  File "C:\Users\Mihnea\Documents\Unibuc-FMI\2024-2025\Semestrul_1\Django\proiect\app_0\views.py", line 282, in assign_offer_permission
    permission = Permission.objects.get(codename='vizualizeaza_oferta')
                 ^^^^^^^^^^^^^^^^^^^^^^^^^^^^^^^^^^^^^^^^^^^^^^^^^^^^^^
  File "C:\Users\Mihnea\AppData\Local\Programs\Python\Python312\Lib\site-packages\django\db\models\manager.py", line 87, in manager_method
    return getattr(self.get_queryset(), name)(*args, **kwargs)
           ^^^^^^^^^^^^^^^^^^^^^^^^^^^^^^^^^^^^^^^^^^^^^^^^^^^
  File "C:\Users\Mihnea\AppData\Local\Programs\Python\Python312\Lib\site-packages\django\db\models\query.py", line 649, in get
    raise self.model.DoesNotExist(
django.contrib.auth.models.Permission.DoesNotExist: Permission matching query does not exist.
ERROR 2025-01-16 05:05:13,791 basehttp "POST /index/assign_offer_permission/ HTTP/1.1" 500 84370
ERROR 2025-01-16 05:05:15,390 log Internal Server Error: /index/assign_offer_permission/
Traceback (most recent call last):
  File "C:\Users\Mihnea\AppData\Local\Programs\Python\Python312\Lib\site-packages\django\core\handlers\exception.py", line 55, in inner
    response = get_response(request)
               ^^^^^^^^^^^^^^^^^^^^^
  File "C:\Users\Mihnea\AppData\Local\Programs\Python\Python312\Lib\site-packages\django\core\handlers\base.py", line 197, in _get_response
    response = wrapped_callback(request, *callback_args, **callback_kwargs)
               ^^^^^^^^^^^^^^^^^^^^^^^^^^^^^^^^^^^^^^^^^^^^^^^^^^^^^^^^^^^^
  File "C:\Users\Mihnea\AppData\Local\Programs\Python\Python312\Lib\site-packages\django\contrib\auth\decorators.py", line 60, in _view_wrapper
    return view_func(request, *args, **kwargs)
           ^^^^^^^^^^^^^^^^^^^^^^^^^^^^^^^^^^^
  File "C:\Users\Mihnea\Documents\Unibuc-FMI\2024-2025\Semestrul_1\Django\proiect\app_0\views.py", line 282, in assign_offer_permission
    permission = Permission.objects.get(codename='vizualizeaza_oferta')
                 ^^^^^^^^^^^^^^^^^^^^^^^^^^^^^^^^^^^^^^^^^^^^^^^^^^^^^^
  File "C:\Users\Mihnea\AppData\Local\Programs\Python\Python312\Lib\site-packages\django\db\models\manager.py", line 87, in manager_method
    return getattr(self.get_queryset(), name)(*args, **kwargs)
           ^^^^^^^^^^^^^^^^^^^^^^^^^^^^^^^^^^^^^^^^^^^^^^^^^^^
  File "C:\Users\Mihnea\AppData\Local\Programs\Python\Python312\Lib\site-packages\django\db\models\query.py", line 649, in get
    raise self.model.DoesNotExist(
django.contrib.auth.models.Permission.DoesNotExist: Permission matching query does not exist.
ERROR 2025-01-16 05:05:15,392 basehttp "POST /index/assign_offer_permission/ HTTP/1.1" 500 84370
ERROR 2025-01-16 05:05:16,426 log Internal Server Error: /index/assign_offer_permission/
Traceback (most recent call last):
  File "C:\Users\Mihnea\AppData\Local\Programs\Python\Python312\Lib\site-packages\django\core\handlers\exception.py", line 55, in inner
    response = get_response(request)
               ^^^^^^^^^^^^^^^^^^^^^
  File "C:\Users\Mihnea\AppData\Local\Programs\Python\Python312\Lib\site-packages\django\core\handlers\base.py", line 197, in _get_response
    response = wrapped_callback(request, *callback_args, **callback_kwargs)
               ^^^^^^^^^^^^^^^^^^^^^^^^^^^^^^^^^^^^^^^^^^^^^^^^^^^^^^^^^^^^
  File "C:\Users\Mihnea\AppData\Local\Programs\Python\Python312\Lib\site-packages\django\contrib\auth\decorators.py", line 60, in _view_wrapper
    return view_func(request, *args, **kwargs)
           ^^^^^^^^^^^^^^^^^^^^^^^^^^^^^^^^^^^
  File "C:\Users\Mihnea\Documents\Unibuc-FMI\2024-2025\Semestrul_1\Django\proiect\app_0\views.py", line 282, in assign_offer_permission
    permission = Permission.objects.get(codename='vizualizeaza_oferta')
                 ^^^^^^^^^^^^^^^^^^^^^^^^^^^^^^^^^^^^^^^^^^^^^^^^^^^^^^
  File "C:\Users\Mihnea\AppData\Local\Programs\Python\Python312\Lib\site-packages\django\db\models\manager.py", line 87, in manager_method
    return getattr(self.get_queryset(), name)(*args, **kwargs)
           ^^^^^^^^^^^^^^^^^^^^^^^^^^^^^^^^^^^^^^^^^^^^^^^^^^^
  File "C:\Users\Mihnea\AppData\Local\Programs\Python\Python312\Lib\site-packages\django\db\models\query.py", line 649, in get
    raise self.model.DoesNotExist(
django.contrib.auth.models.Permission.DoesNotExist: Permission matching query does not exist.
ERROR 2025-01-16 05:05:16,428 basehttp "POST /index/assign_offer_permission/ HTTP/1.1" 500 84370
ERROR 2025-01-16 05:05:16,608 log Internal Server Error: /index/assign_offer_permission/
Traceback (most recent call last):
  File "C:\Users\Mihnea\AppData\Local\Programs\Python\Python312\Lib\site-packages\django\core\handlers\exception.py", line 55, in inner
    response = get_response(request)
               ^^^^^^^^^^^^^^^^^^^^^
  File "C:\Users\Mihnea\AppData\Local\Programs\Python\Python312\Lib\site-packages\django\core\handlers\base.py", line 197, in _get_response
    response = wrapped_callback(request, *callback_args, **callback_kwargs)
               ^^^^^^^^^^^^^^^^^^^^^^^^^^^^^^^^^^^^^^^^^^^^^^^^^^^^^^^^^^^^
  File "C:\Users\Mihnea\AppData\Local\Programs\Python\Python312\Lib\site-packages\django\contrib\auth\decorators.py", line 60, in _view_wrapper
    return view_func(request, *args, **kwargs)
           ^^^^^^^^^^^^^^^^^^^^^^^^^^^^^^^^^^^
  File "C:\Users\Mihnea\Documents\Unibuc-FMI\2024-2025\Semestrul_1\Django\proiect\app_0\views.py", line 282, in assign_offer_permission
    permission = Permission.objects.get(codename='vizualizeaza_oferta')
                 ^^^^^^^^^^^^^^^^^^^^^^^^^^^^^^^^^^^^^^^^^^^^^^^^^^^^^^
  File "C:\Users\Mihnea\AppData\Local\Programs\Python\Python312\Lib\site-packages\django\db\models\manager.py", line 87, in manager_method
    return getattr(self.get_queryset(), name)(*args, **kwargs)
           ^^^^^^^^^^^^^^^^^^^^^^^^^^^^^^^^^^^^^^^^^^^^^^^^^^^
  File "C:\Users\Mihnea\AppData\Local\Programs\Python\Python312\Lib\site-packages\django\db\models\query.py", line 649, in get
    raise self.model.DoesNotExist(
django.contrib.auth.models.Permission.DoesNotExist: Permission matching query does not exist.
ERROR 2025-01-16 05:05:16,610 basehttp "POST /index/assign_offer_permission/ HTTP/1.1" 500 84370
ERROR 2025-01-16 05:05:17,115 log Internal Server Error: /index/assign_offer_permission/
Traceback (most recent call last):
  File "C:\Users\Mihnea\AppData\Local\Programs\Python\Python312\Lib\site-packages\django\core\handlers\exception.py", line 55, in inner
    response = get_response(request)
               ^^^^^^^^^^^^^^^^^^^^^
  File "C:\Users\Mihnea\AppData\Local\Programs\Python\Python312\Lib\site-packages\django\core\handlers\base.py", line 197, in _get_response
    response = wrapped_callback(request, *callback_args, **callback_kwargs)
               ^^^^^^^^^^^^^^^^^^^^^^^^^^^^^^^^^^^^^^^^^^^^^^^^^^^^^^^^^^^^
  File "C:\Users\Mihnea\AppData\Local\Programs\Python\Python312\Lib\site-packages\django\contrib\auth\decorators.py", line 60, in _view_wrapper
    return view_func(request, *args, **kwargs)
           ^^^^^^^^^^^^^^^^^^^^^^^^^^^^^^^^^^^
  File "C:\Users\Mihnea\Documents\Unibuc-FMI\2024-2025\Semestrul_1\Django\proiect\app_0\views.py", line 282, in assign_offer_permission
    permission = Permission.objects.get(codename='vizualizeaza_oferta')
                 ^^^^^^^^^^^^^^^^^^^^^^^^^^^^^^^^^^^^^^^^^^^^^^^^^^^^^^
  File "C:\Users\Mihnea\AppData\Local\Programs\Python\Python312\Lib\site-packages\django\db\models\manager.py", line 87, in manager_method
    return getattr(self.get_queryset(), name)(*args, **kwargs)
           ^^^^^^^^^^^^^^^^^^^^^^^^^^^^^^^^^^^^^^^^^^^^^^^^^^^
  File "C:\Users\Mihnea\AppData\Local\Programs\Python\Python312\Lib\site-packages\django\db\models\query.py", line 649, in get
    raise self.model.DoesNotExist(
django.contrib.auth.models.Permission.DoesNotExist: Permission matching query does not exist.
ERROR 2025-01-16 05:05:17,117 basehttp "POST /index/assign_offer_permission/ HTTP/1.1" 500 84370
ERROR 2025-01-16 05:05:17,463 log Internal Server Error: /index/assign_offer_permission/
Traceback (most recent call last):
  File "C:\Users\Mihnea\AppData\Local\Programs\Python\Python312\Lib\site-packages\django\core\handlers\exception.py", line 55, in inner
    response = get_response(request)
               ^^^^^^^^^^^^^^^^^^^^^
  File "C:\Users\Mihnea\AppData\Local\Programs\Python\Python312\Lib\site-packages\django\core\handlers\base.py", line 197, in _get_response
    response = wrapped_callback(request, *callback_args, **callback_kwargs)
               ^^^^^^^^^^^^^^^^^^^^^^^^^^^^^^^^^^^^^^^^^^^^^^^^^^^^^^^^^^^^
  File "C:\Users\Mihnea\AppData\Local\Programs\Python\Python312\Lib\site-packages\django\contrib\auth\decorators.py", line 60, in _view_wrapper
    return view_func(request, *args, **kwargs)
           ^^^^^^^^^^^^^^^^^^^^^^^^^^^^^^^^^^^
  File "C:\Users\Mihnea\Documents\Unibuc-FMI\2024-2025\Semestrul_1\Django\proiect\app_0\views.py", line 282, in assign_offer_permission
    permission = Permission.objects.get(codename='vizualizeaza_oferta')
                 ^^^^^^^^^^^^^^^^^^^^^^^^^^^^^^^^^^^^^^^^^^^^^^^^^^^^^^
  File "C:\Users\Mihnea\AppData\Local\Programs\Python\Python312\Lib\site-packages\django\db\models\manager.py", line 87, in manager_method
    return getattr(self.get_queryset(), name)(*args, **kwargs)
           ^^^^^^^^^^^^^^^^^^^^^^^^^^^^^^^^^^^^^^^^^^^^^^^^^^^
  File "C:\Users\Mihnea\AppData\Local\Programs\Python\Python312\Lib\site-packages\django\db\models\query.py", line 649, in get
    raise self.model.DoesNotExist(
django.contrib.auth.models.Permission.DoesNotExist: Permission matching query does not exist.
ERROR 2025-01-16 05:05:17,464 basehttp "POST /index/assign_offer_permission/ HTTP/1.1" 500 84370
ERROR 2025-01-16 05:05:17,901 log Internal Server Error: /index/assign_offer_permission/
Traceback (most recent call last):
  File "C:\Users\Mihnea\AppData\Local\Programs\Python\Python312\Lib\site-packages\django\core\handlers\exception.py", line 55, in inner
    response = get_response(request)
               ^^^^^^^^^^^^^^^^^^^^^
  File "C:\Users\Mihnea\AppData\Local\Programs\Python\Python312\Lib\site-packages\django\core\handlers\base.py", line 197, in _get_response
    response = wrapped_callback(request, *callback_args, **callback_kwargs)
               ^^^^^^^^^^^^^^^^^^^^^^^^^^^^^^^^^^^^^^^^^^^^^^^^^^^^^^^^^^^^
  File "C:\Users\Mihnea\AppData\Local\Programs\Python\Python312\Lib\site-packages\django\contrib\auth\decorators.py", line 60, in _view_wrapper
    return view_func(request, *args, **kwargs)
           ^^^^^^^^^^^^^^^^^^^^^^^^^^^^^^^^^^^
  File "C:\Users\Mihnea\Documents\Unibuc-FMI\2024-2025\Semestrul_1\Django\proiect\app_0\views.py", line 282, in assign_offer_permission
    permission = Permission.objects.get(codename='vizualizeaza_oferta')
                 ^^^^^^^^^^^^^^^^^^^^^^^^^^^^^^^^^^^^^^^^^^^^^^^^^^^^^^
  File "C:\Users\Mihnea\AppData\Local\Programs\Python\Python312\Lib\site-packages\django\db\models\manager.py", line 87, in manager_method
    return getattr(self.get_queryset(), name)(*args, **kwargs)
           ^^^^^^^^^^^^^^^^^^^^^^^^^^^^^^^^^^^^^^^^^^^^^^^^^^^
  File "C:\Users\Mihnea\AppData\Local\Programs\Python\Python312\Lib\site-packages\django\db\models\query.py", line 649, in get
    raise self.model.DoesNotExist(
django.contrib.auth.models.Permission.DoesNotExist: Permission matching query does not exist.
ERROR 2025-01-16 05:05:17,903 basehttp "POST /index/assign_offer_permission/ HTTP/1.1" 500 84370
ERROR 2025-01-16 05:05:18,477 log Internal Server Error: /index/assign_offer_permission/
Traceback (most recent call last):
  File "C:\Users\Mihnea\AppData\Local\Programs\Python\Python312\Lib\site-packages\django\core\handlers\exception.py", line 55, in inner
    response = get_response(request)
               ^^^^^^^^^^^^^^^^^^^^^
  File "C:\Users\Mihnea\AppData\Local\Programs\Python\Python312\Lib\site-packages\django\core\handlers\base.py", line 197, in _get_response
    response = wrapped_callback(request, *callback_args, **callback_kwargs)
               ^^^^^^^^^^^^^^^^^^^^^^^^^^^^^^^^^^^^^^^^^^^^^^^^^^^^^^^^^^^^
  File "C:\Users\Mihnea\AppData\Local\Programs\Python\Python312\Lib\site-packages\django\contrib\auth\decorators.py", line 60, in _view_wrapper
    return view_func(request, *args, **kwargs)
           ^^^^^^^^^^^^^^^^^^^^^^^^^^^^^^^^^^^
  File "C:\Users\Mihnea\Documents\Unibuc-FMI\2024-2025\Semestrul_1\Django\proiect\app_0\views.py", line 282, in assign_offer_permission
    permission = Permission.objects.get(codename='vizualizeaza_oferta')
                 ^^^^^^^^^^^^^^^^^^^^^^^^^^^^^^^^^^^^^^^^^^^^^^^^^^^^^^
  File "C:\Users\Mihnea\AppData\Local\Programs\Python\Python312\Lib\site-packages\django\db\models\manager.py", line 87, in manager_method
    return getattr(self.get_queryset(), name)(*args, **kwargs)
           ^^^^^^^^^^^^^^^^^^^^^^^^^^^^^^^^^^^^^^^^^^^^^^^^^^^
  File "C:\Users\Mihnea\AppData\Local\Programs\Python\Python312\Lib\site-packages\django\db\models\query.py", line 649, in get
    raise self.model.DoesNotExist(
django.contrib.auth.models.Permission.DoesNotExist: Permission matching query does not exist.
ERROR 2025-01-16 05:05:18,479 basehttp "POST /index/assign_offer_permission/ HTTP/1.1" 500 84370
ERROR 2025-01-16 05:07:05,110 log Internal Server Error: /index/assign_offer_permission/
Traceback (most recent call last):
  File "C:\Users\Mihnea\AppData\Local\Programs\Python\Python312\Lib\site-packages\django\core\handlers\exception.py", line 55, in inner
    response = get_response(request)
               ^^^^^^^^^^^^^^^^^^^^^
  File "C:\Users\Mihnea\AppData\Local\Programs\Python\Python312\Lib\site-packages\django\core\handlers\base.py", line 197, in _get_response
    response = wrapped_callback(request, *callback_args, **callback_kwargs)
               ^^^^^^^^^^^^^^^^^^^^^^^^^^^^^^^^^^^^^^^^^^^^^^^^^^^^^^^^^^^^
  File "C:\Users\Mihnea\AppData\Local\Programs\Python\Python312\Lib\site-packages\django\contrib\auth\decorators.py", line 60, in _view_wrapper
    return view_func(request, *args, **kwargs)
           ^^^^^^^^^^^^^^^^^^^^^^^^^^^^^^^^^^^
  File "C:\Users\Mihnea\Documents\Unibuc-FMI\2024-2025\Semestrul_1\Django\proiect\app_0\views.py", line 282, in assign_offer_permission
    permission = Permission.objects.get(codename='vizualizeaza_oferta')
                 ^^^^^^^^^^^^^^^^^^^^^^^^^^^^^^^^^^^^^^^^^^^^^^^^^^^^^^
  File "C:\Users\Mihnea\AppData\Local\Programs\Python\Python312\Lib\site-packages\django\db\models\manager.py", line 87, in manager_method
    return getattr(self.get_queryset(), name)(*args, **kwargs)
           ^^^^^^^^^^^^^^^^^^^^^^^^^^^^^^^^^^^^^^^^^^^^^^^^^^^
  File "C:\Users\Mihnea\AppData\Local\Programs\Python\Python312\Lib\site-packages\django\db\models\query.py", line 649, in get
    raise self.model.DoesNotExist(
django.contrib.auth.models.Permission.DoesNotExist: Permission matching query does not exist.
ERROR 2025-01-16 05:07:05,112 basehttp "POST /index/assign_offer_permission/ HTTP/1.1" 500 84370
ERROR 2025-01-16 05:08:29,260 log Internal Server Error: /index/assign_offer_permission/
Traceback (most recent call last):
  File "C:\Users\Mihnea\AppData\Local\Programs\Python\Python312\Lib\site-packages\django\core\handlers\exception.py", line 55, in inner
    response = get_response(request)
               ^^^^^^^^^^^^^^^^^^^^^
  File "C:\Users\Mihnea\AppData\Local\Programs\Python\Python312\Lib\site-packages\django\core\handlers\base.py", line 197, in _get_response
    response = wrapped_callback(request, *callback_args, **callback_kwargs)
               ^^^^^^^^^^^^^^^^^^^^^^^^^^^^^^^^^^^^^^^^^^^^^^^^^^^^^^^^^^^^
  File "C:\Users\Mihnea\AppData\Local\Programs\Python\Python312\Lib\site-packages\django\contrib\auth\decorators.py", line 60, in _view_wrapper
    return view_func(request, *args, **kwargs)
           ^^^^^^^^^^^^^^^^^^^^^^^^^^^^^^^^^^^
  File "C:\Users\Mihnea\Documents\Unibuc-FMI\2024-2025\Semestrul_1\Django\proiect\app_0\views.py", line 283, in assign_offer_permission
    permission = Permission.objects.get(codename='vizualizeaza_oferta')
                 ^^^^^^^^^^^^^^^^^^^^^^^^^^^^^^^^^^^^^^^^^^^^^^^^^^^^^^
  File "C:\Users\Mihnea\AppData\Local\Programs\Python\Python312\Lib\site-packages\django\db\models\manager.py", line 87, in manager_method
    return getattr(self.get_queryset(), name)(*args, **kwargs)
           ^^^^^^^^^^^^^^^^^^^^^^^^^^^^^^^^^^^^^^^^^^^^^^^^^^^
  File "C:\Users\Mihnea\AppData\Local\Programs\Python\Python312\Lib\site-packages\django\db\models\query.py", line 649, in get
    raise self.model.DoesNotExist(
django.contrib.auth.models.Permission.DoesNotExist: Permission matching query does not exist.
ERROR 2025-01-16 05:08:29,262 basehttp "POST /index/assign_offer_permission/ HTTP/1.1" 500 84370
ERROR 2025-01-16 05:08:29,839 log Internal Server Error: /index/assign_offer_permission/
Traceback (most recent call last):
  File "C:\Users\Mihnea\AppData\Local\Programs\Python\Python312\Lib\site-packages\django\core\handlers\exception.py", line 55, in inner
    response = get_response(request)
               ^^^^^^^^^^^^^^^^^^^^^
  File "C:\Users\Mihnea\AppData\Local\Programs\Python\Python312\Lib\site-packages\django\core\handlers\base.py", line 197, in _get_response
    response = wrapped_callback(request, *callback_args, **callback_kwargs)
               ^^^^^^^^^^^^^^^^^^^^^^^^^^^^^^^^^^^^^^^^^^^^^^^^^^^^^^^^^^^^
  File "C:\Users\Mihnea\AppData\Local\Programs\Python\Python312\Lib\site-packages\django\contrib\auth\decorators.py", line 60, in _view_wrapper
    return view_func(request, *args, **kwargs)
           ^^^^^^^^^^^^^^^^^^^^^^^^^^^^^^^^^^^
  File "C:\Users\Mihnea\Documents\Unibuc-FMI\2024-2025\Semestrul_1\Django\proiect\app_0\views.py", line 283, in assign_offer_permission
    permission = Permission.objects.get(codename='vizualizeaza_oferta')
                 ^^^^^^^^^^^^^^^^^^^^^^^^^^^^^^^^^^^^^^^^^^^^^^^^^^^^^^
  File "C:\Users\Mihnea\AppData\Local\Programs\Python\Python312\Lib\site-packages\django\db\models\manager.py", line 87, in manager_method
    return getattr(self.get_queryset(), name)(*args, **kwargs)
           ^^^^^^^^^^^^^^^^^^^^^^^^^^^^^^^^^^^^^^^^^^^^^^^^^^^
  File "C:\Users\Mihnea\AppData\Local\Programs\Python\Python312\Lib\site-packages\django\db\models\query.py", line 649, in get
    raise self.model.DoesNotExist(
django.contrib.auth.models.Permission.DoesNotExist: Permission matching query does not exist.
ERROR 2025-01-16 05:08:29,841 basehttp "POST /index/assign_offer_permission/ HTTP/1.1" 500 84370
ERROR 2025-01-16 05:08:30,312 log Internal Server Error: /index/assign_offer_permission/
Traceback (most recent call last):
  File "C:\Users\Mihnea\AppData\Local\Programs\Python\Python312\Lib\site-packages\django\core\handlers\exception.py", line 55, in inner
    response = get_response(request)
               ^^^^^^^^^^^^^^^^^^^^^
  File "C:\Users\Mihnea\AppData\Local\Programs\Python\Python312\Lib\site-packages\django\core\handlers\base.py", line 197, in _get_response
    response = wrapped_callback(request, *callback_args, **callback_kwargs)
               ^^^^^^^^^^^^^^^^^^^^^^^^^^^^^^^^^^^^^^^^^^^^^^^^^^^^^^^^^^^^
  File "C:\Users\Mihnea\AppData\Local\Programs\Python\Python312\Lib\site-packages\django\contrib\auth\decorators.py", line 60, in _view_wrapper
    return view_func(request, *args, **kwargs)
           ^^^^^^^^^^^^^^^^^^^^^^^^^^^^^^^^^^^
  File "C:\Users\Mihnea\Documents\Unibuc-FMI\2024-2025\Semestrul_1\Django\proiect\app_0\views.py", line 283, in assign_offer_permission
    permission = Permission.objects.get(codename='vizualizeaza_oferta')
                 ^^^^^^^^^^^^^^^^^^^^^^^^^^^^^^^^^^^^^^^^^^^^^^^^^^^^^^
  File "C:\Users\Mihnea\AppData\Local\Programs\Python\Python312\Lib\site-packages\django\db\models\manager.py", line 87, in manager_method
    return getattr(self.get_queryset(), name)(*args, **kwargs)
           ^^^^^^^^^^^^^^^^^^^^^^^^^^^^^^^^^^^^^^^^^^^^^^^^^^^
  File "C:\Users\Mihnea\AppData\Local\Programs\Python\Python312\Lib\site-packages\django\db\models\query.py", line 649, in get
    raise self.model.DoesNotExist(
django.contrib.auth.models.Permission.DoesNotExist: Permission matching query does not exist.
ERROR 2025-01-16 05:08:30,313 basehttp "POST /index/assign_offer_permission/ HTTP/1.1" 500 84370
WARNING 2025-01-16 05:08:35,220 log Forbidden: /index/oferta/
WARNING 2025-01-16 05:08:35,221 basehttp "GET /index/oferta/ HTTP/1.1" 403 218
ERROR 2025-01-16 05:08:46,889 log Internal Server Error: /index/assign_offer_permission/
Traceback (most recent call last):
  File "C:\Users\Mihnea\AppData\Local\Programs\Python\Python312\Lib\site-packages\django\core\handlers\exception.py", line 55, in inner
    response = get_response(request)
               ^^^^^^^^^^^^^^^^^^^^^
  File "C:\Users\Mihnea\AppData\Local\Programs\Python\Python312\Lib\site-packages\django\core\handlers\base.py", line 197, in _get_response
    response = wrapped_callback(request, *callback_args, **callback_kwargs)
               ^^^^^^^^^^^^^^^^^^^^^^^^^^^^^^^^^^^^^^^^^^^^^^^^^^^^^^^^^^^^
  File "C:\Users\Mihnea\AppData\Local\Programs\Python\Python312\Lib\site-packages\django\contrib\auth\decorators.py", line 60, in _view_wrapper
    return view_func(request, *args, **kwargs)
           ^^^^^^^^^^^^^^^^^^^^^^^^^^^^^^^^^^^
  File "C:\Users\Mihnea\Documents\Unibuc-FMI\2024-2025\Semestrul_1\Django\proiect\app_0\views.py", line 283, in assign_offer_permission
    permission = Permission.objects.get(codename='vizualizeaza_oferta')
                 ^^^^^^^^^^^^^^^^^^^^^^^^^^^^^^^^^^^^^^^^^^^^^^^^^^^^^^
  File "C:\Users\Mihnea\AppData\Local\Programs\Python\Python312\Lib\site-packages\django\db\models\manager.py", line 87, in manager_method
    return getattr(self.get_queryset(), name)(*args, **kwargs)
           ^^^^^^^^^^^^^^^^^^^^^^^^^^^^^^^^^^^^^^^^^^^^^^^^^^^
  File "C:\Users\Mihnea\AppData\Local\Programs\Python\Python312\Lib\site-packages\django\db\models\query.py", line 649, in get
    raise self.model.DoesNotExist(
django.contrib.auth.models.Permission.DoesNotExist: Permission matching query does not exist.
ERROR 2025-01-16 05:08:46,891 basehttp "POST /index/assign_offer_permission/ HTTP/1.1" 500 84370
WARNING 2025-01-16 05:09:02,351 log Not Found: /index/adauga-oferta
WARNING 2025-01-16 05:09:02,351 basehttp "GET /index/adauga-oferta HTTP/1.1" 404 7333
WARNING 2025-01-16 05:09:13,018 log Bad Request: /index/assign_offer_permission/
WARNING 2025-01-16 05:09:13,018 basehttp "GET /index/assign_offer_permission/ HTTP/1.1" 400 19
WARNING 2025-01-16 05:11:25,898 log Not Found: /index/adauga-oferta
WARNING 2025-01-16 05:11:25,899 basehttp "GET /index/adauga-oferta HTTP/1.1" 404 7333
ERROR 2025-01-16 05:11:36,298 log Internal Server Error: /index/assign_offer_permission/
Traceback (most recent call last):
  File "C:\Users\Mihnea\AppData\Local\Programs\Python\Python312\Lib\site-packages\django\core\handlers\exception.py", line 55, in inner
    response = get_response(request)
               ^^^^^^^^^^^^^^^^^^^^^
  File "C:\Users\Mihnea\AppData\Local\Programs\Python\Python312\Lib\site-packages\django\core\handlers\base.py", line 197, in _get_response
    response = wrapped_callback(request, *callback_args, **callback_kwargs)
               ^^^^^^^^^^^^^^^^^^^^^^^^^^^^^^^^^^^^^^^^^^^^^^^^^^^^^^^^^^^^
  File "C:\Users\Mihnea\AppData\Local\Programs\Python\Python312\Lib\site-packages\django\contrib\auth\decorators.py", line 60, in _view_wrapper
    return view_func(request, *args, **kwargs)
           ^^^^^^^^^^^^^^^^^^^^^^^^^^^^^^^^^^^
  File "C:\Users\Mihnea\Documents\Unibuc-FMI\2024-2025\Semestrul_1\Django\proiect\app_0\views.py", line 283, in assign_offer_permission
    permission = Permission.objects.get(codename='vizualizeaza_oferta')
                 ^^^^^^^^^^^^^^^^^^^^^^^^^^^^^^^^^^^^^^^^^^^^^^^^^^^^^^
  File "C:\Users\Mihnea\AppData\Local\Programs\Python\Python312\Lib\site-packages\django\db\models\manager.py", line 87, in manager_method
    return getattr(self.get_queryset(), name)(*args, **kwargs)
           ^^^^^^^^^^^^^^^^^^^^^^^^^^^^^^^^^^^^^^^^^^^^^^^^^^^
  File "C:\Users\Mihnea\AppData\Local\Programs\Python\Python312\Lib\site-packages\django\db\models\query.py", line 649, in get
    raise self.model.DoesNotExist(
django.contrib.auth.models.Permission.DoesNotExist: Permission matching query does not exist.
ERROR 2025-01-16 05:11:36,300 basehttp "POST /index/assign_offer_permission/ HTTP/1.1" 500 84370
ERROR 2025-01-16 05:11:36,810 log Internal Server Error: /index/assign_offer_permission/
Traceback (most recent call last):
  File "C:\Users\Mihnea\AppData\Local\Programs\Python\Python312\Lib\site-packages\django\core\handlers\exception.py", line 55, in inner
    response = get_response(request)
               ^^^^^^^^^^^^^^^^^^^^^
  File "C:\Users\Mihnea\AppData\Local\Programs\Python\Python312\Lib\site-packages\django\core\handlers\base.py", line 197, in _get_response
    response = wrapped_callback(request, *callback_args, **callback_kwargs)
               ^^^^^^^^^^^^^^^^^^^^^^^^^^^^^^^^^^^^^^^^^^^^^^^^^^^^^^^^^^^^
  File "C:\Users\Mihnea\AppData\Local\Programs\Python\Python312\Lib\site-packages\django\contrib\auth\decorators.py", line 60, in _view_wrapper
    return view_func(request, *args, **kwargs)
           ^^^^^^^^^^^^^^^^^^^^^^^^^^^^^^^^^^^
  File "C:\Users\Mihnea\Documents\Unibuc-FMI\2024-2025\Semestrul_1\Django\proiect\app_0\views.py", line 283, in assign_offer_permission
    permission = Permission.objects.get(codename='vizualizeaza_oferta')
                 ^^^^^^^^^^^^^^^^^^^^^^^^^^^^^^^^^^^^^^^^^^^^^^^^^^^^^^
  File "C:\Users\Mihnea\AppData\Local\Programs\Python\Python312\Lib\site-packages\django\db\models\manager.py", line 87, in manager_method
    return getattr(self.get_queryset(), name)(*args, **kwargs)
           ^^^^^^^^^^^^^^^^^^^^^^^^^^^^^^^^^^^^^^^^^^^^^^^^^^^
  File "C:\Users\Mihnea\AppData\Local\Programs\Python\Python312\Lib\site-packages\django\db\models\query.py", line 649, in get
    raise self.model.DoesNotExist(
django.contrib.auth.models.Permission.DoesNotExist: Permission matching query does not exist.
ERROR 2025-01-16 05:11:36,811 basehttp "POST /index/assign_offer_permission/ HTTP/1.1" 500 84370
ERROR 2025-01-16 05:11:37,390 log Internal Server Error: /index/assign_offer_permission/
Traceback (most recent call last):
  File "C:\Users\Mihnea\AppData\Local\Programs\Python\Python312\Lib\site-packages\django\core\handlers\exception.py", line 55, in inner
    response = get_response(request)
               ^^^^^^^^^^^^^^^^^^^^^
  File "C:\Users\Mihnea\AppData\Local\Programs\Python\Python312\Lib\site-packages\django\core\handlers\base.py", line 197, in _get_response
    response = wrapped_callback(request, *callback_args, **callback_kwargs)
               ^^^^^^^^^^^^^^^^^^^^^^^^^^^^^^^^^^^^^^^^^^^^^^^^^^^^^^^^^^^^
  File "C:\Users\Mihnea\AppData\Local\Programs\Python\Python312\Lib\site-packages\django\contrib\auth\decorators.py", line 60, in _view_wrapper
    return view_func(request, *args, **kwargs)
           ^^^^^^^^^^^^^^^^^^^^^^^^^^^^^^^^^^^
  File "C:\Users\Mihnea\Documents\Unibuc-FMI\2024-2025\Semestrul_1\Django\proiect\app_0\views.py", line 283, in assign_offer_permission
    permission = Permission.objects.get(codename='vizualizeaza_oferta')
                 ^^^^^^^^^^^^^^^^^^^^^^^^^^^^^^^^^^^^^^^^^^^^^^^^^^^^^^
  File "C:\Users\Mihnea\AppData\Local\Programs\Python\Python312\Lib\site-packages\django\db\models\manager.py", line 87, in manager_method
    return getattr(self.get_queryset(), name)(*args, **kwargs)
           ^^^^^^^^^^^^^^^^^^^^^^^^^^^^^^^^^^^^^^^^^^^^^^^^^^^
  File "C:\Users\Mihnea\AppData\Local\Programs\Python\Python312\Lib\site-packages\django\db\models\query.py", line 649, in get
    raise self.model.DoesNotExist(
django.contrib.auth.models.Permission.DoesNotExist: Permission matching query does not exist.
ERROR 2025-01-16 05:11:37,392 basehttp "POST /index/assign_offer_permission/ HTTP/1.1" 500 84370
ERROR 2025-01-16 05:11:38,056 log Internal Server Error: /index/assign_offer_permission/
Traceback (most recent call last):
  File "C:\Users\Mihnea\AppData\Local\Programs\Python\Python312\Lib\site-packages\django\core\handlers\exception.py", line 55, in inner
    response = get_response(request)
               ^^^^^^^^^^^^^^^^^^^^^
  File "C:\Users\Mihnea\AppData\Local\Programs\Python\Python312\Lib\site-packages\django\core\handlers\base.py", line 197, in _get_response
    response = wrapped_callback(request, *callback_args, **callback_kwargs)
               ^^^^^^^^^^^^^^^^^^^^^^^^^^^^^^^^^^^^^^^^^^^^^^^^^^^^^^^^^^^^
  File "C:\Users\Mihnea\AppData\Local\Programs\Python\Python312\Lib\site-packages\django\contrib\auth\decorators.py", line 60, in _view_wrapper
    return view_func(request, *args, **kwargs)
           ^^^^^^^^^^^^^^^^^^^^^^^^^^^^^^^^^^^
  File "C:\Users\Mihnea\Documents\Unibuc-FMI\2024-2025\Semestrul_1\Django\proiect\app_0\views.py", line 283, in assign_offer_permission
    permission = Permission.objects.get(codename='vizualizeaza_oferta')
                 ^^^^^^^^^^^^^^^^^^^^^^^^^^^^^^^^^^^^^^^^^^^^^^^^^^^^^^
  File "C:\Users\Mihnea\AppData\Local\Programs\Python\Python312\Lib\site-packages\django\db\models\manager.py", line 87, in manager_method
    return getattr(self.get_queryset(), name)(*args, **kwargs)
           ^^^^^^^^^^^^^^^^^^^^^^^^^^^^^^^^^^^^^^^^^^^^^^^^^^^
  File "C:\Users\Mihnea\AppData\Local\Programs\Python\Python312\Lib\site-packages\django\db\models\query.py", line 649, in get
    raise self.model.DoesNotExist(
django.contrib.auth.models.Permission.DoesNotExist: Permission matching query does not exist.
ERROR 2025-01-16 05:11:38,057 basehttp "POST /index/assign_offer_permission/ HTTP/1.1" 500 84370
ERROR 2025-01-16 05:11:39,789 log Internal Server Error: /index/assign_offer_permission/
Traceback (most recent call last):
  File "C:\Users\Mihnea\AppData\Local\Programs\Python\Python312\Lib\site-packages\django\core\handlers\exception.py", line 55, in inner
    response = get_response(request)
               ^^^^^^^^^^^^^^^^^^^^^
  File "C:\Users\Mihnea\AppData\Local\Programs\Python\Python312\Lib\site-packages\django\core\handlers\base.py", line 197, in _get_response
    response = wrapped_callback(request, *callback_args, **callback_kwargs)
               ^^^^^^^^^^^^^^^^^^^^^^^^^^^^^^^^^^^^^^^^^^^^^^^^^^^^^^^^^^^^
  File "C:\Users\Mihnea\AppData\Local\Programs\Python\Python312\Lib\site-packages\django\contrib\auth\decorators.py", line 60, in _view_wrapper
    return view_func(request, *args, **kwargs)
           ^^^^^^^^^^^^^^^^^^^^^^^^^^^^^^^^^^^
  File "C:\Users\Mihnea\Documents\Unibuc-FMI\2024-2025\Semestrul_1\Django\proiect\app_0\views.py", line 283, in assign_offer_permission
    permission = Permission.objects.get(codename='vizualizeaza_oferta')
                 ^^^^^^^^^^^^^^^^^^^^^^^^^^^^^^^^^^^^^^^^^^^^^^^^^^^^^^
  File "C:\Users\Mihnea\AppData\Local\Programs\Python\Python312\Lib\site-packages\django\db\models\manager.py", line 87, in manager_method
    return getattr(self.get_queryset(), name)(*args, **kwargs)
           ^^^^^^^^^^^^^^^^^^^^^^^^^^^^^^^^^^^^^^^^^^^^^^^^^^^
  File "C:\Users\Mihnea\AppData\Local\Programs\Python\Python312\Lib\site-packages\django\db\models\query.py", line 649, in get
    raise self.model.DoesNotExist(
django.contrib.auth.models.Permission.DoesNotExist: Permission matching query does not exist.
ERROR 2025-01-16 05:11:39,790 basehttp "POST /index/assign_offer_permission/ HTTP/1.1" 500 84370
ERROR 2025-01-16 05:13:16,907 log Internal Server Error: /index/bilete/
Traceback (most recent call last):
  File "C:\Users\Mihnea\AppData\Local\Programs\Python\Python312\Lib\site-packages\django\core\handlers\exception.py", line 55, in inner
    response = get_response(request)
               ^^^^^^^^^^^^^^^^^^^^^
  File "C:\Users\Mihnea\AppData\Local\Programs\Python\Python312\Lib\site-packages\django\core\handlers\base.py", line 197, in _get_response
    response = wrapped_callback(request, *callback_args, **callback_kwargs)
               ^^^^^^^^^^^^^^^^^^^^^^^^^^^^^^^^^^^^^^^^^^^^^^^^^^^^^^^^^^^^
  File "C:\Users\Mihnea\Documents\Unibuc-FMI\2024-2025\Semestrul_1\Django\proiect\app_0\views.py", line 57, in lista_bilete
    return render(request, 'app_0/lista_bilete.html', {'form': form, 'page_obj': page_obj})
           ^^^^^^^^^^^^^^^^^^^^^^^^^^^^^^^^^^^^^^^^^^^^^^^^^^^^^^^^^^^^^^^^^^^^^^^^^^^^^^^^
  File "C:\Users\Mihnea\AppData\Local\Programs\Python\Python312\Lib\site-packages\django\shortcuts.py", line 25, in render
    content = loader.render_to_string(template_name, context, request, using=using)
              ^^^^^^^^^^^^^^^^^^^^^^^^^^^^^^^^^^^^^^^^^^^^^^^^^^^^^^^^^^^^^^^^^^^^^
  File "C:\Users\Mihnea\AppData\Local\Programs\Python\Python312\Lib\site-packages\django\template\loader.py", line 62, in render_to_string
    return template.render(context, request)
           ^^^^^^^^^^^^^^^^^^^^^^^^^^^^^^^^^
  File "C:\Users\Mihnea\AppData\Local\Programs\Python\Python312\Lib\site-packages\django\template\backends\django.py", line 107, in render
    return self.template.render(context)
           ^^^^^^^^^^^^^^^^^^^^^^^^^^^^^
  File "C:\Users\Mihnea\AppData\Local\Programs\Python\Python312\Lib\site-packages\django\template\base.py", line 171, in render
    return self._render(context)
           ^^^^^^^^^^^^^^^^^^^^^
  File "C:\Users\Mihnea\AppData\Local\Programs\Python\Python312\Lib\site-packages\django\template\base.py", line 163, in _render
    return self.nodelist.render(context)
           ^^^^^^^^^^^^^^^^^^^^^^^^^^^^^
  File "C:\Users\Mihnea\AppData\Local\Programs\Python\Python312\Lib\site-packages\django\template\base.py", line 1008, in render
    return SafeString("".join([node.render_annotated(context) for node in self]))
                               ^^^^^^^^^^^^^^^^^^^^^^^^^^^^^^
  File "C:\Users\Mihnea\AppData\Local\Programs\Python\Python312\Lib\site-packages\django\template\base.py", line 969, in render_annotated
    return self.render(context)
           ^^^^^^^^^^^^^^^^^^^^
  File "C:\Users\Mihnea\AppData\Local\Programs\Python\Python312\Lib\site-packages\django\template\defaulttags.py", line 327, in render
    return nodelist.render(context)
           ^^^^^^^^^^^^^^^^^^^^^^^^
  File "C:\Users\Mihnea\AppData\Local\Programs\Python\Python312\Lib\site-packages\django\template\base.py", line 1008, in render
    return SafeString("".join([node.render_annotated(context) for node in self]))
                               ^^^^^^^^^^^^^^^^^^^^^^^^^^^^^^
  File "C:\Users\Mihnea\AppData\Local\Programs\Python\Python312\Lib\site-packages\django\template\base.py", line 969, in render_annotated
    return self.render(context)
           ^^^^^^^^^^^^^^^^^^^^
  File "C:\Users\Mihnea\AppData\Local\Programs\Python\Python312\Lib\site-packages\django\template\defaulttags.py", line 480, in render
    url = reverse(view_name, args=args, kwargs=kwargs, current_app=current_app)
          ^^^^^^^^^^^^^^^^^^^^^^^^^^^^^^^^^^^^^^^^^^^^^^^^^^^^^^^^^^^^^^^^^^^^^
  File "C:\Users\Mihnea\AppData\Local\Programs\Python\Python312\Lib\site-packages\django\urls\base.py", line 88, in reverse
    return resolver._reverse_with_prefix(view, prefix, *args, **kwargs)
           ^^^^^^^^^^^^^^^^^^^^^^^^^^^^^^^^^^^^^^^^^^^^^^^^^^^^^^^^^^^^
  File "C:\Users\Mihnea\AppData\Local\Programs\Python\Python312\Lib\site-packages\django\urls\resolvers.py", line 831, in _reverse_with_prefix
    raise NoReverseMatch(msg)
django.urls.exceptions.NoReverseMatch: Reverse for 'oferta.html' not found. 'oferta.html' is not a valid view function or pattern name.
ERROR 2025-01-16 05:13:20,078 basehttp "GET /index/bilete/ HTTP/1.1" 500 136761
ERROR 2025-01-16 05:14:01,100 log Internal Server Error: /index/assign_offer_permission/
Traceback (most recent call last):
  File "C:\Users\Mihnea\AppData\Local\Programs\Python\Python312\Lib\site-packages\django\core\handlers\exception.py", line 55, in inner
    response = get_response(request)
               ^^^^^^^^^^^^^^^^^^^^^
  File "C:\Users\Mihnea\AppData\Local\Programs\Python\Python312\Lib\site-packages\django\core\handlers\base.py", line 197, in _get_response
    response = wrapped_callback(request, *callback_args, **callback_kwargs)
               ^^^^^^^^^^^^^^^^^^^^^^^^^^^^^^^^^^^^^^^^^^^^^^^^^^^^^^^^^^^^
  File "C:\Users\Mihnea\AppData\Local\Programs\Python\Python312\Lib\site-packages\django\contrib\auth\decorators.py", line 60, in _view_wrapper
    return view_func(request, *args, **kwargs)
           ^^^^^^^^^^^^^^^^^^^^^^^^^^^^^^^^^^^
  File "C:\Users\Mihnea\Documents\Unibuc-FMI\2024-2025\Semestrul_1\Django\proiect\app_0\views.py", line 283, in assign_offer_permission
    permission = Permission.objects.get(codename='vizualizeaza_oferta')
                 ^^^^^^^^^^^^^^^^^^^^^^^^^^^^^^^^^^^^^^^^^^^^^^^^^^^^^^
  File "C:\Users\Mihnea\AppData\Local\Programs\Python\Python312\Lib\site-packages\django\db\models\manager.py", line 87, in manager_method
    return getattr(self.get_queryset(), name)(*args, **kwargs)
           ^^^^^^^^^^^^^^^^^^^^^^^^^^^^^^^^^^^^^^^^^^^^^^^^^^^
  File "C:\Users\Mihnea\AppData\Local\Programs\Python\Python312\Lib\site-packages\django\db\models\query.py", line 649, in get
    raise self.model.DoesNotExist(
django.contrib.auth.models.Permission.DoesNotExist: Permission matching query does not exist.
ERROR 2025-01-16 05:14:01,101 basehttp "POST /index/assign_offer_permission/ HTTP/1.1" 500 84370
ERROR 2025-01-16 05:14:01,685 log Internal Server Error: /index/assign_offer_permission/
Traceback (most recent call last):
  File "C:\Users\Mihnea\AppData\Local\Programs\Python\Python312\Lib\site-packages\django\core\handlers\exception.py", line 55, in inner
    response = get_response(request)
               ^^^^^^^^^^^^^^^^^^^^^
  File "C:\Users\Mihnea\AppData\Local\Programs\Python\Python312\Lib\site-packages\django\core\handlers\base.py", line 197, in _get_response
    response = wrapped_callback(request, *callback_args, **callback_kwargs)
               ^^^^^^^^^^^^^^^^^^^^^^^^^^^^^^^^^^^^^^^^^^^^^^^^^^^^^^^^^^^^
  File "C:\Users\Mihnea\AppData\Local\Programs\Python\Python312\Lib\site-packages\django\contrib\auth\decorators.py", line 60, in _view_wrapper
    return view_func(request, *args, **kwargs)
           ^^^^^^^^^^^^^^^^^^^^^^^^^^^^^^^^^^^
  File "C:\Users\Mihnea\Documents\Unibuc-FMI\2024-2025\Semestrul_1\Django\proiect\app_0\views.py", line 283, in assign_offer_permission
    permission = Permission.objects.get(codename='vizualizeaza_oferta')
                 ^^^^^^^^^^^^^^^^^^^^^^^^^^^^^^^^^^^^^^^^^^^^^^^^^^^^^^
  File "C:\Users\Mihnea\AppData\Local\Programs\Python\Python312\Lib\site-packages\django\db\models\manager.py", line 87, in manager_method
    return getattr(self.get_queryset(), name)(*args, **kwargs)
           ^^^^^^^^^^^^^^^^^^^^^^^^^^^^^^^^^^^^^^^^^^^^^^^^^^^
  File "C:\Users\Mihnea\AppData\Local\Programs\Python\Python312\Lib\site-packages\django\db\models\query.py", line 649, in get
    raise self.model.DoesNotExist(
django.contrib.auth.models.Permission.DoesNotExist: Permission matching query does not exist.
ERROR 2025-01-16 05:14:01,687 basehttp "POST /index/assign_offer_permission/ HTTP/1.1" 500 84370
ERROR 2025-01-16 05:14:02,635 log Internal Server Error: /index/assign_offer_permission/
Traceback (most recent call last):
  File "C:\Users\Mihnea\AppData\Local\Programs\Python\Python312\Lib\site-packages\django\core\handlers\exception.py", line 55, in inner
    response = get_response(request)
               ^^^^^^^^^^^^^^^^^^^^^
  File "C:\Users\Mihnea\AppData\Local\Programs\Python\Python312\Lib\site-packages\django\core\handlers\base.py", line 197, in _get_response
    response = wrapped_callback(request, *callback_args, **callback_kwargs)
               ^^^^^^^^^^^^^^^^^^^^^^^^^^^^^^^^^^^^^^^^^^^^^^^^^^^^^^^^^^^^
  File "C:\Users\Mihnea\AppData\Local\Programs\Python\Python312\Lib\site-packages\django\contrib\auth\decorators.py", line 60, in _view_wrapper
    return view_func(request, *args, **kwargs)
           ^^^^^^^^^^^^^^^^^^^^^^^^^^^^^^^^^^^
  File "C:\Users\Mihnea\Documents\Unibuc-FMI\2024-2025\Semestrul_1\Django\proiect\app_0\views.py", line 283, in assign_offer_permission
    permission = Permission.objects.get(codename='vizualizeaza_oferta')
                 ^^^^^^^^^^^^^^^^^^^^^^^^^^^^^^^^^^^^^^^^^^^^^^^^^^^^^^
  File "C:\Users\Mihnea\AppData\Local\Programs\Python\Python312\Lib\site-packages\django\db\models\manager.py", line 87, in manager_method
    return getattr(self.get_queryset(), name)(*args, **kwargs)
           ^^^^^^^^^^^^^^^^^^^^^^^^^^^^^^^^^^^^^^^^^^^^^^^^^^^
  File "C:\Users\Mihnea\AppData\Local\Programs\Python\Python312\Lib\site-packages\django\db\models\query.py", line 649, in get
    raise self.model.DoesNotExist(
django.contrib.auth.models.Permission.DoesNotExist: Permission matching query does not exist.
ERROR 2025-01-16 05:14:02,636 basehttp "POST /index/assign_offer_permission/ HTTP/1.1" 500 84370
ERROR 2025-01-16 05:14:02,778 log Internal Server Error: /index/assign_offer_permission/
Traceback (most recent call last):
  File "C:\Users\Mihnea\AppData\Local\Programs\Python\Python312\Lib\site-packages\django\core\handlers\exception.py", line 55, in inner
    response = get_response(request)
               ^^^^^^^^^^^^^^^^^^^^^
  File "C:\Users\Mihnea\AppData\Local\Programs\Python\Python312\Lib\site-packages\django\core\handlers\base.py", line 197, in _get_response
    response = wrapped_callback(request, *callback_args, **callback_kwargs)
               ^^^^^^^^^^^^^^^^^^^^^^^^^^^^^^^^^^^^^^^^^^^^^^^^^^^^^^^^^^^^
  File "C:\Users\Mihnea\AppData\Local\Programs\Python\Python312\Lib\site-packages\django\contrib\auth\decorators.py", line 60, in _view_wrapper
    return view_func(request, *args, **kwargs)
           ^^^^^^^^^^^^^^^^^^^^^^^^^^^^^^^^^^^
  File "C:\Users\Mihnea\Documents\Unibuc-FMI\2024-2025\Semestrul_1\Django\proiect\app_0\views.py", line 283, in assign_offer_permission
    permission = Permission.objects.get(codename='vizualizeaza_oferta')
                 ^^^^^^^^^^^^^^^^^^^^^^^^^^^^^^^^^^^^^^^^^^^^^^^^^^^^^^
  File "C:\Users\Mihnea\AppData\Local\Programs\Python\Python312\Lib\site-packages\django\db\models\manager.py", line 87, in manager_method
    return getattr(self.get_queryset(), name)(*args, **kwargs)
           ^^^^^^^^^^^^^^^^^^^^^^^^^^^^^^^^^^^^^^^^^^^^^^^^^^^
  File "C:\Users\Mihnea\AppData\Local\Programs\Python\Python312\Lib\site-packages\django\db\models\query.py", line 649, in get
    raise self.model.DoesNotExist(
django.contrib.auth.models.Permission.DoesNotExist: Permission matching query does not exist.
ERROR 2025-01-16 05:14:02,780 basehttp "POST /index/assign_offer_permission/ HTTP/1.1" 500 84370
ERROR 2025-01-16 05:15:47,385 log Internal Server Error: /index/assign_offer_permission/
Traceback (most recent call last):
  File "C:\Users\Mihnea\AppData\Local\Programs\Python\Python312\Lib\site-packages\django\core\handlers\exception.py", line 55, in inner
    response = get_response(request)
               ^^^^^^^^^^^^^^^^^^^^^
  File "C:\Users\Mihnea\AppData\Local\Programs\Python\Python312\Lib\site-packages\django\core\handlers\base.py", line 197, in _get_response
    response = wrapped_callback(request, *callback_args, **callback_kwargs)
               ^^^^^^^^^^^^^^^^^^^^^^^^^^^^^^^^^^^^^^^^^^^^^^^^^^^^^^^^^^^^
  File "C:\Users\Mihnea\AppData\Local\Programs\Python\Python312\Lib\site-packages\django\contrib\auth\decorators.py", line 60, in _view_wrapper
    return view_func(request, *args, **kwargs)
           ^^^^^^^^^^^^^^^^^^^^^^^^^^^^^^^^^^^
  File "C:\Users\Mihnea\Documents\Unibuc-FMI\2024-2025\Semestrul_1\Django\proiect\app_0\views.py", line 283, in assign_offer_permission
    permission = Permission.objects.get(codename='vizualizeaza_oferta')
                 ^^^^^^^^^^^^^^^^^^^^^^^^^^^^^^^^^^^^^^^^^^^^^^^^^^^^^^
  File "C:\Users\Mihnea\AppData\Local\Programs\Python\Python312\Lib\site-packages\django\db\models\manager.py", line 87, in manager_method
    return getattr(self.get_queryset(), name)(*args, **kwargs)
           ^^^^^^^^^^^^^^^^^^^^^^^^^^^^^^^^^^^^^^^^^^^^^^^^^^^
  File "C:\Users\Mihnea\AppData\Local\Programs\Python\Python312\Lib\site-packages\django\db\models\query.py", line 649, in get
    raise self.model.DoesNotExist(
django.contrib.auth.models.Permission.DoesNotExist: Permission matching query does not exist.
ERROR 2025-01-16 05:15:47,387 basehttp "POST /index/assign_offer_permission/ HTTP/1.1" 500 84370
ERROR 2025-01-16 05:15:47,955 log Internal Server Error: /index/assign_offer_permission/
Traceback (most recent call last):
  File "C:\Users\Mihnea\AppData\Local\Programs\Python\Python312\Lib\site-packages\django\core\handlers\exception.py", line 55, in inner
    response = get_response(request)
               ^^^^^^^^^^^^^^^^^^^^^
  File "C:\Users\Mihnea\AppData\Local\Programs\Python\Python312\Lib\site-packages\django\core\handlers\base.py", line 197, in _get_response
    response = wrapped_callback(request, *callback_args, **callback_kwargs)
               ^^^^^^^^^^^^^^^^^^^^^^^^^^^^^^^^^^^^^^^^^^^^^^^^^^^^^^^^^^^^
  File "C:\Users\Mihnea\AppData\Local\Programs\Python\Python312\Lib\site-packages\django\contrib\auth\decorators.py", line 60, in _view_wrapper
    return view_func(request, *args, **kwargs)
           ^^^^^^^^^^^^^^^^^^^^^^^^^^^^^^^^^^^
  File "C:\Users\Mihnea\Documents\Unibuc-FMI\2024-2025\Semestrul_1\Django\proiect\app_0\views.py", line 283, in assign_offer_permission
    permission = Permission.objects.get(codename='vizualizeaza_oferta')
                 ^^^^^^^^^^^^^^^^^^^^^^^^^^^^^^^^^^^^^^^^^^^^^^^^^^^^^^
  File "C:\Users\Mihnea\AppData\Local\Programs\Python\Python312\Lib\site-packages\django\db\models\manager.py", line 87, in manager_method
    return getattr(self.get_queryset(), name)(*args, **kwargs)
           ^^^^^^^^^^^^^^^^^^^^^^^^^^^^^^^^^^^^^^^^^^^^^^^^^^^
  File "C:\Users\Mihnea\AppData\Local\Programs\Python\Python312\Lib\site-packages\django\db\models\query.py", line 649, in get
    raise self.model.DoesNotExist(
django.contrib.auth.models.Permission.DoesNotExist: Permission matching query does not exist.
ERROR 2025-01-16 05:15:47,956 basehttp "POST /index/assign_offer_permission/ HTTP/1.1" 500 84370
ERROR 2025-01-16 05:15:56,791 log Internal Server Error: /index/assign_offer_permission/
Traceback (most recent call last):
  File "C:\Users\Mihnea\AppData\Local\Programs\Python\Python312\Lib\site-packages\django\core\handlers\exception.py", line 55, in inner
    response = get_response(request)
               ^^^^^^^^^^^^^^^^^^^^^
  File "C:\Users\Mihnea\AppData\Local\Programs\Python\Python312\Lib\site-packages\django\core\handlers\base.py", line 197, in _get_response
    response = wrapped_callback(request, *callback_args, **callback_kwargs)
               ^^^^^^^^^^^^^^^^^^^^^^^^^^^^^^^^^^^^^^^^^^^^^^^^^^^^^^^^^^^^
  File "C:\Users\Mihnea\AppData\Local\Programs\Python\Python312\Lib\site-packages\django\contrib\auth\decorators.py", line 60, in _view_wrapper
    return view_func(request, *args, **kwargs)
           ^^^^^^^^^^^^^^^^^^^^^^^^^^^^^^^^^^^
  File "C:\Users\Mihnea\Documents\Unibuc-FMI\2024-2025\Semestrul_1\Django\proiect\app_0\views.py", line 283, in assign_offer_permission
    permission = Permission.objects.get(codename='vizualizeaza_oferta')
                 ^^^^^^^^^^^^^^^^^^^^^^^^^^^^^^^^^^^^^^^^^^^^^^^^^^^^^^
  File "C:\Users\Mihnea\AppData\Local\Programs\Python\Python312\Lib\site-packages\django\db\models\manager.py", line 87, in manager_method
    return getattr(self.get_queryset(), name)(*args, **kwargs)
           ^^^^^^^^^^^^^^^^^^^^^^^^^^^^^^^^^^^^^^^^^^^^^^^^^^^
  File "C:\Users\Mihnea\AppData\Local\Programs\Python\Python312\Lib\site-packages\django\db\models\query.py", line 649, in get
    raise self.model.DoesNotExist(
django.contrib.auth.models.Permission.DoesNotExist: Permission matching query does not exist.
ERROR 2025-01-16 05:15:56,793 basehttp "POST /index/assign_offer_permission/ HTTP/1.1" 500 84370
WARNING 2025-01-16 05:17:39,694 log Bad Request: /index/assign_offer_permission/
WARNING 2025-01-16 05:17:39,695 basehttp "POST /index/assign_offer_permission/ HTTP/1.1" 400 59
WARNING 2025-01-16 05:17:40,317 log Bad Request: /index/assign_offer_permission/
WARNING 2025-01-16 05:17:40,319 basehttp "POST /index/assign_offer_permission/ HTTP/1.1" 400 59
WARNING 2025-01-16 05:17:43,263 log Forbidden: /index/oferta/
WARNING 2025-01-16 05:17:43,264 basehttp "GET /index/oferta/ HTTP/1.1" 403 218
